Workbook
Name EFETIVO: #REF!
Name EFETIVO: #REF!
Name SSSSS: #REF!
Name SSSSS: #REF!
Name SSSSSS: #REF!
Name SSSSSS: #REF!
Name xxxxxxxxxxx: #REF!
Name xxxxxxxxxxx: #REF!

Sheet RESUMO-CURVA ACM
A3: PREV | B3: REAL | C3: Item | D3: Descrição | E3: CONTRATO | F3: ACUMULADO | H3: PERCENTUAL | I3: CONTRATO | J3: ACUMULADO
A4: 220 | B4: 221 | C4: 2.14 | D4: ="FERRAMENTAS - CIVIL " -> FERRAMENTAS - CIVIL | E4: =I4 -> 6965.42 | F4: =J4 -> 3935.0304 | G4: 20 | H4: =SUMIF('RESUMO-CURVA GRÁFICO'!$B$4:$B$261,'RESUMO-CURVA ACM'!B4,'RESUMO-CURVA GRÁFICO'!$Y$4:$Y$261) -> 0.56493799 | I4: =SUMIF('RESUMO-CURVA GRÁFICO'!$B$4:$B$261,'RESUMO-CURVA ACM'!A4,'RESUMO-CURVA GRÁFICO'!$X$4:$X$261) -> 6965.42 | J4: =SUMIF('RESUMO-CURVA GRÁFICO'!$B$4:$B$261,'RESUMO-CURVA ACM'!B4,'RESUMO-CURVA GRÁFICO'!$X$4:$X$261) -> 3935.0304
A5: 212 | B5: 213 | C5: 2.12 | D5: ="INSTRUMENTOS - ELÉTRICA" -> INSTRUMENTOS - ELÉTRICA | E5: =I5 -> 14304 | F5: =J5 -> 2791.7333 | G5: 19 | H5: =SUMIF('RESUMO-CURVA GRÁFICO'!$B$4:$B$261,'RESUMO-CURVA ACM'!B5,'RESUMO-CURVA GRÁFICO'!$Y$4:$Y$261) -> 0.19517151 | I5: =SUMIF('RESUMO-CURVA GRÁFICO'!$B$4:$B$261,'RESUMO-CURVA ACM'!A5,'RESUMO-CURVA GRÁFICO'!$X$4:$X$261) -> 14304 | J5: =SUMIF('RESUMO-CURVA GRÁFICO'!$B$4:$B$261,'RESUMO-CURVA ACM'!B5,'RESUMO-CURVA GRÁFICO'!$X$4:$X$261) -> 2791.7333
A6: 228 | B6: 229 | C6: 2.16 | D6: ="MOBILIZAÇÃO E DESMOBILIZAÇÃO " -> MOBILIZAÇÃO E DESMOBILIZAÇÃO | E6: =I6 -> 16308.35 | F6: =J6 -> 8154.175 | G6: 18 | H6: =SUMIF('RESUMO-CURVA GRÁFICO'!$B$4:$B$261,'RESUMO-CURVA ACM'!B6,'RESUMO-CURVA GRÁFICO'!$Y$4:$Y$261) -> 0.5 | I6: =SUMIF('RESUMO-CURVA GRÁFICO'!$B$4:$B$261,'RESUMO-CURVA ACM'!A6,'RESUMO-CURVA GRÁFICO'!$X$4:$X$261) -> 16308.35 | J6: =SUMIF('RESUMO-CURVA GRÁFICO'!$B$4:$B$261,'RESUMO-CURVA ACM'!B6,'RESUMO-CURVA GRÁFICO'!$X$4:$X$261) -> 8154.175
A7: 234 | B7: 235 | C7: 2.17 | D7: ="FRENTES MÓVEIS" -> FRENTES MÓVEIS | E7: =I7 -> 70204 | F7: =J7 -> 39782.267 | G7: 17 | H7: =SUMIF('RESUMO-CURVA GRÁFICO'!$B$4:$B$261,'RESUMO-CURVA ACM'!B7,'RESUMO-CURVA GRÁFICO'!$Y$4:$Y$261) -> 0.56666667 | I7: =SUMIF('RESUMO-CURVA GRÁFICO'!$B$4:$B$261,'RESUMO-CURVA ACM'!A7,'RESUMO-CURVA GRÁFICO'!$X$4:$X$261) -> 70204 | J7: =SUMIF('RESUMO-CURVA GRÁFICO'!$B$4:$B$261,'RESUMO-CURVA ACM'!B7,'RESUMO-CURVA GRÁFICO'!$X$4:$X$261) -> 39782.267
A8: 196 | B8: 197 | C8: 2.8 | D8: ="MATERIAL DE CONSUMO - ELÉTRICO" -> MATERIAL DE CONSUMO - ELÉTRICO | E8: =I8 -> 83279.41 | F8: =J8 -> 39574.542 | G8: 16 | H8: =SUMIF('RESUMO-CURVA GRÁFICO'!$B$4:$B$261,'RESUMO-CURVA ACM'!B8,'RESUMO-CURVA GRÁFICO'!$Y$4:$Y$261) -> 0.475202 | I8: =SUMIF('RESUMO-CURVA GRÁFICO'!$B$4:$B$261,'RESUMO-CURVA ACM'!A8,'RESUMO-CURVA GRÁFICO'!$X$4:$X$261) -> 83279.41 | J8: =SUMIF('RESUMO-CURVA GRÁFICO'!$B$4:$B$261,'RESUMO-CURVA ACM'!B8,'RESUMO-CURVA GRÁFICO'!$X$4:$X$261) -> 39574.542
A9: 200 | B9: 201 | C9: 2.9 | D9: ="FERRAMENTAS ELÉTRICA" -> FERRAMENTAS ELÉTRICA | E9: =I9 -> 96713.2 | F9: =J9 -> 31392.959 | G9: 15 | H9: =SUMIF('RESUMO-CURVA GRÁFICO'!$B$4:$B$261,'RESUMO-CURVA ACM'!B9,'RESUMO-CURVA GRÁFICO'!$Y$4:$Y$261) -> 0.32459849 | I9: =SUMIF('RESUMO-CURVA GRÁFICO'!$B$4:$B$261,'RESUMO-CURVA ACM'!A9,'RESUMO-CURVA GRÁFICO'!$X$4:$X$261) -> 96713.2 | J9: =SUMIF('RESUMO-CURVA GRÁFICO'!$B$4:$B$261,'RESUMO-CURVA ACM'!B9,'RESUMO-CURVA GRÁFICO'!$X$4:$X$261) -> 31392.959
A10: 96 | B10: 97 | C10: 2.2 | D10: ="EQUIPAMENTOS DE INFORMÁTICA" -> EQUIPAMENTOS DE INFORMÁTICA | E10: =I10 -> 138086.16 | F10: =J10 -> 78248.824 | G10: 14 | H10: =SUMIF('RESUMO-CURVA GRÁFICO'!$B$4:$B$261,'RESUMO-CURVA ACM'!B10,'RESUMO-CURVA GRÁFICO'!$Y$4:$Y$261) -> 0.56666667 | I10: =SUMIF('RESUMO-CURVA GRÁFICO'!$B$4:$B$261,'RESUMO-CURVA ACM'!A10,'RESUMO-CURVA GRÁFICO'!$X$4:$X$261) -> 138086.16 | J10: =SUMIF('RESUMO-CURVA GRÁFICO'!$B$4:$B$261,'RESUMO-CURVA ACM'!B10,'RESUMO-CURVA GRÁFICO'!$X$4:$X$261) -> 78248.824
A11: 216 | B11: 217 | C11: 2.13 | D11: ="MANUTENÇÃO CIVIL - MATERIAIS CONSUMÍVEIS" -> MANUTENÇÃO CIVIL - MATERIAIS CONSUMÍVEIS | E11: =I11 -> 237025.32 | F11: =J11 -> 145430.81 | G11: 13 | H11: =SUMIF('RESUMO-CURVA GRÁFICO'!$B$4:$B$261,'RESUMO-CURVA ACM'!B11,'RESUMO-CURVA GRÁFICO'!$Y$4:$Y$261) -> 0.61356658 | I11: =SUMIF('RESUMO-CURVA GRÁFICO'!$B$4:$B$261,'RESUMO-CURVA ACM'!A11,'RESUMO-CURVA GRÁFICO'!$X$4:$X$261) -> 237025.32 | J11: =SUMIF('RESUMO-CURVA GRÁFICO'!$B$4:$B$261,'RESUMO-CURVA ACM'!B11,'RESUMO-CURVA GRÁFICO'!$X$4:$X$261) -> 145430.81
A12: 224 | B12: 225 | C12: 2.15 | D12: ="TRANSPORTE DE EQUIPAMENTOS" -> TRANSPORTE DE EQUIPAMENTOS | E12: =I12 -> 270788.7 | F12: =J12 -> 0 | G12: 12 | H12: =SUMIF('RESUMO-CURVA GRÁFICO'!$B$4:$B$261,'RESUMO-CURVA ACM'!B12,'RESUMO-CURVA GRÁFICO'!$Y$4:$Y$261) -> 0 | I12: =SUMIF('RESUMO-CURVA GRÁFICO'!$B$4:$B$261,'RESUMO-CURVA ACM'!A12,'RESUMO-CURVA GRÁFICO'!$X$4:$X$261) -> 270788.7 | J12: =SUMIF('RESUMO-CURVA GRÁFICO'!$B$4:$B$261,'RESUMO-CURVA ACM'!B12,'RESUMO-CURVA GRÁFICO'!$X$4:$X$261) -> 0
A13: 256 | B13: 257 | C13: 3 | D13: ="DESPESAS REEMBOLSÁVEIS" -> DESPESAS REEMBOLSÁVEIS | E13: =I13 -> 337157.91 | F13: =J13 -> 169515.73 | G13: 11 | H13: =SUMIF('RESUMO-CURVA GRÁFICO'!$B$4:$B$261,'RESUMO-CURVA ACM'!B13,'RESUMO-CURVA GRÁFICO'!$Y$4:$Y$261) -> 0.50277845 | I13: =SUMIF('RESUMO-CURVA GRÁFICO'!$B$4:$B$261,'RESUMO-CURVA ACM'!A13,'RESUMO-CURVA GRÁFICO'!$X$4:$X$261) -> 337157.91 | J13: =SUMIF('RESUMO-CURVA GRÁFICO'!$B$4:$B$261,'RESUMO-CURVA ACM'!B13,'RESUMO-CURVA GRÁFICO'!$X$4:$X$261) -> 169515.73
A14: 84 | B14: 85 | C14: 2.1 | D14: ="VIAGENS" -> VIAGENS | E14: =I14 -> 382021.68 | F14: =J14 -> 94516.99 | G14: 10 | H14: =SUMIF('RESUMO-CURVA GRÁFICO'!$B$4:$B$261,'RESUMO-CURVA ACM'!B14,'RESUMO-CURVA GRÁFICO'!$Y$4:$Y$261) -> 0.24741263 | I14: =SUMIF('RESUMO-CURVA GRÁFICO'!$B$4:$B$261,'RESUMO-CURVA ACM'!A14,'RESUMO-CURVA GRÁFICO'!$X$4:$X$261) -> 382021.68 | J14: =SUMIF('RESUMO-CURVA GRÁFICO'!$B$4:$B$261,'RESUMO-CURVA ACM'!B14,'RESUMO-CURVA GRÁFICO'!$X$4:$X$261) -> 94516.99
A15: 204 | B15: 205 | C15: 2.10 | D15: ="SOBRESSALENTES - ELÉTRICA" -> SOBRESSALENTES - ELÉTRICA | E15: =I15 -> 426502.25 | F15: =J15 -> 77900.75 | G15: 9 | H15: =SUMIF('RESUMO-CURVA GRÁFICO'!$B$4:$B$261,'RESUMO-CURVA ACM'!B15,'RESUMO-CURVA GRÁFICO'!$Y$4:$Y$261) -> 0.18265027 | I15: =SUMIF('RESUMO-CURVA GRÁFICO'!$B$4:$B$261,'RESUMO-CURVA ACM'!A15,'RESUMO-CURVA GRÁFICO'!$X$4:$X$261) -> 426502.25 | J15: =SUMIF('RESUMO-CURVA GRÁFICO'!$B$4:$B$261,'RESUMO-CURVA ACM'!B15,'RESUMO-CURVA GRÁFICO'!$X$4:$X$261) -> 77900.75
A16: 208 | B16: 209 | C16: 2.11 | D16: ="SOBRESSALENTES - LINHA DE TRANSMISSÃO" -> SOBRESSALENTES - LINHA DE TRANSMISSÃO | E16: =I16 -> 469086.46 | F16: =J16 -> 3220.1303 | G16: 8 | H16: =SUMIF('RESUMO-CURVA GRÁFICO'!$B$4:$B$261,'RESUMO-CURVA ACM'!B16,'RESUMO-CURVA GRÁFICO'!$Y$4:$Y$261) -> 0.006864684 | I16: =SUMIF('RESUMO-CURVA GRÁFICO'!$B$4:$B$261,'RESUMO-CURVA ACM'!A16,'RESUMO-CURVA GRÁFICO'!$X$4:$X$261) -> 469086.46 | J16: =SUMIF('RESUMO-CURVA GRÁFICO'!$B$4:$B$261,'RESUMO-CURVA ACM'!B16,'RESUMO-CURVA GRÁFICO'!$X$4:$X$261) -> 3220.1303
A17: 126 | B17: 127 | C17: 2.4 | D17: ="ESCRITÓRIO" -> ESCRITÓRIO | E17: =I17 -> 518209.68 | F17: =J17 -> 293425.62 | G17: 7 | H17: =SUMIF('RESUMO-CURVA GRÁFICO'!$B$4:$B$261,'RESUMO-CURVA ACM'!B17,'RESUMO-CURVA GRÁFICO'!$Y$4:$Y$261) -> 0.56622953 | I17: =SUMIF('RESUMO-CURVA GRÁFICO'!$B$4:$B$261,'RESUMO-CURVA ACM'!A17,'RESUMO-CURVA GRÁFICO'!$X$4:$X$261) -> 518209.68 | J17: =SUMIF('RESUMO-CURVA GRÁFICO'!$B$4:$B$261,'RESUMO-CURVA ACM'!B17,'RESUMO-CURVA GRÁFICO'!$X$4:$X$261) -> 293425.62
A18: 142 | B18: 143 | C18: 2.5 | D18: ="SISTEMA DE RÁDIO COMUNICAÇÃO" -> SISTEMA DE RÁDIO COMUNICAÇÃO | E18: =I18 -> 528013.08 | F18: =J18 -> 278959.32 | G18: 6 | H18: =SUMIF('RESUMO-CURVA GRÁFICO'!$B$4:$B$261,'RESUMO-CURVA ACM'!B18,'RESUMO-CURVA GRÁFICO'!$Y$4:$Y$261) -> 0.52831897 | I18: =SUMIF('RESUMO-CURVA GRÁFICO'!$B$4:$B$261,'RESUMO-CURVA ACM'!A18,'RESUMO-CURVA GRÁFICO'!$X$4:$X$261) -> 528013.08 | J18: =SUMIF('RESUMO-CURVA GRÁFICO'!$B$4:$B$261,'RESUMO-CURVA ACM'!B18,'RESUMO-CURVA GRÁFICO'!$X$4:$X$261) -> 278959.32
A19: 158 | B19: 159 | C19: 2.6 | D19: ="INSTALAÇÃO DA EQUIPE" -> INSTALAÇÃO DA EQUIPE | E19: =I19 -> 685215 | F19: =J19 -> 388288.5 | G19: 5 | H19: =SUMIF('RESUMO-CURVA GRÁFICO'!$B$4:$B$261,'RESUMO-CURVA ACM'!B19,'RESUMO-CURVA GRÁFICO'!$Y$4:$Y$261) -> 0.56666667 | I19: =SUMIF('RESUMO-CURVA GRÁFICO'!$B$4:$B$261,'RESUMO-CURVA ACM'!A19,'RESUMO-CURVA GRÁFICO'!$X$4:$X$261) -> 685215 | J19: =SUMIF('RESUMO-CURVA GRÁFICO'!$B$4:$B$261,'RESUMO-CURVA ACM'!B19,'RESUMO-CURVA GRÁFICO'!$X$4:$X$261) -> 388288.5
A20: 166 | B20: 167 | C20: 2.7 | D20: ="EQUIPAMENTOS PARA MANUTENÇÃO ELÉTRICA" -> EQUIPAMENTOS PARA MANUTENÇÃO ELÉTRICA | E20: =I20 -> 4591811.1 | F20: =J20 -> 2717231.3 | G20: 4 | H20: =SUMIF('RESUMO-CURVA GRÁFICO'!$B$4:$B$261,'RESUMO-CURVA ACM'!B20,'RESUMO-CURVA GRÁFICO'!$Y$4:$Y$261) -> 0.5917559 | I20: =SUMIF('RESUMO-CURVA GRÁFICO'!$B$4:$B$261,'RESUMO-CURVA ACM'!A20,'RESUMO-CURVA GRÁFICO'!$X$4:$X$261) -> 4591811.1 | J20: =SUMIF('RESUMO-CURVA GRÁFICO'!$B$4:$B$261,'RESUMO-CURVA ACM'!B20,'RESUMO-CURVA GRÁFICO'!$X$4:$X$261) -> 2717231.3
A21: 112 | B21: 113 | C21: 2.3 | D21: ="VEÍCULOS, COMBUSTÍVEL E MANUTENÇÃO" -> VEÍCULOS, COMBUSTÍVEL E MANUTENÇÃO | E21: =I21 -> 3783418.9 | F21: =J21 -> 2109858.5 | G21: 3 | H21: =SUMIF('RESUMO-CURVA GRÁFICO'!$B$4:$B$261,'RESUMO-CURVA ACM'!B21,'RESUMO-CURVA GRÁFICO'!$Y$4:$Y$261) -> 0.55765924 | I21: =SUMIF('RESUMO-CURVA GRÁFICO'!$B$4:$B$261,'RESUMO-CURVA ACM'!A21,'RESUMO-CURVA GRÁFICO'!$X$4:$X$261) -> 3783418.9 | J21: =SUMIF('RESUMO-CURVA GRÁFICO'!$B$4:$B$261,'RESUMO-CURVA ACM'!B21,'RESUMO-CURVA GRÁFICO'!$X$4:$X$261) -> 2109858.5
A22: 78 | B22: 79 | C22: 1 | D22: ="RESUMO DA MÃO DE OBRA" -> RESUMO DA MÃO DE OBRA | E22: =I22 -> 18310884 | F22: =J22 -> 9407553.8 | G22: 1 | H22: =SUMIF('RESUMO-CURVA GRÁFICO'!$B$4:$B$261,'RESUMO-CURVA ACM'!B22,'RESUMO-CURVA GRÁFICO'!$Y$4:$Y$261) -> 0.51376841 | I22: =SUMIF('RESUMO-CURVA GRÁFICO'!$B$4:$B$261,'RESUMO-CURVA ACM'!A22,'RESUMO-CURVA GRÁFICO'!$X$4:$X$261) -> 18310884 | J22: =SUMIF('RESUMO-CURVA GRÁFICO'!$B$4:$B$261,'RESUMO-CURVA ACM'!B22,'RESUMO-CURVA GRÁFICO'!$X$4:$X$261) -> 9407553.8
A23: 249 | B23: 250 | C23: 2 | D23: ="CUSTOS DIRETOS" -> CUSTOS DIRETOS | E23: =I23 -> 12317953 | F23: =J23 -> 6312711.5 | G23: 2 | H23: =SUMIF('RESUMO-CURVA GRÁFICO'!$B$4:$B$261,'RESUMO-CURVA ACM'!B23,'RESUMO-CURVA GRÁFICO'!$Y$4:$Y$261) -> 0.51248057 | I23: =SUMIF('RESUMO-CURVA GRÁFICO'!$B$4:$B$261,'RESUMO-CURVA ACM'!A23,'RESUMO-CURVA GRÁFICO'!$X$4:$X$261) -> 12317953 | J23: =SUMIF('RESUMO-CURVA GRÁFICO'!$B$4:$B$261,'RESUMO-CURVA ACM'!B23,'RESUMO-CURVA GRÁFICO'!$X$4:$X$261) -> 6312711.5
E24: =SUM(E4:E12,E14:E21,E22,E13) -> 30965995 | F24: =SUM(F4:F12,F14:F21,F22,F13) -> 15889781 | H24: =F24/E24 -> 0.51313646 | I24: =SUM(I4:I12,I14:I21,I22,I13) -> 30965995 | J24: =SUM(J4:J12,J14:J21,J22,J13) -> 15889781
E25: =E24-I24 -> 0 | F25: =F24-J24 -> 0 | I25: =I24-'Evolução Mensal'!AR12 -> 7.3425472e-06 | J25: =J24-'Evolução Mensal'!AR13 -> 0

Sheet RESUMO-CURVA PREV
A3: PREV | B3: REAL | C3: Item | D3: Descrição | E3: CONTRATO | F3: PREVISÃO | H3: PERCENTUAL | I3: CONTRATO | J3: PREVISÃO
A4: 220 | B4: 221 | C4: 2.14 | D4: ="FERRAMENTAS - CIVIL " -> FERRAMENTAS - CIVIL | E4: =I4 -> 6965.42 | F4: =J4 -> 6965.42 | G4: 20 | H4: =SUMIF('RESUMO-CURVA GRÁFICO'!$B$4:$B$261,'RESUMO-CURVA PREV'!B4,'RESUMO-CURVA GRÁFICO'!$AD$4:$AD$261) -> 1 | I4: =SUMIF('RESUMO-CURVA GRÁFICO'!$B$4:$B$261,'RESUMO-CURVA PREV'!A4,'RESUMO-CURVA GRÁFICO'!$X$4:$X$261) -> 6965.42 | J4: =SUMIF('RESUMO-CURVA GRÁFICO'!$B$4:$B$261,'RESUMO-CURVA PREV'!B4,'RESUMO-CURVA GRÁFICO'!$AC$4:$AC$261) -> 6965.42
A5: 212 | B5: 213 | C5: 2.12 | D5: ="INSTRUMENTOS - ELÉTRICA" -> INSTRUMENTOS - ELÉTRICA | E5: =I5 -> 14304 | F5: =J5 -> 4971.36 | G5: 19 | H5: =SUMIF('RESUMO-CURVA GRÁFICO'!$B$4:$B$261,'RESUMO-CURVA PREV'!B5,'RESUMO-CURVA GRÁFICO'!$AD$4:$AD$261) -> 0.34755034 | I5: =SUMIF('RESUMO-CURVA GRÁFICO'!$B$4:$B$261,'RESUMO-CURVA PREV'!A5,'RESUMO-CURVA GRÁFICO'!$X$4:$X$261) -> 14304 | J5: =SUMIF('RESUMO-CURVA GRÁFICO'!$B$4:$B$261,'RESUMO-CURVA PREV'!B5,'RESUMO-CURVA GRÁFICO'!$AC$4:$AC$261) -> 4971.36
A6: 228 | B6: 229 | C6: 2.16 | D6: ="MOBILIZAÇÃO E DESMOBILIZAÇÃO " -> MOBILIZAÇÃO E DESMOBILIZAÇÃO | E6: =I6 -> 16308.35 | F6: =J6 -> 8154.175 | G6: 18 | H6: =SUMIF('RESUMO-CURVA GRÁFICO'!$B$4:$B$261,'RESUMO-CURVA PREV'!B6,'RESUMO-CURVA GRÁFICO'!$AD$4:$AD$261) -> 0.5 | I6: =SUMIF('RESUMO-CURVA GRÁFICO'!$B$4:$B$261,'RESUMO-CURVA PREV'!A6,'RESUMO-CURVA GRÁFICO'!$X$4:$X$261) -> 16308.35 | J6: =SUMIF('RESUMO-CURVA GRÁFICO'!$B$4:$B$261,'RESUMO-CURVA PREV'!B6,'RESUMO-CURVA GRÁFICO'!$AC$4:$AC$261) -> 8154.175
A7: 234 | B7: 235 | C7: 2.17 | D7: ="FRENTES MÓVEIS" -> FRENTES MÓVEIS | E7: =I7 -> 70204 | F7: =J7 -> 70204 | G7: 17 | H7: =SUMIF('RESUMO-CURVA GRÁFICO'!$B$4:$B$261,'RESUMO-CURVA PREV'!B7,'RESUMO-CURVA GRÁFICO'!$AD$4:$AD$261) -> 1 | I7: =SUMIF('RESUMO-CURVA GRÁFICO'!$B$4:$B$261,'RESUMO-CURVA PREV'!A7,'RESUMO-CURVA GRÁFICO'!$X$4:$X$261) -> 70204 | J7: =SUMIF('RESUMO-CURVA GRÁFICO'!$B$4:$B$261,'RESUMO-CURVA PREV'!B7,'RESUMO-CURVA GRÁFICO'!$AC$4:$AC$261) -> 70204
A8: 196 | B8: 197 | C8: 2.8 | D8: ="MATERIAL DE CONSUMO - ELÉTRICO" -> MATERIAL DE CONSUMO - ELÉTRICO | E8: =I8 -> 83279.41 | F8: =J8 -> 73584.516 | G8: 16 | H8: =SUMIF('RESUMO-CURVA GRÁFICO'!$B$4:$B$261,'RESUMO-CURVA PREV'!B8,'RESUMO-CURVA GRÁFICO'!$AD$4:$AD$261) -> 0.88358595 | I8: =SUMIF('RESUMO-CURVA GRÁFICO'!$B$4:$B$261,'RESUMO-CURVA PREV'!A8,'RESUMO-CURVA GRÁFICO'!$X$4:$X$261) -> 83279.41 | J8: =SUMIF('RESUMO-CURVA GRÁFICO'!$B$4:$B$261,'RESUMO-CURVA PREV'!B8,'RESUMO-CURVA GRÁFICO'!$AC$4:$AC$261) -> 73584.516
A9: 200 | B9: 201 | C9: 2.9 | D9: ="FERRAMENTAS ELÉTRICA" -> FERRAMENTAS ELÉTRICA | E9: =I9 -> 96713.2 | F9: =J9 -> 55670.23 | G9: 15 | H9: =SUMIF('RESUMO-CURVA GRÁFICO'!$B$4:$B$261,'RESUMO-CURVA PREV'!B9,'RESUMO-CURVA GRÁFICO'!$AD$4:$AD$261) -> 0.57562184 | I9: =SUMIF('RESUMO-CURVA GRÁFICO'!$B$4:$B$261,'RESUMO-CURVA PREV'!A9,'RESUMO-CURVA GRÁFICO'!$X$4:$X$261) -> 96713.2 | J9: =SUMIF('RESUMO-CURVA GRÁFICO'!$B$4:$B$261,'RESUMO-CURVA PREV'!B9,'RESUMO-CURVA GRÁFICO'!$AC$4:$AC$261) -> 55670.23
A10: 96 | B10: 97 | C10: 2.2 | D10: ="EQUIPAMENTOS DE INFORMÁTICA" -> EQUIPAMENTOS DE INFORMÁTICA | E10: =I10 -> 138086.16 | F10: =J10 -> 138086.16 | G10: 14 | H10: =SUMIF('RESUMO-CURVA GRÁFICO'!$B$4:$B$261,'RESUMO-CURVA PREV'!B10,'RESUMO-CURVA GRÁFICO'!$AD$4:$AD$261) -> 1 | I10: =SUMIF('RESUMO-CURVA GRÁFICO'!$B$4:$B$261,'RESUMO-CURVA PREV'!A10,'RESUMO-CURVA GRÁFICO'!$X$4:$X$261) -> 138086.16 | J10: =SUMIF('RESUMO-CURVA GRÁFICO'!$B$4:$B$261,'RESUMO-CURVA PREV'!B10,'RESUMO-CURVA GRÁFICO'!$AC$4:$AC$261) -> 138086.16
A11: 216 | B11: 217 | C11: 2.13 | D11: ="MANUTENÇÃO CIVIL - MATERIAIS CONSUMÍVEIS" -> MANUTENÇÃO CIVIL - MATERIAIS CONSUMÍVEIS | E11: =I11 -> 237025.32 | F11: =J11 -> 237025.32 | G11: 13 | H11: =SUMIF('RESUMO-CURVA GRÁFICO'!$B$4:$B$261,'RESUMO-CURVA PREV'!B11,'RESUMO-CURVA GRÁFICO'!$AD$4:$AD$261) -> 1 | I11: =SUMIF('RESUMO-CURVA GRÁFICO'!$B$4:$B$261,'RESUMO-CURVA PREV'!A11,'RESUMO-CURVA GRÁFICO'!$X$4:$X$261) -> 237025.32 | J11: =SUMIF('RESUMO-CURVA GRÁFICO'!$B$4:$B$261,'RESUMO-CURVA PREV'!B11,'RESUMO-CURVA GRÁFICO'!$AC$4:$AC$261) -> 237025.32
A12: 224 | B12: 225 | C12: 2.15 | D12: ="TRANSPORTE DE EQUIPAMENTOS" -> TRANSPORTE DE EQUIPAMENTOS | E12: =I12 -> 270788.7 | F12: =J12 -> 0 | G12: 12 | H12: =SUMIF('RESUMO-CURVA GRÁFICO'!$B$4:$B$261,'RESUMO-CURVA PREV'!B12,'RESUMO-CURVA GRÁFICO'!$AD$4:$AD$261) -> 0 | I12: =SUMIF('RESUMO-CURVA GRÁFICO'!$B$4:$B$261,'RESUMO-CURVA PREV'!A12,'RESUMO-CURVA GRÁFICO'!$X$4:$X$261) -> 270788.7 | J12: =SUMIF('RESUMO-CURVA GRÁFICO'!$B$4:$B$261,'RESUMO-CURVA PREV'!B12,'RESUMO-CURVA GRÁFICO'!$AC$4:$AC$261) -> 0
A13: 253 | B13: 254 | C13: 3 | D13: ="DESPESAS REEMBOLSÁVEIS" -> DESPESAS REEMBOLSÁVEIS | E13: =I13 -> 337157.91 | F13: =J13 -> 290598.39 | G13: 11 | H13: =SUMIF('RESUMO-CURVA GRÁFICO'!$B$4:$B$261,'RESUMO-CURVA PREV'!B13,'RESUMO-CURVA GRÁFICO'!$AD$4:$AD$261) -> 0.86190591 | I13: =SUMIF('RESUMO-CURVA GRÁFICO'!$B$4:$B$261,'RESUMO-CURVA PREV'!A13,'RESUMO-CURVA GRÁFICO'!$X$4:$X$261) -> 337157.91 | J13: =SUMIF('RESUMO-CURVA GRÁFICO'!$B$4:$B$261,'RESUMO-CURVA PREV'!B13,'RESUMO-CURVA GRÁFICO'!$AC$4:$AC$261) -> 290598.39
A14: 84 | B14: 85 | C14: 2.1 | D14: ="VIAGENS" -> VIAGENS | E14: =I14 -> 382021.68 | F14: =J14 -> 95210.78 | G14: 10 | H14: =SUMIF('RESUMO-CURVA GRÁFICO'!$B$4:$B$261,'RESUMO-CURVA PREV'!B14,'RESUMO-CURVA GRÁFICO'!$AD$4:$AD$261) -> 0.24922873 | I14: =SUMIF('RESUMO-CURVA GRÁFICO'!$B$4:$B$261,'RESUMO-CURVA PREV'!A14,'RESUMO-CURVA GRÁFICO'!$X$4:$X$261) -> 382021.68 | J14: =SUMIF('RESUMO-CURVA GRÁFICO'!$B$4:$B$261,'RESUMO-CURVA PREV'!B14,'RESUMO-CURVA GRÁFICO'!$AC$4:$AC$261) -> 95210.78
A15: 204 | B15: 205 | C15: 2.10 | D15: ="SOBRESSALENTES - ELÉTRICA" -> SOBRESSALENTES - ELÉTRICA | E15: =I15 -> 426502.25 | F15: =J15 -> 155801.5 | G15: 9 | H15: =SUMIF('RESUMO-CURVA GRÁFICO'!$B$4:$B$261,'RESUMO-CURVA PREV'!B15,'RESUMO-CURVA GRÁFICO'!$AD$4:$AD$261) -> 0.36530053 | I15: =SUMIF('RESUMO-CURVA GRÁFICO'!$B$4:$B$261,'RESUMO-CURVA PREV'!A15,'RESUMO-CURVA GRÁFICO'!$X$4:$X$261) -> 426502.25 | J15: =SUMIF('RESUMO-CURVA GRÁFICO'!$B$4:$B$261,'RESUMO-CURVA PREV'!B15,'RESUMO-CURVA GRÁFICO'!$AC$4:$AC$261) -> 155801.5
A16: 208 | B16: 209 | C16: 2.11 | D16: ="SOBRESSALENTES - LINHA DE TRANSMISSÃO" -> SOBRESSALENTES - LINHA DE TRANSMISSÃO | E16: =I16 -> 469086.46 | F16: =J16 -> 5393.04 | G16: 8 | H16: =SUMIF('RESUMO-CURVA GRÁFICO'!$B$4:$B$261,'RESUMO-CURVA PREV'!B16,'RESUMO-CURVA GRÁFICO'!$AD$4:$AD$261) -> 0.0114969 | I16: =SUMIF('RESUMO-CURVA GRÁFICO'!$B$4:$B$261,'RESUMO-CURVA PREV'!A16,'RESUMO-CURVA GRÁFICO'!$X$4:$X$261) -> 469086.46 | J16: =SUMIF('RESUMO-CURVA GRÁFICO'!$B$4:$B$261,'RESUMO-CURVA PREV'!B16,'RESUMO-CURVA GRÁFICO'!$AC$4:$AC$261) -> 5393.04
A17: 126 | B17: 127 | C17: 2.4 | D17: ="ESCRITÓRIO" -> ESCRITÓRIO | E17: =I17 -> 518209.68 | F17: =J17 -> 518209.68 | G17: 7 | H17: =SUMIF('RESUMO-CURVA GRÁFICO'!$B$4:$B$261,'RESUMO-CURVA PREV'!B17,'RESUMO-CURVA GRÁFICO'!$AD$4:$AD$261) -> 1 | I17: =SUMIF('RESUMO-CURVA GRÁFICO'!$B$4:$B$261,'RESUMO-CURVA PREV'!A17,'RESUMO-CURVA GRÁFICO'!$X$4:$X$261) -> 518209.68 | J17: =SUMIF('RESUMO-CURVA GRÁFICO'!$B$4:$B$261,'RESUMO-CURVA PREV'!B17,'RESUMO-CURVA GRÁFICO'!$AC$4:$AC$261) -> 518209.68
A18: 142 | B18: 143 | C18: 2.5 | D18: ="SISTEMA DE RÁDIO COMUNICAÇÃO" -> SISTEMA DE RÁDIO COMUNICAÇÃO | E18: =I18 -> 528013.08 | F18: =J18 -> 492055.56 | G18: 6 | H18: =SUMIF('RESUMO-CURVA GRÁFICO'!$B$4:$B$261,'RESUMO-CURVA PREV'!B18,'RESUMO-CURVA GRÁFICO'!$AD$4:$AD$261) -> 0.93190032 | I18: =SUMIF('RESUMO-CURVA GRÁFICO'!$B$4:$B$261,'RESUMO-CURVA PREV'!A18,'RESUMO-CURVA GRÁFICO'!$X$4:$X$261) -> 528013.08 | J18: =SUMIF('RESUMO-CURVA GRÁFICO'!$B$4:$B$261,'RESUMO-CURVA PREV'!B18,'RESUMO-CURVA GRÁFICO'!$AC$4:$AC$261) -> 492055.56
A19: 158 | B19: 159 | C19: 2.6 | D19: ="INSTALAÇÃO DA EQUIPE" -> INSTALAÇÃO DA EQUIPE | E19: =I19 -> 685215 | F19: =J19 -> 685214.34 | G19: 5 | H19: =SUMIF('RESUMO-CURVA GRÁFICO'!$B$4:$B$261,'RESUMO-CURVA PREV'!B19,'RESUMO-CURVA GRÁFICO'!$AD$4:$AD$261) -> 0.99999905 | I19: =SUMIF('RESUMO-CURVA GRÁFICO'!$B$4:$B$261,'RESUMO-CURVA PREV'!A19,'RESUMO-CURVA GRÁFICO'!$X$4:$X$261) -> 685215 | J19: =SUMIF('RESUMO-CURVA GRÁFICO'!$B$4:$B$261,'RESUMO-CURVA PREV'!B19,'RESUMO-CURVA GRÁFICO'!$AC$4:$AC$261) -> 685214.34
A20: 166 | B20: 167 | C20: 2.7 | D20: ="EQUIPAMENTOS PARA MANUTENÇÃO ELÉTRICA" -> EQUIPAMENTOS PARA MANUTENÇÃO ELÉTRICA | E20: =I20 -> 4591811.1 | F20: =J20 -> 4591811.1 | G20: 4 | H20: =SUMIF('RESUMO-CURVA GRÁFICO'!$B$4:$B$261,'RESUMO-CURVA PREV'!B20,'RESUMO-CURVA GRÁFICO'!$AD$4:$AD$261) -> 1 | I20: =SUMIF('RESUMO-CURVA GRÁFICO'!$B$4:$B$261,'RESUMO-CURVA PREV'!A20,'RESUMO-CURVA GRÁFICO'!$X$4:$X$261) -> 4591811.1 | J20: =SUMIF('RESUMO-CURVA GRÁFICO'!$B$4:$B$261,'RESUMO-CURVA PREV'!B20,'RESUMO-CURVA GRÁFICO'!$AC$4:$AC$261) -> 4591811.1
A21: 112 | B21: 113 | C21: 2.3 | D21: ="VEÍCULOS, COMBUSTÍVEL E MANUTENÇÃO" -> VEÍCULOS, COMBUSTÍVEL E MANUTENÇÃO | E21: =I21 -> 3783418.9 | F21: =J21 -> 3720309.9 | G21: 3 | H21: =SUMIF('RESUMO-CURVA GRÁFICO'!$B$4:$B$261,'RESUMO-CURVA PREV'!B21,'RESUMO-CURVA GRÁFICO'!$AD$4:$AD$261) -> 0.98331958 | I21: =SUMIF('RESUMO-CURVA GRÁFICO'!$B$4:$B$261,'RESUMO-CURVA PREV'!A21,'RESUMO-CURVA GRÁFICO'!$X$4:$X$261) -> 3783418.9 | J21: =SUMIF('RESUMO-CURVA GRÁFICO'!$B$4:$B$261,'RESUMO-CURVA PREV'!B21,'RESUMO-CURVA GRÁFICO'!$AC$4:$AC$261) -> 3720309.9
A22: 78 | B22: 79 | C22: 1 | D22: ="RESUMO DA MÃO DE OBRA" -> RESUMO DA MÃO DE OBRA | E22: =I22 -> 18310884 | F22: =J22 -> 16541555 | G22: 1 | H22: =SUMIF('RESUMO-CURVA GRÁFICO'!$B$4:$B$261,'RESUMO-CURVA PREV'!B22,'RESUMO-CURVA GRÁFICO'!$AD$4:$AD$261) -> 0.90337283 | I22: =SUMIF('RESUMO-CURVA GRÁFICO'!$B$4:$B$261,'RESUMO-CURVA PREV'!A22,'RESUMO-CURVA GRÁFICO'!$X$4:$X$261) -> 18310884 | J22: =SUMIF('RESUMO-CURVA GRÁFICO'!$B$4:$B$261,'RESUMO-CURVA PREV'!B22,'RESUMO-CURVA GRÁFICO'!$AC$4:$AC$261) -> 16541555
A23: 249 | B23: 250 | C23: 2 | D23: ="CUSTOS DIRETOS" -> CUSTOS DIRETOS | E23: =I23 -> 12317953 | F23: =J23 -> 10858667 | G23: 2 | H23: =SUMIF('RESUMO-CURVA GRÁFICO'!$B$4:$B$261,'RESUMO-CURVA PREV'!B23,'RESUMO-CURVA GRÁFICO'!$AD$4:$AD$261) -> 0.88153181 | I23: =SUMIF('RESUMO-CURVA GRÁFICO'!$B$4:$B$261,'RESUMO-CURVA PREV'!A23,'RESUMO-CURVA GRÁFICO'!$X$4:$X$261) -> 12317953 | J23: =SUMIF('RESUMO-CURVA GRÁFICO'!$B$4:$B$261,'RESUMO-CURVA PREV'!B23,'RESUMO-CURVA GRÁFICO'!$AC$4:$AC$261) -> 10858667
E24: =SUM(E4:E12,E14:E21,E22,E13) -> 30965995 | F24: =SUM(F4:F12,F14:F21,F22,F13) -> 27690821 | H24: =F24/E24 -> 0.89423321 | I24: =SUM(I4:I12,I14:I21,I22,I13) -> 30965995 | J24: =SUM(J4:J12,J14:J21,J22,J13) -> 27690821
E25: =E24-I24 -> 0 | F25: =F24-J24 -> 0 | I25: =I24-'Evolução Mensal'!AR12 -> 7.3425472e-06 | J25: =J24-'Evolução Mensal'!AR13 -> 11801040

Sheet GRÁFICO

Sheet Evolução Mensal
AD2: EVOLUÇÃO MENSAL DO CONTRATO POR TIPO DE DESPESA
AD3: 2025 / 2026
E4: 1 | F4: 2 | G4: 3 | H4: 4 | I4: 5 | J4: 6 | K4: 7 | L4: 8 | M4: 9 | N4: 10 | O4: 11 | P4: 12 | Q4: 24.1 | R4: 25 | S4: 26 | T4: 27 | U4: 28 | V4: 29 | W4: 30 | X4: 31 | Y4: 32 | Z4: 33 | AA4: 34 | AB4: 35 | AC4: 36 | AD4: 36.1 | AE4: 37 | AF4: 38 | AG4: 39 | AH4: 40 | AI4: 41 | AJ4: 42 | AK4: 43 | AL4: 44 | AM4: 45 | AN4: 46 | AO4: 47 | AP4: 48 | AQ4: 49
B5: ITEM | E5: 44774 | F5: 44805 | G5: 44835 | H5: 44866 | I5: 44896 | J5: 44927 | K5: 44958 | L5: 44986 | M5: 45017 | N5: 45047 | O5: 45078 | P5: 45108 | Q5: 45474 | R5: 45505 | S5: 45536 | T5: 45566 | U5: 45597 | V5: 45627 | W5: 45658 | X5: 45689 | Y5: 45717 | Z5: 45748 | AA5: 45778 | AB5: 45809 | AC5: 45839 | AD5: 45839 | AE5: 45870 | AF5: 45901 | AG5: 45931 | AH5: 45962 | AI5: 45992 | AJ5: 46023 | AK5: 46054 | AL5: 46082 | AM5: 46113 | AN5: 46143 | AO5: 46174 | AP5: 46204 | AQ5: 46235
B6: MÃO DE OBRA | C6: P | D6: PREVISTO | E6: 1037503.2 | F6: 1556254.8 | G6: 1556254.8 | H6: 1556254.8 | I6: 1556254.8 | J6: 1556254.8 | K6: 1556254.8 | L6: 1556254.8 | M6: 1556254.8 | N6: 1556254.8 | O6: 1556254.8 | P6: =1556254.78727273/30*10 -> 518751.6 | Q6: 1269132.2 | R6: 1586415.3 | S6: 1586415.3 | T6: 1586415.3 | U6: =$AO6 -> 1525907 | V6: 1586415.3 | W6: 1586415.3 | X6: 1586415.3 | Y6: 1586415.3 | Z6: 1586415.3 | AA6: 1586415.3 | AB6: 1586415.3 | AC6: 317283.06 | AD6: 1220725.6 | AE6: 1525907 | AF6: =$AT6 -> 1525907 | AG6: 1525907 | AH6: 1525907 | AI6: 1525907 | AJ6: 1525907 | AK6: =$AT6 -> 1525907 | AL6: =$AT6 -> 1525907 | AM6: =$AT6 -> 1525907 | AN6: =$AT6 -> 1525907 | AO6: =$AT6 -> 1525907 | AP6: =$AU$6 -> 305181.4 | AR6: =SUM(AD6:AP6) -> 18310884 | AS6: 18310884 | AT6: =AS6/12 -> 1525907 | AU6: =AT6/30*6 -> 305181.4 | AV6: =AT6/30*24 -> 1220725.6 | AW6: =SUM(AU6:AV6) -> 1525907
C7: R | D7: REALIZADO | E7: 46913.72 | F7: 406924.85 | G7: 463411.74 | H7: 529425.99 | I7: 549858.83 | J7: 595088.38 | K7: 1199430.9 | L7: 1362135.9 | M7: 1460872.3 | N7: 1319827.1 | O7: 1270484.2 | P7: ='[1]Preços e Quantidades'!$G$152 -> 1432552.8 | Q7: 996036.25 | R7: 1250732.7 | S7: 1280533.1 | T7: 1282102 | U7: 1283823.9 | V7: 1213630.5 | W7: 1231114.9 | X7: 1290820.6 | Y7: 1233378.5 | Z7: 1246962.9 | AA7: 1351334.4 | AB7: 1290728 | AC7: 274952.27 | AD7: 1036060.1 | AE7: 1403557.9 | AF7: ='[1]Preços e Quantidades'!$G$152 -> 1432552.8 | AG7: 1439360.9 | AH7: 1411640.5 | AI7: 1361814.4 | AJ7: 1322567.1 | AR7: =SUM(AD7:AP7) -> 9407553.8
B8: CUSTO DIRETO | C8: P | D8: PREVISTO | E8: 489032.69 | F8: 733549.04 | G8: 733549.04 | H8: 733549.04 | I8: 733549.04 | J8: 733549.04 | K8: 733549.04 | L8: 733549.04 | M8: 733549.04 | N8: 733549.04 | O8: 733549.04 | P8: =733549.038763636/30*10 -> 244516.35 | Q8: 755607.11 | R8: 944508.88 | S8: 944508.88 | T8: 944508.88 | U8: 944508.88 | V8: 944508.88 | W8: 944508.88 | X8: 944508.88 | Y8: 944508.88 | Z8: 944508.88 | AA8: 944508.88 | AB8: 944508.88 | AC8: 188901.78 | AD8: 821196.85 | AE8: 1026496.1 | AF8: =$AT8 -> 1026496.1 | AG8: 1026496.1 | AH8: 1026496.1 | AI8: 1026496.1 | AJ8: 1026496.1 | AK8: =$AT8 -> 1026496.1 | AL8: =$AT8 -> 1026496.1 | AM8: =$AT8 -> 1026496.1 | AN8: =$AT8 -> 1026496.1 | AO8: =$AT8 -> 1026496.1 | AP8: =$AU$8 -> 205299.21 | AR8: =SUM(AD8:AP8) -> 12317953 | AS8: 12317953 | AT8: =AS8/12 -> 1026496.1 | AU8: =AT8/30*6 -> 205299.21 | AV8: =AT8/30*24 -> 821196.85 | AW8: =SUM(AU8:AV8) -> 1026496.1
C9: R | D9: REALIZADO | E9: 116828.3 | F9: 201832.13 | G9: 228734.68 | H9: 227639.39 | I9: 230252.11 | J9: 237781.55 | K9: 330763.36 | L9: 369581.69 | M9: 396822.38 | N9: 407746.22 | O9: 406407.33 | P9: ='[1]Preços e Quantidades'!$G$153 -> 907395.95 | Q9: 613563.97 | R9: 758419.44 | S9: 873330.12 | T9: 796004.1 | U9: 802132.21 | V9: 792488.11 | W9: 817526.81 | X9: 810848.35 | Y9: 789206.22 | Z9: 793343.79 | AA9: 798539.9 | AB9: 836013.31 | AC9: 161912.89 | AD9: 720189.1 | AE9: 970056.98 | AF9: ='[1]Preços e Quantidades'!$G$153 -> 907395.95 | AG9: 994206.55 | AH9: 898971.07 | AI9: 919039.37 | AJ9: 902852.48 | AR9: =SUM(AD9:AP9) -> 6312711.5
B10: DESPESAS REEMBOLSÁVEIS | C10: P | D10: PREVISTO | E10: 20433.813 | F10: 30650.719 | G10: 30650.719 | H10: 30650.719 | I10: 30650.719 | J10: 30650.719 | K10: 30650.719 | L10: 30650.719 | M10: 30650.719 | N10: 30650.719 | O10: 30650.719 | P10: =30650.7190909091/30*10 -> 10216.906 | Q10: 22477.194 | R10: 28096.493 | S10: 28096.493 | T10: 28096.493 | U10: 28096.493 | V10: 28096.493 | W10: 28096.493 | X10: 28096.493 | Y10: 28096.493 | Z10: 28096.493 | AA10: 28096.493 | AB10: 28096.493 | AC10: 5619.2985 | AD10: 22477.194 | AE10: 28096.493 | AF10: =$AT10 -> 28096.493 | AG10: 28096.493 | AH10: 28096.493 | AI10: 28096.493 | AJ10: 28096.493 | AK10: =$AT10 -> 28096.493 | AL10: =$AT10 -> 28096.493 | AM10: =$AT10 -> 28096.493 | AN10: =$AT10 -> 28096.493 | AO10: =$AT10 -> 28096.493 | AP10: =$AU$10 -> 5619.2985 | AR10: =SUM(AD10:AP10) -> 337157.91 | AS10: 337157.91 | AT10: =AS10/12 -> 28096.493 | AU10: =AT10/30*6 -> 5619.2985 | AV10: =AT10/30*24 -> 22477.194 | AW10: =SUM(AU10:AV10) -> 28096.493
C11: R | D11: REALIZADO | E11: 0 | F11: 0 | G11: 0 | H11: 0 | I11: 3713.87 | J11: 62182.99 | K11: 2726.21 | L11: 14037.6 | M11: 96542.9 | N11: 604 | O11: 66515.35 | P11: ='[1]Preços e Quantidades'!$G$154 -> 78759.74 | Q11: 800 | R11: 0 | S11: 48628.64 | T11: 112440 | U11: 138841.77 | V11: 0 | W11: 0 | X11: 0 | Y11: 8366.53 | Z11: 14783.48 | AA11: 7150 | AB11: 6068.25 | AC11: 0 | AD11: 0 | AE11: 0 | AF11: ='[1]Preços e Quantidades'!$G$154 -> 78759.74 | AG11: 6211.55 | AH11: 38256.14 | AI11: 38488.3 | AJ11: 7800 | AR11: =SUM(AD11:AP11) -> 169515.73
B12: TOTAL MENSAL | C12: P | D12: PREVISTO | E12: =SUM(E10,E8,E6) -> 1546969.7 | F12: =SUM(F10,F8,F6) -> 2320454.5 | G12: =SUM(G10,G8,G6) -> 2320454.5 | H12: =SUM(H10,H8,H6) -> 2320454.5 | I12: =SUM(I10,I8,I6) -> 2320454.5 | J12: =SUM(J10,J8,J6) -> 2320454.5 | K12: =SUM(K10,K8,K6) -> 2320454.5 | L12: =SUM(L10,L8,L6) -> 2320454.5 | ... AP12: =SUM(AP10,AP8,AP6) -> 516099.91 | AR12: =SUM(AD12:AP12) -> 30965995
C13: R | D13: REALIZADO | E13: =SUM(E11,E9,E7) -> 163742.02 | F13: =SUM(F11,F9,F7) -> 608756.98 | G13: =SUM(G11,G9,G7) -> 692146.42 | H13: =SUM(H11,H9,H7) -> 757065.38 | I13: =SUM(I11,I9,I7) -> 783824.8 | J13: =SUM(J11,J9,J7) -> 895052.92 | K13: =SUM(K11,K9,K7) -> 1532920.5 | L13: =SUM(L11,L9,L7) -> 1745755.2 | ... AP13: =SUM(AP11,AP9,AP7) -> 0 | AR13: =SUM(AD13:AP13) -> 15889781
B14: TOTAL ACUMULADO | C14: P | D14: PREVISTO | E14: =SUM(E10,E8,E6) -> 1546969.7 | F14: =SUM(F10,F8,F6)+E14 -> 3867424.2 | G14: =SUM(G10,G8,G6)+F14 -> 6187878.8 | H14: =SUM(H10,H8,H6)+G14 -> 8508333.3 | I14: =SUM(I10,I8,I6)+H14 -> 10828788 | J14: =SUM(J10,J8,J6)+I14 -> 13149242 | K14: =SUM(K10,K8,K6)+J14 -> 15469697 | L14: =SUM(L10,L8,L6)+K14 -> 17790152 | M14: =SUM(M10,M8,M6)+L14 -> 20110606 | ... P14: =SUM(P10,P8,P6)+O14 -> 25525000 | Q14: =SUM(Q10,Q8,Q6) -> 2047216.5 | R14: =SUM(R10,R8,R6)+Q14 -> 4606237.2 | S14: =SUM(S10,S8,S6)+R14 -> 7165257.9 | T14: =SUM(T10,T8,T6)+S14 -> 9724278.5 | U14: =SUM(U10,U8,U6)+T14 -> 12222791 | V14: =SUM(V10,V8,V6)+U14 -> 14781812 | W14: =SUM(W10,W8,W6)+V14 -> 17340832 | X14: =SUM(X10,X8,X6)+W14 -> 19899853 | Y14: =SUM(Y10,Y8,Y6)+X14 -> 22458874 | ... AC14: =SUM(AC10,AC8,AC6)+AB14 -> 30647740 | AD14: =SUM(AD10,AD8,AD6) -> 2064399.6 | AE14: =SUM(AE10,AE8,AE6)+AD14 -> 4644899.2 | AF14: =SUM(AF10,AF8,AF6)+AE14 -> 7225398.8 | AG14: =SUM(AG10,AG8,AG6)+AF14 -> 9805898.3 | AH14: =SUM(AH10,AH8,AH6)+AG14 -> 12386398 | AI14: =SUM(AI10,AI8,AI6)+AH14 -> 14966897 | AJ14: =SUM(AJ10,AJ8,AJ6)+AI14 -> 17547397 | AK14: =SUM(AK10,AK8,AK6)+AJ14 -> 20127897 | AL14: =SUM(AL10,AL8,AL6)+AK14 -> 22708396 | ... AP14: =SUM(AP10,AP8,AP6)+AO14 -> 30965995
C15: R | D15: REALIZADO | E15: =SUM(E11,E9,E7) -> 163742.02 | F15: =E15+F13 -> 772499 | G15: =F15+G13 -> 1464645.4 | H15: =G15+H13 -> 2221710.8 | I15: =H15+I13 -> 3005535.6 | J15: =I15+J13 -> 3900588.5 | K15: =J15+K13 -> 5433509 | L15: =K15+L13 -> 7179264.1 | M15: =L15+M13 -> 9133501.7 | ... P15: =O15+P13 -> 15023794 | Q15: =Q13 -> 1610400.2 | R15: =Q15+R13 -> 3619552.4 | S15: =R15+S13 -> 5822044.3 | T15: =S15+T13 -> 8012590.3 | U15: =T15+U13 -> 10237388 | V15: =U15+V13 -> 12243507 | W15: =V15+W13 -> 14292149 | X15: =W15+X13 -> 16393817 | Y15: =X15+Y13 -> 18424769 | ... AC15: =AB15+AC13 -> 25206558 | AD15: =AD13 -> 1756249.2 | AE15: =AD15+AE13 -> 4129864.1 | AF15: =AE15+AF13 -> 6548572.6 | AG15: =AF15+AG13 -> 8988351.6 | AH15: =AG15+AH13 -> 11337219 | AI15: =AH15+AI13 -> 13656561 | AJ15: =AI15+AJ13 -> 15889781
R48: Previsto Mensal | U48: Realizado Mensal | X48: Previsto Acumulado | AB48: Realizado Acumulado
U53: 10178229
U54: =U53-V15 -> -2065277.8

Sheet RESUMO-CURVA GRÁFICO
D1: PLANILHA REFERENCIAL DE PREÇOS - RESUMO (COM DESONERAÇÃO) | Z1: NÃO MEDIDOS
D2: Item | E2: Descrição | F2: Classe | H2: % | I2: Meses | V2: Quantidade | W2: Preço Unitário | X2: Preço Total | Y2: PERCENTUAL MEDIDO | Z2: =SUM(Z5:Z258) -> 3228614.5 | AB2: Média Mensal | AC2: Projeção R$ | AD2: Projeção %
I3: 36.1 | J3: 37 | K3: 38 | L3: 39 | M3: 40 | N3: 41 | O3: 42 | P3: 43 | Q3: 44 | R3: 45 | S3: 46 | T3: 47 | U3: 48 | AB3: x 12 meses | AC3: 12 meses | AD3: 12 meses
I4: jul | J4: ago | K4: set | L4: out | M4: nov | N4: dez | O4: jan | P4: fev | Q4: mar | R4: abr | S4: mai | T4: jun | U4: jul
B5: 1 | C5: PREV | D5: 1 | E5: RESUMO DA MÃO DE OBRA | Y5: =Y6 -> 0.51376841
B6: 2 | C6: REAL | D6: 1 | E6: RESUMO DA MÃO DE OBRA | Y6: =Y83 -> 0.51376841 | AC6: =SUM(AC8:AC80) -> 16541555 | AD6: =AC6/X82 -> 0.90337283 | AE6: 1 | AF6: 1 | AG6: 1 | AH6: 1
B7: 3 | C7: PREV | D7: 1.1 | E7: Consultor Especializado | F7: P8060 | G7: =C7&E7 -> PREVConsultor Especializado | H7: =Y7 | I7: 0.4 | J7: 0.5 | K7: 0.5 | L7: 0.5 | M7: 0.5 | N7: 0.5 | O7: 0.5 | P7: 0.5 | Q7: 0.5 | R7: 0.5 | S7: 0.5 | T7: 0.5 | U7: 0.1 | V7: =SUM(I7:U7) -> 6 | W7: 24703.45 | X7: =W7*V7 -> 148220.7 | AL7: Consultor Especializado
B8: 4 | C8: REAL | D8: 1.1 | E8: Consultor Especializado | F8: P8060 | G8: =C8&E8 -> REALConsultor Especializado | H8: =Y8 -> 0 | I8: 0 | J8: 0 | K8: 0 | L8: 0 | M8: 0 | N8: 0 | O8: 0 | V8: =SUM(I8:U8) -> 0 | W8: 24703.45 | X8: =W8*V8 -> 0 | Y8: =X8/X7 -> 0 | Z8: =X7-AC8 -> 148220.7 | AB8: =ROUND((AVERAGE(J8:T8)*12),1) -> 0 | AC8: =IF(AB8*W8>X7,X7,AB8*W8) -> 0 | AD8: =AC8/X7 -> 0 | AL8: Almoxarife
B9: 5 | C9: PREV | D9: 1.2 | E9: Almoxarife | F9: P9803 | G9: =C9&E9 -> PREVAlmoxarife | H9: =Y9 | I9: 1.6 | J9: 2 | K9: 2 | L9: 2 | M9: 2 | N9: 2 | O9: 2 | P9: 2 | Q9: 2 | R9: 2 | S9: 2 | T9: 2 | U9: 0.4 | V9: =SUM(I9:U9) -> 24 | W9: 5580.99 | X9: =W9*V9 -> 133943.76 | AL9: Auxiliar Administrativo
B10: 6 | C10: REAL | D10: 1.2 | E10: Almoxarife | F10: P9803 | G10: =C10&E10 -> REALAlmoxarife | H10: =Y10 -> 0.24166667 | I10: 0.8 | J10: 0.066666667 | K10: 0.93333333 | L10: 1 | M10: 1 | N10: 1 | O10: 1 | V10: =SUM(I10:U10) -> 5.8 | W10: 5580.99 | X10: =W10*V10 -> 32369.742 | Y10: =X10/X9 -> 0.24166667 | Z10: =X9-AC10 -> 78133.86 | AB10: =ROUND((AVERAGE(J10:T10)*12),1) -> 10 | AC10: =IF(AB10*W10>X9,X9,AB10*W10) -> 55809.9 | AD10: =AC10/X9 -> 0.41666667 | AL10: Técnico Administrativo
B11: 7 | C11: PREV | D11: 1.3 | E11: Auxiliar Administrativo | F11: P9806 | G11: =C11&E11 -> PREVAuxiliar Administrativo | H11: =Y11 | I11: 0.8 | J11: 1 | K11: 1 | L11: 1 | M11: 1 | N11: 1 | O11: 1 | P11: 1 | Q11: 1 | R11: 1 | S11: 1 | T11: 1 | U11: 0.2 | V11: =SUM(I11:U11) -> 12 | W11: 4487.35 | X11: =W11*V11 -> 53848.2 | AL11: Técnico Pleno - Encarregado - Com Periculosidade
B12: 8 | C12: REAL | D12: 1.3 | E12: Auxiliar Administrativo | F12: P9806 | G12: =C12&E12 -> REALAuxiliar Administrativo | H12: =Y12 -> 0.56666667 | I12: 0.8 | J12: 1 | K12: 1 | L12: 1 | M12: 1 | N12: 1 | O12: 1 | V12: =SUM(I12:U12) -> 6.8 | W12: 4487.35 | X12: =W12*V12 -> 30513.98 | Y12: =X12/X11 -> 0.56666667 | Z12: =X11-AC12 -> 0 | AB12: =ROUND((AVERAGE(J12:T12)*12),1) -> 12 | AC12: =IF(AB12*W12>X11,X11,AB12*W12) -> 53848.2 | AD12: =AC12/X11 -> 1 | AL12: Engenheiro Pleno - Eletricista - Telecomunicações - Com Periculosidade
B13: 9 | C13: PREV | D13: 1.4 | E13: Técnico Administrativo | F13: P9809 | G13: =C13&E13 -> PREVTécnico Administrativo | H13: =Y13 | I13: 1.6 | J13: 2 | K13: 2 | L13: 2 | M13: 2 | N13: 2 | O13: 2 | P13: 2 | Q13: 2 | R13: 2 | S13: 2 | T13: 2 | U13: 0.4 | V13: =SUM(I13:U13) -> 24 | W13: 7072.06 | X13: =W13*V13 -> 169729.44 | AL13: Engenheiro Sênior - Proteção e Controle / Eletricista - Coord - Com Periculosidade
B14: 10 | C14: REAL | D14: 1.4 | E14: Técnico Administrativo | F14: P9809 | G14: =C14&E14 -> REALTécnico Administrativo | H14: =Y14 -> 0.51388889 | I14: 0.83333333 | J14: 2 | K14: 2 | L14: 2 | M14: 2 | N14: 2 | O14: 1.5 | V14: =SUM(I14:U14) -> 12.333333 | W14: 7072.06 | X14: =W14*V14 -> 87222.073 | Y14: =X14/X13 -> 0.51388889 | Z14: =X13-AC14 -> 7072.06 | AB14: =ROUND((AVERAGE(J14:T14)*12),1) -> 23 | AC14: =IF(AB14*W14>X13,X13,AB14*W14) -> 162657.38 | AD14: =AC14/X13 -> 0.95833333 | AL14: Vigia (12X36) - Diurno
B15: 11 | C15: PREV | D15: 1.5 | E15: Técnico Pleno - Encarregado - Com Periculosidade | F15: P9811 (*) | G15: =C15&E15 -> PREVTécnico Pleno - Encarregado - Com Periculosidade | H15: =Y15 | I15: 3.2 | J15: 4 | K15: 4 | L15: 4 | M15: 4 | N15: 4 | O15: 4 | P15: 4 | Q15: 4 | R15: 4 | S15: 4 | T15: 4 | U15: 0.8 | V15: =SUM(I15:U15) -> 48 | W15: 7821.94 | X15: =W15*V15 -> 375453.12 | AL15: Vigia (12x36) - Noturno
B16: 12 | C16: REAL | D16: 1.5 | E16: Técnico Pleno - Encarregado - Com Periculosidade | F16: P9811 (*) | G16: =C16&E16 -> REALTécnico Pleno - Encarregado - Com Periculosidade | H16: =Y16 -> 0.63402778 | I16: 4 | J16: 5 | K16: 5 | L16: 3.9666667 | M16: 4.5333333 | N16: 3.9666667 | O16: 3.9666667 | V16: =SUM(I16:U16) -> 30.433333 | W16: 7821.94 | X16: =W16*V16 -> 238047.71 | Y16: =X16/X15 -> 0.63402778 | Z16: =X15-AC16 -> 0 | AB16: =ROUND((AVERAGE(J16:T16)*12),1) -> 52.9 | AC16: =IF(AB16*W16>X15,X15,AB16*W16) -> 375453.12 | AD16: =AC16/X15 -> 1 | AL16: Eletromecânico - Montador - Com Periculosidade
B17: 13 | C17: PREV | D17: 1.6 | E17: Engenheiro Pleno - Eletricista - Telecomunicações - Com Periculosidade | F17: P9812 (*) | G17: =C17&E17 -> PREVEngenheiro Pleno - Eletricista - Telecomunicações - Com Periculosidade | H17: =Y17 | I17: 1.6 | J17: 2 | K17: 2 | L17: 2 | M17: 2 | N17: 2 | O17: 2 | P17: 2 | Q17: 2 | R17: 2 | S17: 2 | T17: 2 | U17: 0.4 | V17: =SUM(I17:U17) -> 24 | W17: 27055.66 | X17: =W17*V17 -> 649335.84 | AL17: Médico
B18: 14 | C18: REAL | D18: 1.6 | E18: Engenheiro Pleno - Eletricista - Telecomunicações - Com Periculosidade | F18: P9812 (*) | G18: =C18&E18 -> REALEngenheiro Pleno - Eletricista - Telecomunicações - Com Periculosidade | H18: =Y18 -> 0.53055556 | I18: 1.1333333 | J18: 2 | K18: 2 | L18: 2 | M18: 2 | N18: 2 | O18: 1.6 | V18: =SUM(I18:U18) -> 12.733333 | W18: 27055.66 | X18: =W18*V18 -> 344508.74 | Y18: =X18/X17 -> 0.53055556 | Z18: =X17-AC18 -> 21644.528 | AB18: =ROUND((AVERAGE(J18:T18)*12),1) -> 23.2 | AC18: =IF(AB18*W18>X17,X17,AB18*W18) -> 627691.31 | AD18: =AC18/X17 -> 0.96666667 | AL18: Engenheiro Pleno - Segurança do Trabalho
B19: 15 | C19: PREV | D19: 1.8 | E19: Engenheiro Sênior - Proteção e Controle / Eletricista - Coord - Com Periculosidade | F19: P9819 (*) | G19: =C19&E19 -> PREVEngenheiro Sênior - Proteção e Controle / Eletricista - Coord - Com Periculosidade | H19: =Y19 | I19: 4 | J19: 5 | K19: 5 | L19: 5 | M19: 5 | N19: 5 | O19: 5 | P19: 5 | Q19: 5 | R19: 5 | S19: 5 | T19: 5 | U19: 1 | V19: =SUM(I19:U19) -> 60 | W19: 27055.66 | X19: =W19*V19 -> 1623339.6 | AL19: Técnico Sênior - TI / Eletrotécnico (12X36) - Diurno
B20: 16 | C20: REAL | D20: 1.8 | E20: Engenheiro Sênior - Proteção e Controle / Eletricista - Coord - Com Periculosidade | F20: P9819 (*) | G20: =C20&E20 -> REALEngenheiro Sênior - Proteção e Controle / Eletricista - Coord - Com Periculosidade | H20: =Y20 -> 0.47847233 | I20: 2.4 | J20: 4.3666667 | K20: 4.7683346 | L20: 4.7683346 | M20: 4.4683346 | N20: 4.5683346 | O20: 3.3683346 | V20: =SUM(I20:U20) -> 28.70834 | W20: 27055.66 | X20: =W20*V20 -> 776723.07 | Y20: =X20/X19 -> 0.47847233 | Z20: =X19-AC20 -> 200211.88 | AB20: =ROUND((AVERAGE(J20:T20)*12),1) -> 52.6 | AC20: =IF(AB20*W20>X19,X19,AB20*W20) -> 1423127.7 | AD20: =AC20/X19 -> 0.87666667 | AL20: Técnico Sênior - Eletrotécnico / Operador de Subest (12X36) - Diurno / Técnico Pleno - Eletromecânico/ Telecomunicações / Eletrotécnico / Eletrônico - Com Periculosidade
B21: 17 | C21: PREV | D21: 1.9 | E21: Vigia (12X36) - Diurno | F21: P9827 | G21: =C21&E21 -> PREVVigia (12X36) - Diurno | H21: =Y21 | I21: 9.6 | J21: 12 | K21: 12 | L21: 12 | M21: 12 | N21: 12 | O21: 12 | P21: 12 | Q21: 12 | R21: 12 | S21: 12 | T21: 12 | U21: 2.4 | V21: =SUM(I21:U21) -> 144 | W21: 4015.53 | X21: =W21*V21 -> 578236.32 | AL21: Técnico Sênior - Eletrotécnico - Noturno / Técnico Pleno - Operador de Subest (12X36) - Noturno
B22: 18 | C22: REAL | D22: 1.9 | E22: Vigia (12X36) - Diurno | F22: P9827 | G22: =C22&E22 -> REALVigia (12X36) - Diurno | H22: =Y22 -> 0.39583333 | I22: 8 | J22: 9 | K22: 8 | L22: 8 | M22: 7.3666667 | N22: 7.7 | O22: 8.9333333 | V22: =SUM(I22:U22) -> 57 | W22: 4015.53 | X22: =W22*V22 -> 228885.21 | Y22: =X22/X21 -> 0.39583333 | Z22: =X21-AC22 -> 184714.38 | AB22: =ROUND((AVERAGE(J22:T22)*12),1) -> 98 | AC22: =IF(AB22*W22>X21,X21,AB22*W22) -> 393521.94 | AD22: =AC22/X21 -> 0.68055556 | AL22: Técnico Sênior - Segurança
B23: 19 | C23: PREV | D23: 1.10 | E23: Vigia (12x36) - Noturno | F23: P9827N | G23: =C23&E23 -> PREVVigia (12x36) - Noturno | H23: =Y23 | I23: 9.6 | J23: 12 | K23: 12 | L23: 12 | M23: 12 | N23: 12 | O23: 12 | P23: 12 | Q23: 12 | R23: 12 | S23: 12 | T23: 12 | U23: 2.4 | V23: =SUM(I23:U23) -> 144 | W23: 5965.92 | X23: =W23*V23 -> 859092.48 | AL23: Secretária
B24: 20 | C24: REAL | D24: 1.10 | E24: Vigia (12x36) - Noturno | F24: P9827N | G24: =C24&E24 -> REALVigia (12x36) - Noturno | H24: =Y24 -> 0.52407407 | I24: 8 | J24: 11 | K24: 12 | L24: 12 | M24: 11.066667 | N24: 11 | O24: 10.4 | V24: =SUM(I24:U24) -> 75.466667 | W24: 5965.92 | X24: =W24*V24 -> 450228.1 | Y24: =X24/X23 -> 0.52407407 | Z24: =X23-AC24 -> 54289.872 | AB24: =ROUND((AVERAGE(J24:T24)*12),1) -> 134.9 | AC24: =IF(AB24*W24>X23,X23,AB24*W24) -> 804802.61 | AD24: =AC24/X23 -> 0.93680556 | AL24: Chefe de Escritório
B25: 21 | C25: PREV | D25: 1.11 | E25: Eletromecânico - Montador - Com Periculosidade | F25: P9830 (*) | G25: =C25&E25 -> PREVEletromecânico - Montador - Com Periculosidade | H25: =Y25 | I25: 6.4 | J25: 8 | K25: 8 | L25: 8 | M25: 8 | N25: 8 | O25: 8 | P25: 8 | Q25: 8 | R25: 8 | S25: 8 | T25: 8 | U25: 1.6 | V25: =SUM(I25:U25) -> 96 | W25: 8508.7 | X25: =W25*V25 -> 816835.2 | AL25: Comprador
B26: 22 | C26: REAL | D26: 1.11 | E26: Eletromecânico - Montador - Com Periculosidade | F26: P9830 (*) | G26: =C26&E26 -> REALEletromecânico - Montador - Com Periculosidade | H26: =Y26 -> 0.44895833 | I26: 4.5 | J26: 5.6 | K26: 7 | L26: 6.5 | M26: 7 | N26: 6.4333333 | O26: 6.0666667 | V26: =SUM(I26:U26) -> 43.1 | W26: 8508.7 | X26: =W26*V26 -> 366724.97 | Y26: =X26/X25 -> 0.44895833 | Z26: =X25-AC26 -> 159963.56 | AB26: =ROUND((AVERAGE(J26:T26)*12),1) -> 77.2 | AC26: =IF(AB26*W26>X25,X25,AB26*W26) -> 656871.64 | AD26: =AC26/X25 -> 0.80416667 | AL26: Eletricista - Com Periculosidade
B27: 23 | C27: PREV | D27: 1.12 | E27: Médico | F27: P9851 | G27: =C27&E27 -> PREVMédico | H27: =Y27 | I27: 0.8 | J27: 1 | K27: 1 | L27: 1 | M27: 1 | N27: 1 | O27: 1 | P27: 1 | Q27: 1 | R27: 1 | S27: 1 | T27: 1 | U27: 0.2 | V27: =SUM(I27:U27) -> 12 | W27: 19815.81 | X27: =W27*V27 -> 237789.72 | AL27: Engenheiro Júnior - Eletricista - Com Periculosidade
B28: 24 | C28: REAL | D28: 1.12 | E28: Médico | F28: P9851 | G28: =C28&E28 -> REALMédico | H28: =Y28 -> 0.4067211 | I28: 0.49823106 | J28: 0.62278882 | K28: 0.75192666 | L28: 0.75192666 | M28: 0.75192666 | N28: 0.75192666 | O28: 0.75192666 | V28: =SUM(I28:U28) -> 4.8806532 | W28: 19815.81 | X28: =W28*V28 -> 96714.096 | Y28: =X28/X27 -> 0.4067211 | Z28: =X27-AC28 -> 63410.592 | AB28: =ROUND((AVERAGE(J28:T28)*12),1) -> 8.8 | AC28: =IF(AB28*W28>X27,X27,AB28*W28) -> 174379.13 | AD28: =AC28/X27 -> 0.73333333 | AL28: Motorista
B29: 25 | C29: PREV | D29: 1.13 | E29: Engenheiro Pleno - Segurança do Trabalho | F29: P9864 (*) | G29: =C29&E29 -> PREVEngenheiro Pleno - Segurança do Trabalho | H29: =Y29 | I29: 0.8 | J29: 1 | K29: 1 | L29: 1 | M29: 1 | N29: 1 | O29: 1 | P29: 1 | Q29: 1 | R29: 1 | S29: 1 | T29: 1 | U29: 0.2 | V29: =SUM(I29:U29) -> 12 | W29: 25688.39 | X29: =W29*V29 -> 308260.68 | AL29: Motorista (12x36) - Noturno
B30: 26 | C30: REAL | D30: 1.13 | E30: Engenheiro Pleno - Segurança do Trabalho | F30: P9864 (*) | G30: =C30&E30 -> REALEngenheiro Pleno - Segurança do Trabalho | H30: =Y30 -> 0.51666667 | I30: 0.8 | J30: 1 | K30: 1 | L30: 0.83333333 | M30: 1 | N30: 1 | O30: 0.56666667 | V30: =SUM(I30:U30) -> 6.2 | W30: 25688.39 | X30: =W30*V30 -> 159268.02 | Y30: =X30/X29 -> 0.51666667 | Z30: =X29-AC30 -> 30826.068 | AB30: =ROUND((AVERAGE(J30:T30)*12),1) -> 10.8 | AC30: =IF(AB30*W30>X29,X29,AB30*W30) -> 277434.61 | AD30: =AC30/X29 -> 0.9 | AL30: Oficial - Pedreiro/Armador/Carpinteiro - Com Periculosidade
B31: 27 | C31: PREV | D31: 1.14 | E31: Técnico Sênior - TI / Eletrotécnico (12X36) - Diurno | F31: P9867 | G31: =C31&E31 -> PREVTécnico Sênior - TI / Eletrotécnico (12X36) - Diurno | H31: =Y31 | I31: 1.6 | J31: 2 | K31: 2 | L31: 2 | M31: 2 | N31: 2 | O31: 2 | P31: 2 | Q31: 2 | R31: 2 | S31: 2 | T31: 2 | U31: 0.4 | V31: =SUM(I31:U31) -> 24 | W31: 6328.66 | X31: =W31*V31 -> 151887.84 | AL31: Servente / Zelador
B32: 28 | C32: REAL | D32: 1.14 | E32: Técnico Sênior - TI / Eletrotécnico (12X36) - Diurno | F32: P9867 | G32: =C32&E32 -> REALTécnico Sênior - TI / Eletrotécnico (12X36) - Diurno | H32: =Y32 -> 0.2625 | I32: 0.8 | J32: 1 | K32: 1 | L32: 0.5 | M32: 1 | N32: 1 | O32: 1 | V32: =SUM(I32:U32) -> 6.3 | W32: 6328.66 | X32: =W32*V32 -> 39870.558 | Y32: =X32/X31 -> 0.2625 | Z32: =X31-AC32 -> 82272.58 | AB32: =ROUND((AVERAGE(J32:T32)*12),1) -> 11 | AC32: =IF(AB32*W32>X31,X31,AB32*W32) -> 69615.26 | AD32: =AC32/X31 -> 0.45833333 | AL32: Servente - Com Periculosidade
B33: 29 | C33: PREV | D33: 1.15 | E33: Técnico Sênior - Eletrotécnico / Operador de Subest (12X36) - Diurno / Técnico Pleno - Eletromecânico/ Telecomunicações / Eletrotécnico / Eletrônico - Com Periculosidade | F33: P9867 (*) | G33: =C33&E33 -> PREVTécnico Sênior - Eletrotécnico / Operador de Subest (12X36) - Diurno / Técnico Pleno - Eletromecânico/ Telecomunicações / Eletrotécnico / Eletrônico - Com Periculosidade | H33: =Y33 | I33: 48 | J33: 60 | K33: 60 | L33: 60 | M33: 60 | N33: 60 | O33: 60 | P33: 60 | Q33: 60 | R33: 60 | S33: 60 | T33: 60 | U33: 12 | V33: =SUM(I33:U33) -> 720 | W33: 8227.26 | X33: =W33*V33 -> 5923627.2 | AL33: Engenheiro Coordenador
B34: 30 | C34: REAL | D34: 1.15 | E34: Técnico Sênior - Eletrotécnico / Operador de Subest (12X36) - Diurno / Técnico Pleno - Eletromecânico/ Telecomunicações / Eletrotécnico / Eletrônico - Com Periculosidade | F34: P9867 (*) | G34: =C34&E34 -> REALTécnico Sênior - Eletrotécnico / Operador de Subest (12X36) - Diurno / Técnico Pleno - Eletromecânico/ Telecomunicações / Eletrotécnico / Eletrônico - Com Periculosidade | H34: =Y34 -> 0.55274738 | I34: 42.373335 | J34: 58.10667 | K34: 59.117146 | L34: 62.561908 | M34: 60.580956 | N34: 56.20286 | O34: 59.035241 | V34: =SUM(I34:U34) -> 397.97812 | W34: 8227.26 | X34: =W34*V34 -> 3274269.4 | Y34: =X34/X33 -> 0.55274738 | Z34: =X33-AC34 -> 72399.888 | AB34: =ROUND((AVERAGE(J34:T34)*12),1) -> 711.2 | AC34: =IF(AB34*W34>X33,X33,AB34*W34) -> 5851227.3 | AD34: =AC34/X33 -> 0.98777778 | AL34: Previsão de Horas Extras - Eletromecânico - Montador
B35: 31 | C35: PREV | D35: 1.17 | E35: Técnico Sênior - Eletrotécnico - Noturno / Técnico Pleno - Operador de Subest (12X36) - Noturno | F35: P9867N (*) | G35: =C35&E35 -> PREVTécnico Sênior - Eletrotécnico - Noturno / Técnico Pleno - Operador de Subest (12X36) - Noturno | H35: =Y35 | I35: 3.2 | J35: 4 | K35: 4 | L35: 4 | M35: 4 | N35: 4 | O35: 4 | P35: 4 | Q35: 4 | R35: 4 | S35: 4 | T35: 4 | U35: 0.8 | V35: =SUM(I35:U35) -> 48 | W35: 12223.36 | X35: =W35*V35 -> 586721.28 | AL35: Previsão de Horas Extras - Eletromecânico - Montador
B36: 32 | C36: REAL | D36: 1.17 | E36: Técnico Sênior - Eletrotécnico - Noturno / Técnico Pleno - Operador de Subest (12X36) - Noturno | F36: P9867N (*) | G36: =C36&E36 -> REALTécnico Sênior - Eletrotécnico - Noturno / Técnico Pleno - Operador de Subest (12X36) - Noturno | H36: =Y36 -> 0.56666667 | I36: 3.2 | J36: 4 | K36: 4 | L36: 4 | M36: 4 | N36: 4 | O36: 4 | V36: =SUM(I36:U36) -> 27.2 | W36: 12223.36 | X36: =W36*V36 -> 332475.39 | Y36: =X36/X35 -> 0.56666667 | Z36: =X35-AC36 -> 0 | AB36: =ROUND((AVERAGE(J36:T36)*12),1) -> 48 | AC36: =IF(AB36*W36>X35,X35,AB36*W36) -> 586721.28 | AD36: =AC36/X35 -> 1 | AL36: Previsão de Horas Sobreaviso - Técnico Sênior Eletromecânico/Eletrotécnico/Eletrônico
B37: 33 | C37: PREV | D37: 1.18 | E37: Técnico Sênior - Segurança | F37: P9876 (*) | G37: =C37&E37 -> PREVTécnico Sênior - Segurança | H37: =Y37 | I37: 1.6 | J37: 2 | K37: 2 | L37: 2 | M37: 2 | N37: 2 | O37: 2 | P37: 2 | Q37: 2 | R37: 2 | S37: 2 | T37: 2 | U37: 0.4 | V37: =SUM(I37:U37) -> 24 | W37: 8433.02 | X37: =W37*V37 -> 202392.48 | AL37: Previsão de Horas Extras - Técnico Sênior Eletromecânico/Eletrotécnico/Eletrônico
B38: 34 | C38: REAL | D38: 1.18 | E38: Técnico Sênior - Segurança | F38: P9876 (*) | G38: =C38&E38 -> REALTécnico Sênior - Segurança | H38: =Y38 -> 0.56666667 | I38: 1.6 | J38: 2 | K38: 2 | L38: 2 | M38: 2 | N38: 2 | O38: 2 | V38: =SUM(I38:U38) -> 13.6 | W38: 8433.02 | X38: =W38*V38 -> 114689.07 | Y38: =X38/X37 -> 0.56666667 | Z38: =X37-AC38 -> 0 | AB38: =ROUND((AVERAGE(J38:T38)*12),1) -> 24 | AC38: =IF(AB38*W38>X37,X37,AB38*W38) -> 202392.48 | AD38: =AC38/X37 -> 1 | AL38: Previsão de Horas Extras - Técnico Sênior Eletromecânico/Eletrotécnico/Eletrônico
B39: 35 | C39: PREV | D39: 1.19 | E39: Secretária | F39: P9878 | G39: =C39&E39 -> PREVSecretária | H39: =Y39 | I39: 0.8 | J39: 1 | K39: 1 | L39: 1 | M39: 1 | N39: 1 | O39: 1 | P39: 1 | Q39: 1 | R39: 1 | S39: 1 | T39: 1 | U39: 0.2 | V39: =SUM(I39:U39) -> 12 | W39: 6370.42 | X39: =W39*V39 -> 76445.04 | AL39: Previsão de Horas Sobreaviso ‐ Motorista
B40: 36 | C40: REAL | D40: 1.19 | E40: Secretária | F40: P9878 | G40: =C40&E40 -> REALSecretária | H40: =Y40 -> 0.56666667 | I40: 0.8 | J40: 1 | K40: 1 | L40: 1 | M40: 1 | N40: 1 | O40: 1 | V40: =SUM(I40:U40) -> 6.8 | W40: 6370.42 | X40: =W40*V40 -> 43318.856 | Y40: =X40/X39 -> 0.56666667 | Z40: =X39-AC40 -> 0 | AB40: =ROUND((AVERAGE(J40:T40)*12),1) -> 12 | AC40: =IF(AB40*W40>X39,X39,AB40*W40) -> 76445.04 | AD40: =AC40/X39 -> 1 | AL40: Previsão de Horas Extras - Motorista
...

Sheet CUSTO DIRETO- P x R
C1: PLANILHA REFERENCIAL DE PREÇOS - CUSTOS DIRETOS (COM DESONERAÇÃO)
C2: Item | D2: Descrição | H2: Unidade | I2: Meses | V2: Quantidade | W2: Preço Unitário | X2: Total | Y2: PERCENTUAL MEDIDO
I3: 24.1 | J3: 25 | K3: 26 | L3: 27 | M3: 28 | N3: 29 | O3: 30 | P3: 31 | Q3: 32 | R3: 33 | S3: 34 | T3: 35 | U3: 36
I4: jul | J4: ago | K4: set | L4: out | M4: nov | N4: dez | O4: jan | P4: fev | Q4: mar | R4: abr | S4: mai | T4: jun | U4: jul
A5: 1 | B5: PREV | C5: 1 | D5: GESTÃO DO CONTRATO
A6: 2 | B6: REAL | C6: 1 | D6: GESTÃO DO CONTRATO
A7: 3 | B7: PREV | C7: 1.1 | D7: VEÍCULOS | V7: 0 | W7: 0 | X7: =SUMIF(B9:B18,B7,X9:X18) -> 1396536.1
A8: 4 | B8: REAL | C8: 1.1 | D8: VEÍCULOS | G8: % | X8: =SUMIF(B9:B18,B8,X9:X18) -> 442236.44 | Y8: =X8/X7 -> 0.31666667
A9: 5 | B9: PREV | C9: 1.1.1 | D9: Veículo ‐ caminhonete 4x4 cabine dupla c/ motorista | E9: 2.3.2 | F9: =B9&D9 -> PREVVeículo ‐ caminhonete 4x4 cabine dupla c/ motorista | H9: und x mês | I9: 1.6 | J9: 2 | K9: 2 | L9: 2 | M9: 2 | N9: 2 | O9: 2 | P9: 2 | Q9: 2 | R9: 2 | S9: 2 | T9: 2 | U9: 0.4 | V9: =SUM(I9:U9) -> 24 | W9: 12971.63 | X9: =W9*V9 -> 311319.12
A10: 6 | B10: REAL | C10: 1.1.1 | D10: Veículo ‐ caminhonete 4x4 cabine dupla c/ motorista | E10: 2.3.2 | F10: =B10&D10 -> REALVeículo ‐ caminhonete 4x4 cabine dupla c/ motorista | G10: =Y10 -> 0.31666667 | H10: und x mês | I10: 1.6 | J10: 2 | K10: 2 | L10: 2 | V10: =SUM(I10:U10) -> 7.6 | W10: 12971.63 | X10: =W10*V10 -> 98584.388 | Y10: =X10/X9 -> 0.31666667 | AB10: =AA10*I10 -> 0
A11: 7 | B11: PREV | C11: 1.1.2 | D11: Veículo ‐ caminhonete 4x4 cabine dupla | E11: 2.3.1 | F11: =B11&D11 -> PREVVeículo ‐ caminhonete 4x4 cabine dupla | H11: und x mês | I11: 0.8 | J11: 1 | K11: 1 | L11: 1 | M11: 1 | N11: 1 | O11: 1 | P11: 1 | Q11: 1 | R11: 1 | S11: 1 | T11: 1 | U11: 0.2 | V11: =SUM(I11:U11) -> 12 | W11: 7919.19 | X11: =W11*V11 -> 95030.28
A12: 8 | B12: REAL | C12: 1.1.2 | D12: Veículo ‐ caminhonete 4x4 cabine dupla | E12: 2.3.1 | F12: =B12&D12 -> REALVeículo ‐ caminhonete 4x4 cabine dupla | G12: =Y12 -> 0.31666667 | H12: und x mês | I12: 0.8 | J12: 1 | K12: 1 | L12: 1 | V12: =SUM(I12:U12) -> 3.8 | W12: 7919.19 | X12: =W12*V12 -> 30092.922 | Y12: =X12/X11 -> 0.31666667 | Z12: 84 | AA12: =V11/Z12 -> 0.14285714 | AB12: =AA12*I12 -> 0.11428571
A13: 9 | B13: PREV | C13: 1.1.3 | D13: Veículo ‐ pick up 4x4 (E8891) ‐ Operativo + Improdutivo | E13: 2.3.3 | F13: =B13&D13 -> PREVVeículo ‐ pick up 4x4 (E8891) ‐ Operativo + Improdutivo | H13: und x mês | I13: 2.4 | J13: 3 | K13: 3 | L13: 3 | M13: 3 | N13: 3 | O13: 3 | P13: 3 | Q13: 3 | R13: 3 | S13: 3 | T13: 3 | U13: 0.6 | V13: =SUM(I13:U13) -> 36 | W13: 7459.55 | X13: =W13*V13 -> 268543.8
A14: 10 | B14: REAL | C14: 1.1.3 | D14: Veículo ‐ pick up 4x4 (E8891) ‐ Operativo + Improdutivo | E14: 2.3.3 | F14: =B14&D14 -> REALVeículo ‐ pick up 4x4 (E8891) ‐ Operativo + Improdutivo | G14: =Y14 -> 0.31666667 | H14: und x mês | I14: 2.4 | J14: 3 | K14: 3 | L14: 3 | V14: =SUM(I14:U14) -> 11.4 | W14: 7459.55 | X14: =W14*V14 -> 85038.87 | Y14: =X14/X13 -> 0.31666667 | Z14: 108 | AA14: =V13/Z14 -> 0.33333333 | AB14: =AA14*I14 -> 0.8
A15: 11 | B15: PREV | C15: 1.1.4 | D15: Veículo ‐ sedan 1.6 flex ‐ 115CV (E8889) ‐ Operativo + Improdutivo | E15: 2.3.4 | F15: =B15&D15 -> PREVVeículo ‐ sedan 1.6 flex ‐ 115CV (E8889) ‐ Operativo + Improdutivo | H15: und x mês | I15: 3.2 | J15: 4 | K15: 4 | L15: 4 | M15: 4 | N15: 4 | O15: 4 | P15: 4 | Q15: 4 | R15: 4 | S15: 4 | T15: 4 | U15: 0.8 | V15: =SUM(I15:U15) -> 48 | W15: 3155.45 | X15: =W15*V15 -> 151461.6
A16: 12 | B16: REAL | C16: 1.1.4 | D16: Veículo ‐ sedan 1.6 flex ‐ 115CV (E8889) ‐ Operativo + Improdutivo | E16: 2.3.4 | F16: =B16&D16 -> REALVeículo ‐ sedan 1.6 flex ‐ 115CV (E8889) ‐ Operativo + Improdutivo | G16: =Y16 -> 0.31666667 | H16: und x mês | I16: 3.2 | J16: 4 | K16: 4 | L16: 4 | V16: =SUM(I16:U16) -> 15.2 | W16: 3155.45 | X16: =W16*V16 -> 47962.84 | Y16: =X16/X15 -> 0.31666667 | Z16: 180 | AA16: =V15/Z16 -> 0.26666667
A17: 13 | B17: PREV | C17: 1.1.5 | D17: Ônibus com 45 lugares ‐ 218CV (com motorista ‐ incluindo combustível e manutenção) | E17: 2.3.6 | F17: =B17&D17 -> PREVÔnibus com 45 lugares ‐ 218CV (com motorista ‐ incluindo combustível e manutenção) | H17: und x mês | I17: 2.4 | J17: 3 | K17: 3 | L17: 3 | M17: 3 | N17: 3 | O17: 3 | P17: 3 | Q17: 3 | R17: 3 | S17: 3 | T17: 3 | U17: 0.6 | V17: =SUM(I17:U17) -> 36 | W17: 15838.37 | X17: =W17*V17 -> 570181.32
A18: 14 | B18: REAL | C18: 1.1.5 | D18: Ônibus com 45 lugares ‐ 218CV (com motorista ‐ incluindo combustível e manutenção) | E18: 2.3.6 | F18: =B18&D18 -> REALÔnibus com 45 lugares ‐ 218CV (com motorista ‐ incluindo combustível e manutenção) | G18: =Y18 -> 0.31666667 | H18: und x mês | I18: 2.4 | J18: 3 | K18: 3 | L18: 3 | V18: =SUM(I18:U18) -> 11.4 | W18: 15838.37 | X18: =W18*V18 -> 180557.42 | Y18: =X18/X17 -> 0.31666667 | AB18: =AA18*I18 -> 0
A19: 15 | B19: PREV | C19: 1.2 | D19: ESCRITÓRIO | E19: 2.4 | V19: 0 | W19: 0 | X19: =SUMIF(B21:B66,B19,X21:X66) -> 1512510.2
A20: 16 | B20: REAL | C20: 1.2 | D20: ESCRITÓRIO | E20: 2.4 | X20: =SUMIF(B21:B66,B20,X21:X66) -> 406928.63 | Y20: =X20/X19 -> 0.2690419
A21: 17 | B21: PREV | C21: 1.2.1 | D21: Aluguel de Impressora A3 | E21: 2.2.2 | F21: =B21&D21 -> PREVAluguel de Impressora A3 | H21: und x mês | I21: 0.8 | J21: 1 | K21: 1 | L21: 1 | M21: 1 | N21: 1 | O21: 1 | P21: 1 | Q21: 1 | R21: 1 | S21: 1 | T21: 1 | U21: 0.2 | V21: =SUM(I21:U21) -> 12 | W21: 177.77 | X21: =W21*V21 -> 2133.24
A22: 18 | B22: REAL | C22: 1.2.1 | D22: Aluguel de Impressora A3 | E22: 2.2.2 | F22: =B22&D22 -> REALAluguel de Impressora A3 | G22: =Y22 -> 0.31666667 | H22: und x mês | I22: 0.8 | J22: 1 | K22: 1 | L22: 1 | V22: =SUM(I22:U22) -> 3.8 | W22: 177.77 | X22: =W22*V22 -> 675.526 | Y22: =X22/X21 -> 0.31666667 | Z22: 36
A23: 19 | B23: PREV | C23: 1.2.2 | D23: Aluguel de Servidor | E23: 2.2.3 | F23: =B23&D23 -> PREVAluguel de Servidor | H23: und x mês | I23: 1.6 | J23: 2 | K23: 2 | L23: 2 | M23: 2 | N23: 2 | O23: 2 | P23: 2 | Q23: 2 | R23: 2 | S23: 2 | T23: 2 | U23: 0.4 | V23: =SUM(I23:U23) -> 24 | W23: 1350.87 | X23: =W23*V23 -> 32420.88
A24: 20 | B24: REAL | C24: 1.2.2 | D24: Aluguel de Servidor | E24: 2.2.3 | F24: =B24&D24 -> REALAluguel de Servidor | G24: =Y24 -> 0.31666667 | H24: und x mês | I24: 1.6 | J24: 2 | K24: 2 | L24: 2 | V24: =SUM(I24:U24) -> 7.6 | W24: 1350.87 | X24: =W24*V24 -> 10266.612 | Y24: =X24/X23 -> 0.31666667
A25: 21 | B25: PREV | C25: 1.2.3 | D25: Aluguel de Plotter | E25: 2.2.4 | F25: =B25&D25 -> PREVAluguel de Plotter | H25: und x mês | I25: 0.8 | J25: 1 | K25: 1 | L25: 1 | M25: 1 | N25: 1 | O25: 1 | P25: 1 | Q25: 1 | R25: 1 | S25: 1 | T25: 1 | U25: 0.2 | V25: =SUM(I25:U25) -> 12 | W25: 116.18 | X25: =W25*V25 -> 1394.16
A26: 22 | B26: REAL | C26: 1.2.3 | D26: Aluguel de Plotter | E26: 2.2.4 | F26: =B26&D26 -> REALAluguel de Plotter | G26: =Y26 -> 0.31666667 | H26: und x mês | I26: 0.8 | J26: 1 | K26: 1 | L26: 1 | V26: =SUM(I26:U26) -> 3.8 | W26: 116.18 | X26: =W26*V26 -> 441.484 | Y26: =X26/X25 -> 0.31666667
A27: 23 | B27: PREV | C27: 1.2.4 | D27: Câmera fotografica profissional DSLR, 18 MP, vídeos em Full HD, lente EF‐S 18‐ 55mm f/3.5‐5.6 III e bateria | E27: 2.4.6 | F27: =B27&D27 -> PREVCâmera fotografica profissional DSLR, 18 MP, vídeos em Full HD, lente EF‐S 18‐ 55mm f/3.5‐5.6 III e bateria | H27: und x mês | I27: 1.6 | J27: 2 | K27: 2 | L27: 2 | M27: 2 | N27: 2 | O27: 2 | P27: 2 | Q27: 2 | R27: 2 | S27: 2 | T27: 2 | U27: 0.4 | V27: =SUM(I27:U27) -> 24 | W27: 20.19 | X27: =W27*V27 -> 484.56
A28: 24 | B28: REAL | C28: 1.2.4 | D28: Câmera fotografica profissional DSLR, 18 MP, vídeos em Full HD, lente EF‐S 18‐ 55mm f/3.5‐5.6 III e bateria | E28: 2.4.6 | F28: =B28&D28 -> REALCâmera fotografica profissional DSLR, 18 MP, vídeos em Full HD, lente EF‐S 18‐ 55mm f/3.5‐5.6 III e bateria | G28: =Y28 -> 0.31666667 | H28: und x mês | I28: 1.6 | J28: 2 | K28: 2 | L28: 2 | V28: =SUM(I28:U28) -> 7.6 | W28: 20.19 | X28: =W28*V28 -> 153.444 | Y28: =X28/X27 -> 0.31666667
A29: 25 | B29: PREV | C29: 1.2.5 | D29: Binóculo Profissional Ampliação 8 à 24x 50mm | E29: 2.4.7 | F29: =B29&D29 -> PREVBinóculo Profissional Ampliação 8 à 24x 50mm | H29: und x mês | I29: 1.6 | J29: 2 | K29: 2 | L29: 2 | M29: 2 | N29: 2 | O29: 2 | P29: 2 | Q29: 2 | R29: 2 | S29: 2 | T29: 2 | U29: 0.4 | V29: =SUM(I29:U29) -> 24 | W29: 24.34 | X29: =W29*V29 -> 584.16
A30: 26 | B30: REAL | C30: 1.2.5 | D30: Binóculo Profissional Ampliação 8 à 24x 50mm | E30: 2.4.7 | F30: =B30&D30 -> REALBinóculo Profissional Ampliação 8 à 24x 50mm | G30: =Y30 -> 0.31666667 | H30: und x mês | I30: 1.6 | J30: 2 | K30: 2 | L30: 2 | V30: =SUM(I30:U30) -> 7.6 | W30: 24.34 | X30: =W30*V30 -> 184.984 | Y30: =X30/X29 -> 0.31666667
A31: 27 | B31: PREV | C31: 1.2.6 | D31: Imóvel Comercial ‐ Escritório + Almox (B8951) ‐ 150 m² | E31: 2.4.1 | F31: =B31&D31 -> PREVImóvel Comercial ‐ Escritório + Almox (B8951) ‐ 150 m² | H31: und x mês | I31: 1.6 | J31: 2 | K31: 2 | L31: 2 | M31: 2 | N31: 2 | O31: 2 | P31: 2 | Q31: 2 | R31: 2 | S31: 2 | T31: 2 | U31: 0.4 | V31: =SUM(I31:U31) -> 24 | W31: 7471.5 | X31: =W31*V31 -> 179316
A32: 28 | B32: REAL | C32: 1.2.6 | D32: Imóvel Comercial ‐ Escritório + Almox (B8951) ‐ 150 m² | E32: 2.4.1 | F32: =B32&D32 -> REALImóvel Comercial ‐ Escritório + Almox (B8951) ‐ 150 m² | G32: =Y32 -> 0.475 | H32: und x mês | I32: 2.4 | J32: 3 | K32: 3 | L32: 3 | V32: =SUM(I32:U32) -> 11.4 | W32: 7471.5 | X32: =W32*V32 -> 85175.1 | Y32: =X32/X31 -> 0.475
A33: 29 | B33: PREV | C33: 1.2.7 | D33: Mobiliário para escritório (B8953) | E33: 2.4.2 | F33: =B33&D33 -> PREVMobiliário para escritório (B8953) | H33: ocupante x mês | I33: 19.2 | J33: 24 | K33: 24 | L33: 24 | M33: 24 | N33: 24 | O33: 24 | P33: 24 | Q33: 24 | R33: 24 | S33: 24 | T33: 24 | U33: 4.8 | V33: =SUM(I33:U33) -> 288 | W33: 677.68 | X33: =W33*V33 -> 195171.84
A34: 30 | B34: REAL | C34: 1.2.7 | D34: Mobiliário para escritório (B8953) | E34: 2.4.2 | F34: =B34&D34 -> REALMobiliário para escritório (B8953) | G34: =Y34 -> 0.31666667 | H34: ocupante x mês | I34: 19.2 | J34: 24 | K34: 24 | L34: 24 | V34: =SUM(I34:U34) -> 91.2 | W34: 677.68 | X34: =W34*V34 -> 61804.416 | Y34: =X34/X33 -> 0.31666667
A35: 31 | B35: PREV | C35: 1.2.8 | D35: Custos Diversos ‐ Escritório (B8959) | E35: 2.4.3 | F35: =B35&D35 -> PREVCustos Diversos ‐ Escritório (B8959) | H35: ocupante x mês | I35: 19.2 | J35: 24 | K35: 24 | L35: 24 | M35: 24 | N35: 24 | O35: 24 | P35: 24 | Q35: 24 | R35: 24 | S35: 24 | T35: 24 | U35: 4.8 | V35: =SUM(I35:U35) -> 288 | W35: 153.25 | X35: =W35*V35 -> 44136
A36: 32 | B36: REAL | C36: 1.2.8 | D36: Custos Diversos ‐ Escritório (B8959) | E36: 2.4.3 | F36: =B36&D36 -> REALCustos Diversos ‐ Escritório (B8959) | G36: =Y36 -> 0.31666667 | H36: ocupante x mês | I36: 19.2 | J36: 24 | K36: 24 | L36: 24 | V36: =SUM(I36:U36) -> 91.2 | W36: 153.25 | X36: =W36*V36 -> 13976.4 | Y36: =X36/X35 -> 0.31666667
A37: 33 | B37: PREV | C37: 1.2.9 | D37: GPS de Navegação | E37: 2.4.4 | F37: =B37&D37 -> PREVGPS de Navegação | H37: und x mês | I37: 0.8 | J37: 1 | K37: 1 | L37: 1 | M37: 1 | N37: 1 | O37: 1 | P37: 1 | Q37: 1 | R37: 1 | S37: 1 | T37: 1 | U37: 0.2 | V37: =SUM(I37:U37) -> 12 | W37: 50.58 | X37: =W37*V37 -> 606.96
A38: 34 | B38: REAL | C38: 1.2.9 | D38: GPS de Navegação | E38: 2.4.4 | F38: =B38&D38 -> REALGPS de Navegação | G38: =Y38 -> 0.31666667 | H38: und x mês | I38: 0.8 | J38: 1 | K38: 1 | L38: 1 | V38: =SUM(I38:U38) -> 3.8 | W38: 50.58 | X38: =W38*V38 -> 192.204 | Y38: =X38/X37 -> 0.31666667 | Z38: 144
