Workbook
Name NativeTimeline_Data_da_Ocorrência: #N/A
Name SegmentaçãodeDados_Estrutura: #N/A

Sheet Resumo
H11: Quantitativos & Durações
B18: estruturas sem dados não são exibidas
B20: Estruturas consideradas para a seleção atual
B25: estruturas ativas & inativas
B27: Histograma
H32: Histórico
B43: Duração por Estrutura [h]
B60: Indicadores de manutenção
B101: Legenda
B103: 1. MTBF → Mean Time Between Failures (Tempo Médio Entre Falhas); quanto maior, melhor.
B104: 2. MTTR → Mean Time to Repair (Tempo Médio de Reparo); quanto menor, melhor.
B105: 3. DISP → Disponibilidade; quanto maior, melhor.
B106: 4. CONF → Confiabilidade; quanto maior, melhor.
B108: Observações
B110: 1. Quanto mais valores para uma mesma estrutura, mais acurados serão os valores para cada um dos indicadores.
B111: 2. Com a ausência ou escassez de registros, alguns indicadores podem não ser calculados corretamente; ou, serão tão pequenos que sua representação será em notação científica (arredondadas para zero).
B112: 3. A confiabilidade foi calculada para um período de 7 dias (168 horas). No entanto, em vez de indicar "a chance de não apresentar falhas", indica a probabilidade de "não necessitar desligamento", visto que, em sua maioria, são programados.

Sheet Preenchimento
B2: Observações
B4: 1. Para desligamentos com dias distintos para "Início" e "Término", é necessário fragmentar o desligamento em mais de um dia, sendo o "Término" indicado como "23:59:59" para o primeiro registro, e o início do próximo como "00:00:00", e assim por diante.
B5: 2. Novos valores podem ser inseridos imediatamente ao final da tabela de preenchimento, sendo automaticamente criada uma nova linha de registro.
B6: 3. Os valores para "Estrutura" e "Tipo" devem ser selecionados a partir do menu flutuante que surge ao clicar na célula.
B8: Data da Ocorrência | C8: Estrutura | D8: Nome Reduzido | E8: Contagem de Ocorrências | F8: Tipo | G8: Início | H8: Término | I8: Duração da Parada (h) | J8: Tempo em Funcionamento (h) | K8: Descriminação
B9: 44974 | C9: SE-E1. DJ6-02 - VÃO BX | D9: =MID(Tabela1[[#This Row],[Estrutura]], 1, 5) -> SE-E1 | E9: =COUNTIFS(Tabela1[Data da Ocorrência], Tabela1[[#This Row],[Data da Ocorrência]], Tabela1[Nome Reduzido], Tabela1[[#This Row],[Nome Reduzido]]) -> 1 | F9: PROGRAMADA | G9: 0.82152778 | H9: 0.99998843 | I9: =IF(Tabela1[[#This Row],[Tipo]] <> "", (Tabela1[[#This Row],[Término]] - Tabela1[[#This Row],[Início]])*24/Tabela1[[#This Row],[Contagem de Ocorrências]], "—") -> 4.2830556 | J9: =IF(Tabela1[[#This Row],[Duração da Parada (h)]] <> "—", (24 - Tabela1[[#This Row],[Duração da Parada (h)]]), "") -> 19.716944 | K9: Período: 17/02/2023 (19h43) a 01/03/2023 (11h13) Causa: Ocorrência no ramal 6,9kV no interior da EBV-1. Na ocasião, foi realizada inspeção no transformador 6TR1 do vão BX, disjuntor DJ6-02 e cubículo 6,9 kV.
B10: 44975 | C10: SE-E1. DJ6-02 - VÃO BX | D10: =MID(Tabela1[[#This Row],[Estrutura]], 1, 5) -> SE-E1 | E10: =COUNTIFS(Tabela1[Data da Ocorrência], Tabela1[[#This Row],[Data da Ocorrência]], Tabela1[Nome Reduzido], Tabela1[[#This Row],[Nome Reduzido]]) -> 1 | F10: PROGRAMADA | G10: 0 | H10: 0.99998843 | I10: =IF(Tabela1[[#This Row],[Tipo]] <> "", (Tabela1[[#This Row],[Término]] - Tabela1[[#This Row],[Início]])*24/Tabela1[[#This Row],[Contagem de Ocorrências]], "—") -> 23.999722 | J10: =IF(Tabela1[[#This Row],[Duração da Parada (h)]] <> "—", (24 - Tabela1[[#This Row],[Duração da Parada (h)]]), "") -> 0.00027777778 | K10: Ocorrência no ramal 6,9kV no interior da EBV-1. Na ocasião, foi realizada inspeção no transformador 6TR1 do vão BX, disjuntor DJ6-02 e cubículo 6,9 kV.
B11: 44976 | C11: SE-E1. DJ6-02 - VÃO BX | D11: =MID(Tabela1[[#This Row],[Estrutura]], 1, 5) -> SE-E1 | E11: =COUNTIFS(Tabela1[Data da Ocorrência], Tabela1[[#This Row],[Data da Ocorrência]], Tabela1[Nome Reduzido], Tabela1[[#This Row],[Nome Reduzido]]) -> 1 | F11: PROGRAMADA | G11: 0 | H11: 0.99998843 | I11: =IF(Tabela1[[#This Row],[Tipo]] <> "", (Tabela1[[#This Row],[Término]] - Tabela1[[#This Row],[Início]])*24/Tabela1[[#This Row],[Contagem de Ocorrências]], "—") -> 23.999722 | J11: =IF(Tabela1[[#This Row],[Duração da Parada (h)]] <> "—", (24 - Tabela1[[#This Row],[Duração da Parada (h)]]), "") -> 0.00027777778 | K11: Ocorrência no ramal 6,9kV no interior da EBV-1. Na ocasião, foi realizada inspeção no transformador 6TR1 do vão BX, disjuntor DJ6-02 e cubículo 6,9 kV.
B12: 44977 | C12: SE-E1. DJ6-02 - VÃO BX | D12: =MID(Tabela1[[#This Row],[Estrutura]], 1, 5) -> SE-E1 | E12: =COUNTIFS(Tabela1[Data da Ocorrência], Tabela1[[#This Row],[Data da Ocorrência]], Tabela1[Nome Reduzido], Tabela1[[#This Row],[Nome Reduzido]]) -> 1 | F12: PROGRAMADA | G12: 0 | H12: 0.99998843 | I12: =IF(Tabela1[[#This Row],[Tipo]] <> "", (Tabela1[[#This Row],[Término]] - Tabela1[[#This Row],[Início]])*24/Tabela1[[#This Row],[Contagem de Ocorrências]], "—") -> 23.999722 | J12: =IF(Tabela1[[#This Row],[Duração da Parada (h)]] <> "—", (24 - Tabela1[[#This Row],[Duração da Parada (h)]]), "") -> 0.00027777778 | K12: Ocorrência no ramal 6,9kV no interior da EBV-1. Na ocasião, foi realizada inspeção no transformador 6TR1 do vão BX, disjuntor DJ6-02 e cubículo 6,9 kV.
B13: 44978 | C13: SE-E1. DJ6-02 - VÃO BX | D13: =MID(Tabela1[[#This Row],[Estrutura]], 1, 5) -> SE-E1 | E13: =COUNTIFS(Tabela1[Data da Ocorrência], Tabela1[[#This Row],[Data da Ocorrência]], Tabela1[Nome Reduzido], Tabela1[[#This Row],[Nome Reduzido]]) -> 1 | F13: PROGRAMADA | G13: 0 | H13: 0.99998843 | I13: =IF(Tabela1[[#This Row],[Tipo]] <> "", (Tabela1[[#This Row],[Término]] - Tabela1[[#This Row],[Início]])*24/Tabela1[[#This Row],[Contagem de Ocorrências]], "—") -> 23.999722 | J13: =IF(Tabela1[[#This Row],[Duração da Parada (h)]] <> "—", (24 - Tabela1[[#This Row],[Duração da Parada (h)]]), "") -> 0.00027777778 | K13: Ocorrência no ramal 6,9kV no interior da EBV-1. Na ocasião, foi realizada inspeção no transformador 6TR1 do vão BX, disjuntor DJ6-02 e cubículo 6,9 kV.
B14: 44979 | C14: SE-E1. DJ6-02 - VÃO BX | D14: =MID(Tabela1[[#This Row],[Estrutura]], 1, 5) -> SE-E1 | E14: =COUNTIFS(Tabela1[Data da Ocorrência], Tabela1[[#This Row],[Data da Ocorrência]], Tabela1[Nome Reduzido], Tabela1[[#This Row],[Nome Reduzido]]) -> 1 | F14: PROGRAMADA | G14: 0 | H14: 0.99998843 | I14: =IF(Tabela1[[#This Row],[Tipo]] <> "", (Tabela1[[#This Row],[Término]] - Tabela1[[#This Row],[Início]])*24/Tabela1[[#This Row],[Contagem de Ocorrências]], "—") -> 23.999722 | J14: =IF(Tabela1[[#This Row],[Duração da Parada (h)]] <> "—", (24 - Tabela1[[#This Row],[Duração da Parada (h)]]), "") -> 0.00027777778 | K14: Ocorrência no ramal 6,9kV no interior da EBV-1. Na ocasião, foi realizada inspeção no transformador 6TR1 do vão BX, disjuntor DJ6-02 e cubículo 6,9 kV.
B15: 44980 | C15: SE-E1. DJ6-02 - VÃO BX | D15: =MID(Tabela1[[#This Row],[Estrutura]], 1, 5) -> SE-E1 | E15: =COUNTIFS(Tabela1[Data da Ocorrência], Tabela1[[#This Row],[Data da Ocorrência]], Tabela1[Nome Reduzido], Tabela1[[#This Row],[Nome Reduzido]]) -> 1 | F15: PROGRAMADA | G15: 0 | H15: 0.99998843 | I15: =IF(Tabela1[[#This Row],[Tipo]] <> "", (Tabela1[[#This Row],[Término]] - Tabela1[[#This Row],[Início]])*24/Tabela1[[#This Row],[Contagem de Ocorrências]], "—") -> 23.999722 | J15: =IF(Tabela1[[#This Row],[Duração da Parada (h)]] <> "—", (24 - Tabela1[[#This Row],[Duração da Parada (h)]]), "") -> 0.00027777778 | K15: Ocorrência no ramal 6,9kV no interior da EBV-1. Na ocasião, foi realizada inspeção no transformador 6TR1 do vão BX, disjuntor DJ6-02 e cubículo 6,9 kV.
B16: 44981 | C16: SE-E1. DJ6-02 - VÃO BX | D16: =MID(Tabela1[[#This Row],[Estrutura]], 1, 5) -> SE-E1 | E16: =COUNTIFS(Tabela1[Data da Ocorrência], Tabela1[[#This Row],[Data da Ocorrência]], Tabela1[Nome Reduzido], Tabela1[[#This Row],[Nome Reduzido]]) -> 1 | F16: PROGRAMADA | G16: 0 | H16: 0.99998843 | I16: =IF(Tabela1[[#This Row],[Tipo]] <> "", (Tabela1[[#This Row],[Término]] - Tabela1[[#This Row],[Início]])*24/Tabela1[[#This Row],[Contagem de Ocorrências]], "—") -> 23.999722 | J16: =IF(Tabela1[[#This Row],[Duração da Parada (h)]] <> "—", (24 - Tabela1[[#This Row],[Duração da Parada (h)]]), "") -> 0.00027777778 | K16: Ocorrência no ramal 6,9kV no interior da EBV-1. Na ocasião, foi realizada inspeção no transformador 6TR1 do vão BX, disjuntor DJ6-02 e cubículo 6,9 kV.
B17: 44982 | C17: SE-E1. DJ6-02 - VÃO BX | D17: =MID(Tabela1[[#This Row],[Estrutura]], 1, 5) -> SE-E1 | E17: =COUNTIFS(Tabela1[Data da Ocorrência], Tabela1[[#This Row],[Data da Ocorrência]], Tabela1[Nome Reduzido], Tabela1[[#This Row],[Nome Reduzido]]) -> 1 | F17: PROGRAMADA | G17: 0 | H17: 0.99998843 | I17: =IF(Tabela1[[#This Row],[Tipo]] <> "", (Tabela1[[#This Row],[Término]] - Tabela1[[#This Row],[Início]])*24/Tabela1[[#This Row],[Contagem de Ocorrências]], "—") -> 23.999722 | J17: =IF(Tabela1[[#This Row],[Duração da Parada (h)]] <> "—", (24 - Tabela1[[#This Row],[Duração da Parada (h)]]), "") -> 0.00027777778 | K17: Ocorrência no ramal 6,9kV no interior da EBV-1. Na ocasião, foi realizada inspeção no transformador 6TR1 do vão BX, disjuntor DJ6-02 e cubículo 6,9 kV.
B18: 44983 | C18: SE-E1. DJ6-02 - VÃO BX | D18: =MID(Tabela1[[#This Row],[Estrutura]], 1, 5) -> SE-E1 | E18: =COUNTIFS(Tabela1[Data da Ocorrência], Tabela1[[#This Row],[Data da Ocorrência]], Tabela1[Nome Reduzido], Tabela1[[#This Row],[Nome Reduzido]]) -> 1 | F18: PROGRAMADA | G18: 0 | H18: 0.99998843 | I18: =IF(Tabela1[[#This Row],[Tipo]] <> "", (Tabela1[[#This Row],[Término]] - Tabela1[[#This Row],[Início]])*24/Tabela1[[#This Row],[Contagem de Ocorrências]], "—") -> 23.999722 | J18: =IF(Tabela1[[#This Row],[Duração da Parada (h)]] <> "—", (24 - Tabela1[[#This Row],[Duração da Parada (h)]]), "") -> 0.00027777778 | K18: Ocorrência no ramal 6,9kV no interior da EBV-1. Na ocasião, foi realizada inspeção no transformador 6TR1 do vão BX, disjuntor DJ6-02 e cubículo 6,9 kV.
B19: 44984 | C19: SE-E1. DJ6-02 - VÃO BX | D19: =MID(Tabela1[[#This Row],[Estrutura]], 1, 5) -> SE-E1 | E19: =COUNTIFS(Tabela1[Data da Ocorrência], Tabela1[[#This Row],[Data da Ocorrência]], Tabela1[Nome Reduzido], Tabela1[[#This Row],[Nome Reduzido]]) -> 1 | F19: PROGRAMADA | G19: 0 | H19: 0.99998843 | I19: =IF(Tabela1[[#This Row],[Tipo]] <> "", (Tabela1[[#This Row],[Término]] - Tabela1[[#This Row],[Início]])*24/Tabela1[[#This Row],[Contagem de Ocorrências]], "—") -> 23.999722 | J19: =IF(Tabela1[[#This Row],[Duração da Parada (h)]] <> "—", (24 - Tabela1[[#This Row],[Duração da Parada (h)]]), "") -> 0.00027777778 | K19: Ocorrência no ramal 6,9kV no interior da EBV-1. Na ocasião, foi realizada inspeção no transformador 6TR1 do vão BX, disjuntor DJ6-02 e cubículo 6,9 kV.
B20: 44984 | C20: SE-E3. DJ6-03 - VÃO BX | D20: =MID(Tabela1[[#This Row],[Estrutura]], 1, 5) -> SE-E3 | E20: =COUNTIFS(Tabela1[Data da Ocorrência], Tabela1[[#This Row],[Data da Ocorrência]], Tabela1[Nome Reduzido], Tabela1[[#This Row],[Nome Reduzido]]) -> 1 | F20: PROGRAMADA | G20: 44984.42 | H20: 44984.671 | I20: =IF(Tabela1[[#This Row],[Tipo]] <> "", (Tabela1[[#This Row],[Término]] - Tabela1[[#This Row],[Início]])*24/Tabela1[[#This Row],[Contagem de Ocorrências]], "—") -> 6.0166667 | J20: =IF(Tabela1[[#This Row],[Duração da Parada (h)]] <> "—", (24 - Tabela1[[#This Row],[Duração da Parada (h)]]), "") -> 17.983333 | K20: Período: 27/02/2023 (10h05) a 27/02/2023 (16h06), Fixação dos condutores do link 6,9kV na EBV-03> Na ocasião foi realizada a inspeção no transformador 6TR1 do vão BX, disjuntor DJ6-03 e cubículo 6,9 kV.
... B221: 46077 | C221: SE-E1. DJ6-02 - VÃO BX | D221: =MID(Tabela1[[#This Row],[Estrutura]], 1, 5) -> SE-E1 | E221: =COUNTIFS(Tabela1[Data da Ocorrência], Tabela1[[#This Row],[Data da Ocorrência]], Tabela1[Nome Reduzido], Tabela1[[#This Row],[Nome Reduzido]]) -> 1 | F221: PROGRAMADA | G221: 0.29930556 | H221: 0.59027778 | I221: =IF(Tabela1[[#This Row],[Tipo]] <> "", (Tabela1[[#This Row],[Término]] - Tabela1[[#This Row],[Início]])*24/Tabela1[[#This Row],[Contagem de Ocorrências]], "—") -> 6.9833333 | J221: =IF(Tabela1[[#This Row],[Duração da Parada (h)]] <> "—", (24 - Tabela1[[#This Row],[Duração da Parada (h)]]), "") -> 17.016667 | K221: Desligamento para manutenção preventiva no Cubiculo e painéis elétricos da EBV1 e Link 6.9 kV. Aproveitando o desligamneto, Foi execultado na SE-E1; Retirada de ninho de pássaros; Inspeção e limpeza das buchas do trafo 6TR1; Restauração da pintura interna do cubículo 501-1; Inspeção e limpeza da chave faca 289-01; Teste de resistência de contato (Micromimetro) da chave faca 289-01.

Sheet BCKSTG-TABLES
B2: #001 – Quantitativo para Desligamentos Forçados e Programados | H2: #002 – Contagem de Desligamentos Forçados e Programados | N2: #003 – Ocorrências em Função do Tempo | Q2: #004 – Ocorrências em Função do Tempo | AC2: #005 – Contagem de Ocorrências | AF2: #006 – Duração por Estrutura e Tipo de Parada | AI2: #007 – Contagem de Estruturas Ativas & Ocorrências | AL2: #008 – Quantitativo de Horas por Estrutura | AO2: #009 – Tempo em Funcionamento por Estrutura
B4: Soma de Duração da Parada (H) | C4: Rótulos de Coluna | H4: Contagem de Duração da Parada (H) | I4: Rótulos de Coluna | N4: Linha do Tempo | O4: Contagem de Duração da Parada (H) | Q4: Linha do Tempo | R4: Duração da Parada [h] | S4: Indisponibilidade [%] | T4: Disponibilidade [%] | V4: ORIGINAL | Y4: M1 | AA4: M2 | AC4: Linha do Tempo | AD4: Contagem de Duração da Parada (H) | AF4: Rótulos de Linha | AG4: Soma de Duração da Parada (H) | AI4: Linha do Tempo | AJ4: Contagem de Duração da Parada (H) | AL4: Linha do Tempo | AM4: Soma de Duração da Parada (H) | AO4: Linha do Tempo | AP4: Soma de Tempo em Funcionamento (h)
B5: Linha do Tempo | C5: PROGRAMADA | D5: Total Geral | H5: Linha do Tempo | I5: PROGRAMADA | J5: Total Geral | N5: 45979 | O5: 10 | Q5: SE-E1. DJ6-02 - VÃO BX | R5: 4.5916667 | S5: 19.131944 | T5: 80.868056 | V5: 84.77 | W5: 353 | Y5: =ABS((ROUNDUP(V5/24, 0)*24 - V5)/24 - 1)*100 -> 53.208333 | AA5: =(ABS((ROUNDUP(V5/24, 0)*24 - V5)/24 - 1) + IF(V5 > 24, MID(ROUNDUP(V5/24, 2), 1, 1), 0))*100 -> 353.20833 | AC5: SE-E1. DJ6-02 - VÃO BX | AD5: 1 | AF5: PONTO DE CONEXÃO 04P2 | AG5: 18 | AI5: SE-E1. DJ6-02 - VÃO BX | AJ5: 1 | AL5: SE-E1. DJ6-02 - VÃO BX | AM5: 4.5916667 | AO5: SE-E1. DJ6-02 - VÃO BX | AP5: 19.408333
B6: SE-E1. DJ6-02 - VÃO BX | C6: 4.5916667 | D6: 4.5916667 | H6: SE-E1. DJ6-02 - VÃO BX | I6: 1 | J6: 1 | N6: PROGRAMADA | O6: 10 | Q6: PROGRAMADA | R6: 4.5916667 | S6: 19.131944 | T6: 80.868056 | V6: 84.77 | W6: 353 | Y6: =ABS((ROUNDUP(V6/24, 0)*24 - V6)/24 - 1)*100 -> 53.208333 | AA6: =(ABS((ROUNDUP(V6/24, 0)*24 - V6)/24 - 1) + IF(V6 > 24, MID(ROUNDUP(V6/24, 2), 1, 1), 0))*100 -> 353.20833 | AC6: SE-E2. DJ6-02 - VÃO AY | AD6: 1 | AF6: PROGRAMADA | AG6: 18 | AI6: SE-E2. DJ6-02 - VÃO AY | AJ6: 1 | AL6: SE-E2. DJ6-02 - VÃO AY | AM6: 4.65 | AO6: SE-E2. DJ6-02 - VÃO AY | AP6: 19.35
B7: 46034 | C7: 4.5916667 | D7: 4.5916667 | H7: 46034 | I7: 1 | J7: 1 | N7: 46034 | O7: 2 | Q7: 46034 | R7: 4.5916667 | S7: 19.131944 | T7: 80.868056 | V7: 20.6 | W7: 86 | Y7: =ABS((ROUNDUP(V7/24, 0)*24 - V7)/24 - 1)*100 -> 85.833333 | AA7: =(ABS((ROUNDUP(V7/24, 0)*24 - V7)/24 - 1) + IF(V7 > 24, MID(ROUNDUP(V7/24, 2), 1, 1), 0))*100 -> 85.833333 | AC7: SE-E2. DJ6-03 - VÃO BX | AD7: 2 | AF7: SE-E1. DJ6-02 - VÃO BX | AG7: 471.05417 | AI7: SE-E2. DJ6-03 - VÃO BX | AJ7: 2 | AL7: SE-E2. DJ6-03 - VÃO BX | AM7: 8.3166667 | AO7: SE-E2. DJ6-03 - VÃO BX | AP7: 39.683333
B8: SE-E2. DJ6-02 - VÃO AY | C8: 4.65 | D8: 4.65 | H8: SE-E2. DJ6-02 - VÃO AY | I8: 1 | J8: 1 | N8: PROGRAMADA | O8: 2 | Q8: SE-E2. DJ6-02 - VÃO AY | R8: 4.65 | S8: 19.375 | T8: 80.625 | V8: 24 | W8: 100 | Y8: =ABS((ROUNDUP(V8/24, 0)*24 - V8)/24 - 1)*100 -> 100 | AA8: =(ABS((ROUNDUP(V8/24, 0)*24 - V8)/24 - 1) + IF(V8 > 24, MID(ROUNDUP(V8/24, 2), 1, 1), 0))*100 -> 100 | AC8: SE-E3. DJ6-02 - VÃO AY | AD8: 1 | AF8: FORÇADA | AG8: 84.765833 | AI8: SE-E3. DJ6-02 - VÃO AY | AJ8: 1 | AL8: SE-E3. DJ6-02 - VÃO AY | AM8: 5.8916667 | AO8: SE-E3. DJ6-02 - VÃO AY | AP8: 18.108333
B9: 45979 | C9: 4.65 | D9: 4.65 | H9: 45979 | I9: 1 | J9: 1 | N9: 46035 | O9: 2 | Q9: PROGRAMADA | R9: 4.65 | S9: 19.375 | T9: 80.625 | V9: 24 | W9: 100 | Y9: =ABS((ROUNDUP(V9/24, 0)*24 - V9)/24 - 1)*100 -> 100 | AA9: =(ABS((ROUNDUP(V9/24, 0)*24 - V9)/24 - 1) + IF(V9 > 24, MID(ROUNDUP(V9/24, 2), 1, 1), 0))*100 -> 100 | AC9: SE-E3. DJ6-03 - VÃO BX | AD9: 2 | AF9: PROGRAMADA | AG9: 386.28833 | AI9: SE-E3. DJ6-03 - VÃO BX | AJ9: 2 | AL9: SE-E3. DJ6-03 - VÃO BX | AM9: 9.775 | AO9: SE-E3. DJ6-03 - VÃO BX | AP9: 38.225
B10: SE-E2. DJ6-03 - VÃO BX | C10: 8.3166667 | D10: 8.3166667 | H10: SE-E2. DJ6-03 - VÃO BX | I10: 2 | J10: 2 | N10: PROGRAMADA | O10: 2 | Q10: 45979 | R10: 4.65 | S10: 19.375 | T10: 80.625 | V10: 16.17 | W10: 67 | Y10: =ABS((ROUNDUP(V10/24, 0)*24 - V10)/24 - 1)*100 -> 67.375 | AA10: =(ABS((ROUNDUP(V10/24, 0)*24 - V10)/24 - 1) + IF(V10 > 24, MID(ROUNDUP(V10/24, 2), 1, 1), 0))*100 -> 67.375 | AC10: SE-E4. DJ6-02 - VÃO AY | AD10: 1 | AF10: SE-E2. DJ6-02 - VÃO AY | AG10: 81.549583 | AI10: SE-E4. DJ6-02 - VÃO AY | AJ10: 1 | AL10: SE-E4. DJ6-02 - VÃO AY | AM10: 5.725 | AO10: SE-E4. DJ6-02 - VÃO AY | AP10: 18.275
B11: 45979 | C11: 4.65 | D11: 4.65 | H11: 45979 | I11: 1 | J11: 1 | N11: 46036 | O11: 2 | Q11: SE-E2. DJ6-03 - VÃO BX | R11: 8.3166667 | S11: 34.652778 | T11: 65.347222 | V11: 84.765833 | W11: 353.19097 | Y11: =ABS((ROUNDUP(V11/24, 0)*24 - V11)/24 - 1)*100 -> 53.190972 | AA11: =(ABS((ROUNDUP(V11/24, 0)*24 - V11)/24 - 1) + IF(V11 > 24, MID(ROUNDUP(V11/24, 2), 1, 1), 0))*100 -> 353.19097 | AC11: SE-E4. DJ6-03 - VÃO BX | AD11: 2 | AF11: FORÇADA | AG11: 42.382917 | AI11: SE-E4. DJ6-03 - VÃO BX | AJ11: 2 | AL11: SE-E4. DJ6-03 - VÃO BX | AM11: 9.1416667 | AO11: SE-E4. DJ6-03 - VÃO BX | AP11: 38.858333
B12: 46035 | C12: 3.6666667 | D12: 3.6666667 | H12: 46035 | I12: 1 | J12: 1 | N12: PROGRAMADA | O12: 2 | Q12: PROGRAMADA | R12: 8.3166667 | S12: 34.652778 | T12: 65.347222 | V12: 84.765833 | W12: 353.19097 | Y12: =ABS((ROUNDUP(V12/24, 0)*24 - V12)/24 - 1)*100 -> 53.190972 | AA12: =(ABS((ROUNDUP(V12/24, 0)*24 - V12)/24 - 1) + IF(V12 > 24, MID(ROUNDUP(V12/24, 2), 1, 1), 0))*100 -> 353.19097 | AC12: SE-E5. DJ4-02 - VÃO AY | AD12: 2 | AF12: PROGRAMADA | AG12: 39.166667 | AI12: SE-E5. DJ4-02 - VÃO AY | AJ12: 2 | AL12: SE-E5. DJ4-02 - VÃO AY | AM12: 16.316667 | AO12: SE-E5. DJ4-02 - VÃO AY | AP12: 31.683333
B13: SE-E3. DJ6-02 - VÃO AY | C13: 5.8916667 | D13: 5.8916667 | H13: SE-E3. DJ6-02 - VÃO AY | I13: 1 | J13: 1 | N13: 46037 | O13: 2 | Q13: 45979 | R13: 4.65 | S13: 19.375 | T13: 80.625 | V13: 20.599722 | W13: 85.832176 | Y13: =ABS((ROUNDUP(V13/24, 0)*24 - V13)/24 - 1)*100 -> 85.832176 | AA13: =(ABS((ROUNDUP(V13/24, 0)*24 - V13)/24 - 1) + IF(V13 > 24, MID(ROUNDUP(V13/24, 2), 1, 1), 0))*100 -> 85.832176 | AC13: SE-E6. DJ4-02 - VÃO AZ - RAMAL DO AGRESTE | AD13: 1 | AF13: SE-E2. DJ6-03 - VÃO BX | AG13: 120.54958 | AI13: SE-E6. DJ4-02 - VÃO AZ - RAMAL DO AGRESTE | AJ13: 1 | AL13: SE-E6. DJ4-02 - VÃO AZ - RAMAL DO AGRESTE | AM13: 3.6333333 | AO13: SE-E6. DJ4-02 - VÃO AZ - RAMAL DO AGRESTE | AP13: 20.366667
B14: 45979 | C14: 5.8916667 | D14: 5.8916667 | H14: 45979 | I14: 1 | J14: 1 | N14: PROGRAMADA | O14: 2 | Q14: 46035 | R14: 3.6666667 | S14: 15.277778 | T14: 84.722222 | V14: 23.999722 | W14: 99.998843 | Y14: =ABS((ROUNDUP(V14/24, 0)*24 - V14)/24 - 1)*100 -> 99.998843 | AA14: =(ABS((ROUNDUP(V14/24, 0)*24 - V14)/24 - 1) + IF(V14 > 24, MID(ROUNDUP(V14/24, 2), 1, 1), 0))*100 -> 99.998843 | AC14: SE-E6. DJ4-06 - VÃO CZ | AD14: 1 | AF14: FORÇADA | AG14: 42.382917 | AI14: SE-E6. DJ4-06 - VÃO CZ | AJ14: 1 | AL14: SE-E6. DJ4-06 - VÃO CZ | AM14: 3.6333333 | AO14: SE-E6. DJ4-06 - VÃO CZ | AP14: 20.366667
B15: SE-E3. DJ6-03 - VÃO BX | C15: 9.775 | D15: 9.775 | H15: SE-E3. DJ6-03 - VÃO BX | I15: 2 | J15: 2 | N15: 46038 | O15: 2 | Q15: SE-E3. DJ6-02 - VÃO AY | R15: 5.8916667 | S15: 24.548611 | T15: 75.451389 | V15: 23.999722 | W15: 99.998843 | Y15: =ABS((ROUNDUP(V15/24, 0)*24 - V15)/24 - 1)*100 -> 99.998843 | AA15: =(ABS((ROUNDUP(V15/24, 0)*24 - V15)/24 - 1) + IF(V15 > 24, MID(ROUNDUP(V15/24, 2), 1, 1), 0))*100 -> 99.998843 | AC15: SE-E6. DJ6-01 - VÃO AX | AD15: 1 | AF15: PROGRAMADA | AG15: 78.166667 | AI15: SE-E6. DJ6-01 - VÃO AX | AJ15: 1 | AL15: SE-E6. DJ6-01 - VÃO AX | AM15: 3.6333333 | AO15: SE-E6. DJ6-01 - VÃO AX | AP15: 20.366667
B16: 45979 | C16: 5.8916667 | D16: 5.8916667 | H16: 45979 | I16: 1 | J16: 1 | N16: PROGRAMADA | O16: 2 | Q16: PROGRAMADA | R16: 5.8916667 | S16: 24.548611 | T16: 75.451389 | V16: 16.166667 | W16: 67.361111 | Y16: =ABS((ROUNDUP(V16/24, 0)*24 - V16)/24 - 1)*100 -> 67.361111 | AA16: =(ABS((ROUNDUP(V16/24, 0)*24 - V16)/24 - 1) + IF(V16 > 24, MID(ROUNDUP(V16/24, 2), 1, 1), 0))*100 -> 67.361111 | AC16: SE-E1. 289-01 - "VÃO BX" - LINK 6,9 kV - EBV-01 | AF16: SE-E3. DJ6-02 - VÃO AY | AG16: 80.816296 | AI16: SE-E1. 289-01 - "VÃO BX" - LINK 6,9 kV - EBV-01 | AJ16: 1 | AL16: SE-E1. 289-01 - "VÃO BX" - LINK 6,9 kV - EBV-01 | AM16: 4.6166667 | AO16: SE-E1. 289-01 - "VÃO BX" - LINK 6,9 kV - EBV-01 | AP16: 19.383333
B17: 46036 | C17: 3.8833333 | D17: 3.8833333 | H17: 46036 | I17: 1 | J17: 1 | N17: Total Geral | O17: 20 | Q17: 45979 | R17: 5.8916667 | S17: 24.548611 | T17: 75.451389 | V17: 87.865833 | W17: 366.10764 | Y17: =ABS((ROUNDUP(V17/24, 0)*24 - V17)/24 - 1)*100 -> 66.107639 | AA17: =(ABS((ROUNDUP(V17/24, 0)*24 - V17)/24 - 1) + IF(V17 > 24, MID(ROUNDUP(V17/24, 2), 1, 1), 0))*100 -> 366.10764 | AC17: PROGRAMADA | AD17: 1 | AF17: FORÇADA | AG17: 38.94963 | AI17: SE-E2. 289-01 - "VÃO BX" - LINK 6,9 kV - EBV-02 | AJ17: 1 | AL17: SE-E2. 289-01 - "VÃO BX" - LINK 6,9 kV - EBV-02 | AM17: 3.6 | AO17: SE-E2. 289-01 - "VÃO BX" - LINK 6,9 kV - EBV-02 | AP17: 20.4
B18: SE-E4. DJ6-02 - VÃO AY | C18: 5.725 | D18: 5.725 | H18: SE-E4. DJ6-02 - VÃO AY | I18: 1 | J18: 1 | Q18: SE-E3. DJ6-03 - VÃO BX | R18: 9.775 | S18: 40.729167 | T18: 59.270833 | V18: 84.765833 | W18: 353.19097 | Y18: =ABS((ROUNDUP(V18/24, 0)*24 - V18)/24 - 1)*100 -> 53.190972 | AA18: =(ABS((ROUNDUP(V18/24, 0)*24 - V18)/24 - 1) + IF(V18 > 24, MID(ROUNDUP(V18/24, 2), 1, 1), 0))*100 -> 353.19097 | AC18: SE-E2. 289-01 - "VÃO BX" - LINK 6,9 kV - EBV-02 | AF18: PROGRAMADA | AG18: 41.866667 | AI18: SE-E3. 289-01 - "VÃO BX" - LINK 6,9 kV - EBV-03 | AJ18: 1 | AL18: SE-E3. 289-01 - "VÃO BX" - LINK 6,9 kV - EBV-03 | AM18: 3.9 | AO18: SE-E3. 289-01 - "VÃO BX" - LINK 6,9 kV - EBV-03 | AP18: 20.1
B19: 45979 | C19: 5.725 | D19: 5.725 | H19: 45979 | I19: 1 | J19: 1 | Q19: PROGRAMADA | R19: 9.775 | S19: 40.729167 | T19: 59.270833 | V19: 20.599722 | W19: 85.832176 | Y19: =ABS((ROUNDUP(V19/24, 0)*24 - V19)/24 - 1)*100 -> 85.832176 | AA19: =(ABS((ROUNDUP(V19/24, 0)*24 - V19)/24 - 1) + IF(V19 > 24, MID(ROUNDUP(V19/24, 2), 1, 1), 0))*100 -> 85.832176 | AC19: PROGRAMADA | AD19: 1 | AF19: SE-E3. DJ6-03 - VÃO BX | AG19: 143.91593 | AI19: SE-E4. 289-01 - "VÃO BX" - LINK 6,9 kV - EBV-04 | AJ19: 1 | AL19: SE-E4. 289-01 - "VÃO BX" - LINK 6,9 kV - EBV-04 | AM19: 3.45 | AO19: SE-E4. 289-01 - "VÃO BX" - LINK 6,9 kV - EBV-04 | AP19: 20.55
B20: SE-E4. DJ6-03 - VÃO BX | C20: 9.1416667 | D20: 9.1416667 | H20: SE-E4. DJ6-03 - VÃO BX | I20: 2 | J20: 2 | Q20: 45979 | R20: 5.8916667 | S20: 24.548611 | T20: 75.451389 | V20: 23.999722 | W20: 99.998843 | Y20: =ABS((ROUNDUP(V20/24, 0)*24 - V20)/24 - 1)*100 -> 99.998843 | AA20: =(ABS((ROUNDUP(V20/24, 0)*24 - V20)/24 - 1) + IF(V20 > 24, MID(ROUNDUP(V20/24, 2), 1, 1), 0))*100 -> 99.998843 | AC20: SE-E3. 289-01 - "VÃO BX" - LINK 6,9 kV - EBV-03 | AF20: FORÇADA | AG20: 45.816204 | AI20: SE-E5. 289-01 - "VÃO BX" - LINK 6,9 kV - EBV-05 | AJ20: 1 | AL20: SE-E5. 289-01 - "VÃO BX" - LINK 6,9 kV - EBV-05 | AM20: 4.8833333 | AO20: SE-E5. 289-01 - "VÃO BX" - LINK 6,9 kV - EBV-05 | AP20: 19.116667
B21: 45979 | C21: 5.725 | D21: 5.725 | H21: 45979 | I21: 1 | J21: 1 | Q21: 46036 | R21: 3.8833333 | S21: 16.180556 | T21: 83.819444 | V21: 23.999722 | W21: 99.998843 | Y21: =ABS((ROUNDUP(V21/24, 0)*24 - V21)/24 - 1)*100 -> 99.998843 | AA21: =(ABS((ROUNDUP(V21/24, 0)*24 - V21)/24 - 1) + IF(V21 > 24, MID(ROUNDUP(V21/24, 2), 1, 1), 0))*100 -> 99.998843 | AC21: PROGRAMADA | AD21: 1 | AF21: PROGRAMADA | AG21: 98.099722
B22: 46037 | C22: 3.4166667 | D22: 3.4166667 | H22: 46037 | I22: 1 | J22: 1 | Q22: SE-E4. DJ6-02 - VÃO AY | R22: 5.725 | S22: 23.854167 | T22: 76.145833 | V22: 16.166667 | W22: 67.361111 | Y22: =ABS((ROUNDUP(V22/24, 0)*24 - V22)/24 - 1)*100 -> 67.361111 | AA22: =(ABS((ROUNDUP(V22/24, 0)*24 - V22)/24 - 1) + IF(V22 > 24, MID(ROUNDUP(V22/24, 2), 1, 1), 0))*100 -> 67.361111 | AC22: SE-E4. 289-01 - "VÃO BX" - LINK 6,9 kV - EBV-04 | AF22: SE-E4. DJ6-02 - VÃO AY | AG22: 80.104444
B23: SE-E5. DJ4-02 - VÃO AY | C23: 16.316667 | D23: 16.316667 | H23: SE-E5. DJ4-02 - VÃO AY | I23: 2 | J23: 2 | Q23: PROGRAMADA | R23: 5.725 | S23: 23.854167 | T23: 76.145833 | V23: 3.1 | W23: 12.916667 | Y23: =ABS((ROUNDUP(V23/24, 0)*24 - V23)/24 - 1)*100 -> 12.916667 | AA23: =(ABS((ROUNDUP(V23/24, 0)*24 - V23)/24 - 1) + IF(V23 > 24, MID(ROUNDUP(V23/24, 2), 1, 1), 0))*100 -> 12.916667 | AC23: PROGRAMADA | AD23: 1 | AF23: FORÇADA | AG23: 42.382917
B24: 45979 | C24: 11.45 | D24: 11.45 | H24: 45979 | I24: 1 | J24: 1 | Q24: 45979 | R24: 5.725 | S24: 23.854167 | T24: 76.145833 | V24: 3.1 | W24: 12.916667 | Y24: =ABS((ROUNDUP(V24/24, 0)*24 - V24)/24 - 1)*100 -> 12.916667 | AA24: =(ABS((ROUNDUP(V24/24, 0)*24 - V24)/24 - 1) + IF(V24 > 24, MID(ROUNDUP(V24/24, 2), 1, 1), 0))*100 -> 12.916667 | AC24: SE-E5. 289-01 - "VÃO BX" - LINK 6,9 kV - EBV-05 | AF24: PROGRAMADA | AG24: 37.721528
B25: 46038 | C25: 4.8666667 | D25: 4.8666667 | H25: 46038 | I25: 1 | J25: 1 | Q25: SE-E4. DJ6-03 - VÃO BX | R25: 9.1416667 | S25: 38.090278 | T25: 61.909722 | V25: 92.799167 | W25: 386.66319 | Y25: =ABS((ROUNDUP(V25/24, 0)*24 - V25)/24 - 1)*100 -> 86.663194 | AA25: =(ABS((ROUNDUP(V25/24, 0)*24 - V25)/24 - 1) + IF(V25 > 24, MID(ROUNDUP(V25/24, 2), 1, 1), 0))*100 -> 386.66319 | AC25: PROGRAMADA | AD25: 1 | AF25: SE-E4. DJ6-03 - VÃO BX | AG25: 117.62458
B26: SE-E6. DJ4-02 - VÃO AZ - RAMAL DO AGRESTE | C26: 3.6333333 | D26: 3.6333333 | H26: SE-E6. DJ4-02 - VÃO AZ - RAMAL DO AGRESTE | I26: 1 | J26: 1 | Q26: PROGRAMADA | R26: 9.1416667 | S26: 38.090278 | T26: 61.909722 | V26: 84.765833 | W26: 353.19097 | Y26: =ABS((ROUNDUP(V26/24, 0)*24 - V26)/24 - 1)*100 -> 53.190972 | AA26: =(ABS((ROUNDUP(V26/24, 0)*24 - V26)/24 - 1) + IF(V26 > 24, MID(ROUNDUP(V26/24, 2), 1, 1), 0))*100 -> 353.19097 | AF26: FORÇADA | AG26: 42.382917
B27: 45979 | C27: 3.6333333 | D27: 3.6333333 | H27: 45979 | I27: 1 | J27: 1 | Q27: 45979 | R27: 5.725 | S27: 23.854167 | T27: 76.145833 | V27: 20.599722 | W27: 85.832176 | Y27: =ABS((ROUNDUP(V27/24, 0)*24 - V27)/24 - 1)*100 -> 85.832176 | AA27: =(ABS((ROUNDUP(V27/24, 0)*24 - V27)/24 - 1) + IF(V27 > 24, MID(ROUNDUP(V27/24, 2), 1, 1), 0))*100 -> 85.832176 | AF27: PROGRAMADA | AG27: 75.241667
B28: SE-E6. DJ4-06 - VÃO CZ | C28: 3.6333333 | D28: 3.6333333 | H28: SE-E6. DJ4-06 - VÃO CZ | I28: 1 | J28: 1 | Q28: 46037 | R28: 3.4166667 | S28: 14.236111 | T28: 85.763889 | V28: 23.999722 | W28: 99.998843 | Y28: =ABS((ROUNDUP(V28/24, 0)*24 - V28)/24 - 1)*100 -> 99.998843 | AA28: =(ABS((ROUNDUP(V28/24, 0)*24 - V28)/24 - 1) + IF(V28 > 24, MID(ROUNDUP(V28/24, 2), 1, 1), 0))*100 -> 99.998843 | AF28: SE-E5. DJ4-02 - VÃO AY | AG28: 251.98222
B29: 45979 | C29: 3.6333333 | D29: 3.6333333 | H29: 45979 | I29: 1 | J29: 1 | Q29: SE-E5. DJ4-02 - VÃO AY | R29: 16.316667 | S29: 67.986111 | T29: 32.013889 | V29: 23.999722 | W29: 99.998843 | Y29: =ABS((ROUNDUP(V29/24, 0)*24 - V29)/24 - 1)*100 -> 99.998843 | AA29: =(ABS((ROUNDUP(V29/24, 0)*24 - V29)/24 - 1) + IF(V29 > 24, MID(ROUNDUP(V29/24, 2), 1, 1), 0))*100 -> 99.998843 | AF29: FORÇADA | AG29: 84.765833
B30: SE-E6. DJ6-01 - VÃO AX | C30: 3.6333333 | D30: 3.6333333 | H30: SE-E6. DJ6-01 - VÃO AX | I30: 1 | J30: 1 | Q30: PROGRAMADA | R30: 16.316667 | S30: 67.986111 | T30: 32.013889 | V30: 16.166667 | W30: 67.361111 | Y30: =ABS((ROUNDUP(V30/24, 0)*24 - V30)/24 - 1)*100 -> 67.361111 | AA30: =(ABS((ROUNDUP(V30/24, 0)*24 - V30)/24 - 1) + IF(V30 > 24, MID(ROUNDUP(V30/24, 2), 1, 1), 0))*100 -> 67.361111 | AF30: PROGRAMADA | AG30: 167.21639
B31: 45979 | C31: 3.6333333 | D31: 3.6333333 | H31: 45979 | I31: 1 | J31: 1 | Q31: 45979 | R31: 11.45 | S31: 47.708333 | T31: 52.291667 | V31: 8.0333333 | W31: 33.472222 | Y31: =ABS((ROUNDUP(V31/24, 0)*24 - V31)/24 - 1)*100 -> 33.472222 | AA31: =(ABS((ROUNDUP(V31/24, 0)*24 - V31)/24 - 1) + IF(V31 > 24, MID(ROUNDUP(V31/24, 2), 1, 1), 0))*100 -> 33.472222 | AF31: SE-E6. DJ4-02 - VÃO AZ - RAMAL DO AGRESTE | AG31: 109.05634
B32: SE-E1. 289-01 - "VÃO BX" - LINK 6,9 kV - EBV-01 | C32: 4.6166667 | D32: 4.6166667 | H32: SE-E1. 289-01 - "VÃO BX" - LINK 6,9 kV - EBV-01 | I32: 1 | J32: 1 | Q32: 46038 | R32: 4.8666667 | S32: 20.277778 | T32: 79.722222 | V32: 8.0333333 | W32: 33.472222 | Y32: =ABS((ROUNDUP(V32/24, 0)*24 - V32)/24 - 1)*100 -> 33.472222 | AA32: =(ABS((ROUNDUP(V32/24, 0)*24 - V32)/24 - 1) + IF(V32 > 24, MID(ROUNDUP(V32/24, 2), 1, 1), 0))*100 -> 33.472222 | AF32: FORÇADA | AG32: 55.688287
B33: 46034 | C33: 4.6166667 | D33: 4.6166667 | H33: 46034 | I33: 1 | J33: 1 | Q33: SE-E6. DJ4-02 - VÃO AZ - RAMAL DO AGRESTE | R33: 3.6333333 | S33: 15.138889 | T33: 84.861111 | V33: 105.36556 | W33: 439.02315 | Y33: =ABS((ROUNDUP(V33/24, 0)*24 - V33)/24 - 1)*100 -> 39.023148 | AA33: =(ABS((ROUNDUP(V33/24, 0)*24 - V33)/24 - 1) + IF(V33 > 24, MID(ROUNDUP(V33/24, 2), 1, 1), 0))*100 -> 439.02315 | AF33: PROGRAMADA | AG33: 53.368056
B34: SE-E2. 289-01 - "VÃO BX" - LINK 6,9 kV - EBV-02 | C34: 3.6 | D34: 3.6 | H34: SE-E2. 289-01 - "VÃO BX" - LINK 6,9 kV - EBV-02 | I34: 1 | J34: 1 | Q34: PROGRAMADA | R34: 3.6333333 | S34: 15.138889 | T34: 84.861111 | V34: 105.36556 | W34: 439.02315 | Y34: =ABS((ROUNDUP(V34/24, 0)*24 - V34)/24 - 1)*100 -> 39.023148 | AA34: =(ABS((ROUNDUP(V34/24, 0)*24 - V34)/24 - 1) + IF(V34 > 24, MID(ROUNDUP(V34/24, 2), 1, 1), 0))*100 -> 439.02315 | AF34: SE-E6. DJ4-06 - VÃO CZ | AG34: 74.823287
B35: 46035 | C35: 3.6 | D35: 3.6 | H35: 46035 | I35: 1 | J35: 1 | Q35: 45979 | R35: 3.6333333 | S35: 15.138889 | T35: 84.861111 | V35: 41.199444 | W35: 171.66435 | Y35: =ABS((ROUNDUP(V35/24, 0)*24 - V35)/24 - 1)*100 -> 71.664352 | AA35: =(ABS((ROUNDUP(V35/24, 0)*24 - V35)/24 - 1) + IF(V35 > 24, MID(ROUNDUP(V35/24, 2), 1, 1), 0))*100 -> 171.66435 | AF35: FORÇADA | AG35: 31.688565
B36: SE-E3. 289-01 - "VÃO BX" - LINK 6,9 kV - EBV-03 | C36: 3.9 | D36: 3.9 | H36: SE-E3. 289-01 - "VÃO BX" - LINK 6,9 kV - EBV-03 | I36: 1 | J36: 1 | Q36: SE-E6. DJ4-06 - VÃO CZ | R36: 3.6333333 | S36: 15.138889 | T36: 84.861111 | V36: 23.999722 | W36: 99.998843 | Y36: =ABS((ROUNDUP(V36/24, 0)*24 - V36)/24 - 1)*100 -> 99.998843 | AA36: =(ABS((ROUNDUP(V36/24, 0)*24 - V36)/24 - 1) + IF(V36 > 24, MID(ROUNDUP(V36/24, 2), 1, 1), 0))*100 -> 99.998843 | AF36: PROGRAMADA | AG36: 43.134722
B37: 46036 | C37: 3.9 | D37: 3.9 | H37: 46036 | I37: 1 | J37: 1 | Q37: PROGRAMADA | R37: 3.6333333 | S37: 15.138889 | T37: 84.861111 | V37: 23.999722 | W37: 99.998843 | Y37: =ABS((ROUNDUP(V37/24, 0)*24 - V37)/24 - 1)*100 -> 99.998843 | AA37: =(ABS((ROUNDUP(V37/24, 0)*24 - V37)/24 - 1) + IF(V37 > 24, MID(ROUNDUP(V37/24, 2), 1, 1), 0))*100 -> 99.998843 | AF37: SE-E6. DJ6-01 - VÃO AX | AG37: 101.94398
B38: SE-E4. 289-01 - "VÃO BX" - LINK 6,9 kV - EBV-04 | C38: 3.45 | D38: 3.45 | H38: SE-E4. 289-01 - "VÃO BX" - LINK 6,9 kV - EBV-04 | I38: 1 | J38: 1 | Q38: 45979 | R38: 3.6333333 | S38: 15.138889 | T38: 84.861111 | V38: 16.166667 | W38: 67.361111 | Y38: =ABS((ROUNDUP(V38/24, 0)*24 - V38)/24 - 1)*100 -> 67.361111 | AA38: =(ABS((ROUNDUP(V38/24, 0)*24 - V38)/24 - 1) + IF(V38 > 24, MID(ROUNDUP(V38/24, 2), 1, 1), 0))*100 -> 67.361111 | AF38: FORÇADA | AG38: 21.388704
B39: 46037 | C39: 3.45 | D39: 3.45 | H39: 46037 | I39: 1 | J39: 1 | Q39: SE-E6. DJ6-01 - VÃO AX | R39: 3.6333333 | S39: 15.138889 | T39: 84.861111 | V39: 93.699167 | W39: 390.41319 | Y39: =ABS((ROUNDUP(V39/24, 0)*24 - V39)/24 - 1)*100 -> 90.413194 | AA39: =(ABS((ROUNDUP(V39/24, 0)*24 - V39)/24 - 1) + IF(V39 > 24, MID(ROUNDUP(V39/24, 2), 1, 1), 0))*100 -> 390.41319 | AF39: PROGRAMADA | AG39: 80.555278
B40: SE-E5. 289-01 - "VÃO BX" - LINK 6,9 kV - EBV-05 | C40: 4.8833333 | D40: 4.8833333 | H40: SE-E5. 289-01 - "VÃO BX" - LINK 6,9 kV - EBV-05 | I40: 1 | J40: 1 | Q40: PROGRAMADA | R40: 3.6333333 | S40: 15.138889 | T40: 84.861111 | V40: 84.765833 | W40: 353.19097 | Y40: =ABS((ROUNDUP(V40/24, 0)*24 - V40)/24 - 1)*100 -> 53.190972 | AA40: =(ABS((ROUNDUP(V40/24, 0)*24 - V40)/24 - 1) + IF(V40 > 24, MID(ROUNDUP(V40/24, 2), 1, 1), 0))*100 -> 353.19097 | AF40: (vazio) | AG40: 0
B41: 46038 | C41: 4.8833333 | D41: 4.8833333 | H41: 46038 | I41: 1 | J41: 1 | Q41: 45979 | R41: 3.6333333 | S41: 15.138889 | T41: 84.861111 | V41: 20.599722 | W41: 85.832176 | Y41: =ABS((ROUNDUP(V41/24, 0)*24 - V41)/24 - 1)*100 -> 85.832176 | AA41: =(ABS((ROUNDUP(V41/24, 0)*24 - V41)/24 - 1) + IF(V41 > 24, MID(ROUNDUP(V41/24, 2), 1, 1), 0))*100 -> 85.832176 | AF41: (vazio) | AG41: 0
B42: Total Geral | C42: 95.758333 | D42: 95.758333 | H42: Total Geral | I42: 20 | J42: 20 | Q42: SE-E1. 289-01 - "VÃO BX" - LINK 6,9 kV - EBV-01 | R42: 4.6166667 | S42: 19.236111 | T42: 80.763889 | V42: 23.999722 | W42: 99.998843 | Y42: =ABS((ROUNDUP(V42/24, 0)*24 - V42)/24 - 1)*100 -> 99.998843 | AA42: =(ABS((ROUNDUP(V42/24, 0)*24 - V42)/24 - 1) + IF(V42 > 24, MID(ROUNDUP(V42/24, 2), 1, 1), 0))*100 -> 99.998843 | AF42: SE-E6. DJ6-03 - VÃO BX | AG42: 1.9083333
...

Sheet BCKSTG-ANALYSIS
B2: #001 – Quantitativo para Desligamentos Forçados e Programados
B4: Duração Total de Paradas Forçadas [h] | C4: Duração Total de Paradas Programadas [h] | D4: Duração Total [h] | E4: % Duração Total de Paradas Forçadas | F4: % Duração Total de Paradas Programadas
B5: =IFERROR(IF(GETPIVOTDATA("Duração da Parada (H)",'BCKSTG-TABLES'!$B$4,"Tipo","FORÇADA") <> "", GETPIVOTDATA("Duração da Parada (H)",'BCKSTG-TABLES'!$B$4,"Tipo","FORÇADA"), 0), 0) -> 0 | C5: =IFERROR(IF(GETPIVOTDATA("Duração da Parada (H)",'BCKSTG-TABLES'!$B$4,"Tipo","PROGRAMADA") <> "", GETPIVOTDATA("Duração da Parada (H)",'BCKSTG-TABLES'!$B$4,"Tipo","PROGRAMADA"), 0), 0) -> 95.758333 | D5: =IFERROR(IF(GETPIVOTDATA("Duração da Parada (H)",'BCKSTG-TABLES'!$B$4) <> "", GETPIVOTDATA("Duração da Parada (H)",'BCKSTG-TABLES'!$B$4), 0), 0) -> 95.758333 | E5: =IFERROR(($B$5/$D$5), 0) -> 0 | F5: =IFERROR(($C$5/$D$5), 0) -> 1
B7: #002 – Contagem de Desligamentos Forçados e Programados
B9: Quantidade de Paradas Forçadas | C9: Quantidade de Paradas Programadas | D9: Quantidade Total | E9: % Quantidade de Paradas Forçadas | F9: % Quantidade de Paradas Programadas
B10: =IFERROR(IF(GETPIVOTDATA("Duração da Parada (H)",'BCKSTG-TABLES'!$H$4,"Tipo","FORÇADA") <> "", GETPIVOTDATA("Duração da Parada (H)",'BCKSTG-TABLES'!$H$4,"Tipo","FORÇADA"), 0), 0) -> 0 | C10: =IFERROR(IF(GETPIVOTDATA("Duração da Parada (H)",'BCKSTG-TABLES'!$H$4,"Tipo","PROGRAMADA") <> "", GETPIVOTDATA("Duração da Parada (H)",'BCKSTG-TABLES'!$H$4,"Tipo","PROGRAMADA"), 0), 0) -> 20 | D10: =IFERROR(IF(GETPIVOTDATA("Duração da Parada (H)",'BCKSTG-TABLES'!$H$4) <> "", GETPIVOTDATA("Duração da Parada (H)",'BCKSTG-TABLES'!$H$4), 0), 0) -> 20 | E10: =IFERROR(($B$10/$D$10), 0) -> 0 | F10: =IFERROR(($C$10/$D$10), 0) -> 1
B12: #002 – Contagem de Desligamentos Forçados e Programados
B14: Quantidade de Paradas Forçadas | C14: Quantidade de Paradas Programadas | D14: Quantidade Total | E14: % Quantidade de Paradas Forçadas | F14: % Quantidade de Paradas Programadas
B15: =IFERROR(IF(GETPIVOTDATA("Duração da Parada (H)",'BCKSTG-TABLES'!$H$4,"Tipo","FORÇADA") <> "", GETPIVOTDATA("Duração da Parada (H)",'BCKSTG-TABLES'!$H$4,"Tipo","FORÇADA"), 0), 0) -> 0 | C15: =IFERROR(IF(GETPIVOTDATA("Duração da Parada (H)",'BCKSTG-TABLES'!$H$4,"Tipo","PROGRAMADA") <> "", GETPIVOTDATA("Duração da Parada (H)",'BCKSTG-TABLES'!$H$4,"Tipo","PROGRAMADA"), 0), 0) -> 20 | D15: =IFERROR(IF(GETPIVOTDATA("Duração da Parada (H)",'BCKSTG-TABLES'!$H$4) <> "", GETPIVOTDATA("Duração da Parada (H)",'BCKSTG-TABLES'!$H$4), 0), 0) -> 20 | E15: =IFERROR(($B$10/$D$10), 0) -> 0 | F15: =IFERROR(($C$10/$D$10), 0) -> 1
B17: #005 – Contagem de Estruturas Ativas | H17: #008 – Quantitativo de Horas por Estrutura | M17: 168 | O17: Resumo geral dos indicadores de manutenção
B19: Estruturas | C19: Total | D19: Ativas | E19: Inativas | H19: SE-E1. DJ6-02 - VÃO BX | J19: SE-E2. DJ6-02 - VÃO AY | L19: SE-E2. DJ6-03 - VÃO BX
B20: SE-E1. DJ6-02 - VÃO BX | C20: =COUNTIF($B$20:$B$40, "<>") -> 18 | D20: =IF(COUNTIF('BCKSTG-TABLES'!AI:AI, "<>") - 2 > $C$20, $C$20, COUNTIF('BCKSTG-TABLES'!AI:AI, "<>") - 2) -> 16 | E20: =$C$20 - $D$20 -> 2 | H20: MTBF = | I20: =IFERROR(IF(_xlfn.NUMBERVALUE(TEXT((I27 - I28)/GETPIVOTDATA("Duração da Parada (h)",'BCKSTG-TABLES'!$AI$4,"Estrutura", H19), "0,00")) < 0, "—", TEXT((I27 - I28)/GETPIVOTDATA("Duração da Parada (h)",'BCKSTG-TABLES'!$AI$4,"Estrutura", H19), "0,00") & "h"), "—") -> 26467,41h | J20: MTBF = | K20: =IFERROR(IF(_xlfn.NUMBERVALUE(TEXT((K27 - K28)/GETPIVOTDATA("Duração da Parada (h)",'BCKSTG-TABLES'!$AI$4,"Estrutura", J19), "0,00")) < 0, "—", TEXT((K27 - K28)/GETPIVOTDATA("Duração da Parada (h)",'BCKSTG-TABLES'!$AI$4,"Estrutura", J19), "0,00") & "h"), "—") -> 12523,35h | L20: MTBF = | M20: =IFERROR(IF(_xlfn.NUMBERVALUE(TEXT((M27 - M28)/GETPIVOTDATA("Duração da Parada (h)",'BCKSTG-TABLES'!$AI$4,"Estrutura", L19), "0,00")) < 0, "—", TEXT((M27 - M28)/GETPIVOTDATA("Duração da Parada (h)",'BCKSTG-TABLES'!$AI$4,"Estrutura", L19), "0,00") & "h"), "—") -> 12679,84h | P20: MTBF | Q20: MTTR | R20: DISP | S20: CONF
B21: SE-E2. DJ6-02 - VÃO AY | H21: MTTR = | I21: =IFERROR(TEXT((GETPIVOTDATA("Duração da Parada (h)",'BCKSTG-TABLES'!$AL$4,"Estrutura", H19)/GETPIVOTDATA("Duração da Parada (h)",'BCKSTG-TABLES'!$AI$4,"Estrutura", H19)), "0,00") & "h", "—") -> 4,59h | J21: MTTR = | K21: =IFERROR(TEXT((GETPIVOTDATA("Duração da Parada (h)",'BCKSTG-TABLES'!$AL$4,"Estrutura", J19)/GETPIVOTDATA("Duração da Parada (h)",'BCKSTG-TABLES'!$AI$4,"Estrutura", J19)), "0,00") & "h", "—") -> 4,65h | L21: MTTR = | M21: =IFERROR(TEXT((GETPIVOTDATA("Duração da Parada (h)",'BCKSTG-TABLES'!$AL$4,"Estrutura", L19)/GETPIVOTDATA("Duração da Parada (h)",'BCKSTG-TABLES'!$AI$4,"Estrutura", L19)), "0,00") & "h", "—") -> 4,16h | O21: MÁXIMO | P21: {=TEXT(MAX(IF(P$25:P$36 > 0, P$25:P$36)), "0,00") & "h"} -> 26467,41h | Q21: {=TEXT(MAX(IF(Q$25:Q$36 > 0, Q$25:Q$36)), "0,00") & "h"} -> 8,16h | R21: {=MAX(IF(R$25:R$36 > 0, R$25:R$36))} -> 0.99985372 | S21: {=MAX(IF(S$25:S$36 > 0, S$25:S$36))} -> 0.99369192
B22: SE-E2. DJ6-03 - VÃO BX | H22: DISP = | I22: =IFERROR((MID('BCKSTG-ANALYSIS'!I20, 1, LEN('BCKSTG-ANALYSIS'!I20) - 1))/(MID('BCKSTG-ANALYSIS'!I20, 1, LEN('BCKSTG-ANALYSIS'!I20) - 1) + MID('BCKSTG-ANALYSIS'!I21, 1, LEN('BCKSTG-ANALYSIS'!I21) - 1)), "—") -> 0.99982661 | J22: DISP = | K22: =IFERROR((MID('BCKSTG-ANALYSIS'!K20, 1, LEN('BCKSTG-ANALYSIS'!K20) - 1))/(MID('BCKSTG-ANALYSIS'!K20, 1, LEN('BCKSTG-ANALYSIS'!K20) - 1) + MID('BCKSTG-ANALYSIS'!K21, 1, LEN('BCKSTG-ANALYSIS'!K21) - 1)), "—") -> 0.99962883 | L22: DISP = | M22: =IFERROR((MID('BCKSTG-ANALYSIS'!M20, 1, LEN('BCKSTG-ANALYSIS'!M20) - 1))/(MID('BCKSTG-ANALYSIS'!M20, 1, LEN('BCKSTG-ANALYSIS'!M20) - 1) + MID('BCKSTG-ANALYSIS'!M21, 1, LEN('BCKSTG-ANALYSIS'!M21) - 1)), "—") -> 0.99967203 | O22: MÍNIMO | P22: {=TEXT(MIN(IF(P$25:P$36 > 0, P$25:P$36)), "0,00") & "h"} -> 12523,35h | Q22: {=TEXT(MIN(IF(Q$25:Q$36 > 0, Q$25:Q$36)), "0,00") & "h"} -> 3,63h | R22: {=MIN(IF(R$25:R$36 > 0, R$25:R$36))} -> 0.99935728 | S22: {=MIN(IF(S$25:S$36 > 0, S$25:S$36))} -> 0.98671503
B23: SE-E3. DJ6-02 - VÃO AY | H23: CONF = | I23: =IFERROR((2.71^-((1/MID('BCKSTG-ANALYSIS'!I20, 1, LEN('BCKSTG-ANALYSIS'!I20) - 1))*($M$17))), "—") -> 0.99369192 | J23: CONF = | K23: =IFERROR((2.71^-((1/MID('BCKSTG-ANALYSIS'!K20, 1, LEN('BCKSTG-ANALYSIS'!K20) - 1))*($M$17))), "—") -> 0.98671503 | L23: CONF = | M23: =IFERROR((2.71^-((1/MID('BCKSTG-ANALYSIS'!M20, 1, LEN('BCKSTG-ANALYSIS'!M20) - 1))*($M$17))), "—") -> 0.98687791 | O23: MÉDIA | P23: {=IFERROR(TEXT(AVERAGE(IF(P$25:P$36 > 0, P$25:P$36)), "0,00") & "h", "0,00h")} -> 18162,04h | Q23: {=IFERROR(TEXT(AVERAGE(IF(Q$25:Q$36 > 0, Q$25:Q$36)), "0,00") & "h", "0,00h")} -> 4,87h | R23: {=IFERROR(AVERAGE(IF(R$25:R$36 > 0, R$25:R$36)), "0,00h")} -> 0.99969111 | S23: {=IFERROR(AVERAGE(IF(S$25:S$36 > 0, S$25:S$36)), "0,00h")} -> 0.98978807
B24: SE-E3. DJ6-03 - VÃO BX
B25: SE-E4. DJ6-02 - VÃO AY | H25: Data mais antiga | I25: {=_xlfn.MINIFS(Preenchimento!$B:$B, Preenchimento!$C:$C, 'BCKSTG-ANALYSIS'!H19:H19)} -> 44974 | J25: Data mais antiga | K25: {=_xlfn.MINIFS(Preenchimento!$B:$B, Preenchimento!$C:$C, 'BCKSTG-ANALYSIS'!J19:J19)} -> 45520 | L25: Data mais antiga | M25: {=_xlfn.MINIFS(Preenchimento!$B:$B, Preenchimento!$C:$C, 'BCKSTG-ANALYSIS'!L19:L19)} -> 44985 | O25: SE-E1. DJ6-02 - VÃO BX | P25: =_xlfn.NUMBERVALUE(MID(I20, 1, LEN(I20) - 1)) -> 26467.41 | Q25: =_xlfn.NUMBERVALUE(MID(I21, 1, LEN(I21) - 1)) -> 4.59 | R25: =_xlfn.NUMBERVALUE(MID(I22, 1, LEN(I22) - 1)) -> 0.99982661 | S25: =_xlfn.NUMBERVALUE(MID(I23, 1, LEN(I23) - 1)) -> 0.99369192
B26: SE-E4. DJ6-03 - VÃO BX | H26: Data mais recente | I26: {=_xlfn.MAXIFS(Preenchimento!$B:$B, Preenchimento!$C:$C, 'BCKSTG-ANALYSIS'!H19:H19)} -> 46077 | J26: Data mais recente | K26: {=_xlfn.MAXIFS(Preenchimento!$B:$B, Preenchimento!$C:$C, 'BCKSTG-ANALYSIS'!J19:J19)} -> 46042 | L26: Data mais recente | M26: {=_xlfn.MAXIFS(Preenchimento!$B:$B, Preenchimento!$C:$C, 'BCKSTG-ANALYSIS'!L19:L19)} -> 46042 | O26: SE-E2. DJ6-02 - VÃO AY | P26: =_xlfn.NUMBERVALUE(MID(K20, 1, LEN(K20) - 1)) -> 12523.35 | Q26: =_xlfn.NUMBERVALUE(MID(K21, 1, LEN(K21) - 1)) -> 4.65 | R26: =_xlfn.NUMBERVALUE(MID(K22, 1, LEN(K22) - 1)) -> 0.99962883 | S26: =_xlfn.NUMBERVALUE(MID(K23, 1, LEN(K23) - 1)) -> 0.98671503
B27: SE-E5. DJ4-02 - VÃO AY | H27: Tempo total de operação (sem deduções) | I27: =(I26 - I25)*24 -> 26472 | J27: Tempo total de operação (sem deduções) | K27: =(K26 - K25)*24 -> 12528 | L27: Tempo total de operação (sem deduções) | M27: =(M26 - M25)*24 -> 25368 | O27: SE-E2. DJ6-03 - VÃO BX | P27: =_xlfn.NUMBERVALUE(MID(M20, 1, LEN(M20) - 1)) -> 12679.84 | Q27: =_xlfn.NUMBERVALUE(MID(M21, 1, LEN(M21) - 1)) -> 4.16 | R27: =_xlfn.NUMBERVALUE(MID(M22, 1, LEN(M22) - 1)) -> 0.99967203 | S27: =_xlfn.NUMBERVALUE(MID(M23, 1, LEN(M23) - 1)) -> 0.98687791
B28: SE-E6. DJ4-02 - VÃO AZ - RAMAL DO AGRESTE | H28: Tempo total de parada | I28: {=IFERROR(GETPIVOTDATA("Duração da Parada (h)",'BCKSTG-TABLES'!$AL$4,"Estrutura", 'BCKSTG-ANALYSIS'!H19:H19), "—")} -> 4.5916667 | J28: Tempo total de parada | K28: {=IFERROR(GETPIVOTDATA("Duração da Parada (h)",'BCKSTG-TABLES'!$AL$4,"Estrutura", 'BCKSTG-ANALYSIS'!J19:J19), "—")} -> 4.65 | L28: Tempo total de parada | M28: {=IFERROR(GETPIVOTDATA("Duração da Parada (h)",'BCKSTG-TABLES'!$AL$4,"Estrutura", 'BCKSTG-ANALYSIS'!L19:L19), "—")} -> 8.3166667 | O28: SE-E3. DJ6-02 - VÃO AY | P28: =_xlfn.NUMBERVALUE(MID(I31, 1, LEN(I31) - 1)) -> 13266.11 | Q28: =_xlfn.NUMBERVALUE(MID(I32, 1, LEN(I32) - 1)) -> 5.89 | R28: =_xlfn.NUMBERVALUE(MID(I33, 1, LEN(I33) - 1)) -> 0.99955621 | S28: =_xlfn.NUMBERVALUE(MID(I34, 1, LEN(I34) - 1)) -> 0.98745416
B29: SE-E6. DJ4-06 - VÃO CZ | O29: SE-E3. DJ6-03 - VÃO BX | P29: =_xlfn.NUMBERVALUE(MID(K31, 1, LEN(K31) - 1)) -> 12691.11 | Q29: =_xlfn.NUMBERVALUE(MID(K32, 1, LEN(K32) - 1)) -> 4.89 | R29: =_xlfn.NUMBERVALUE(MID(K33, 1, LEN(K33) - 1)) -> 0.99961484 | S29: =_xlfn.NUMBERVALUE(MID(K34, 1, LEN(K34) - 1)) -> 0.98688948
B30: SE-E6. DJ6-01 - VÃO AX | H30: SE-E3. DJ6-02 - VÃO AY | J30: SE-E3. DJ6-03 - VÃO BX | L30: SE-E4. DJ6-02 - VÃO AY | O30: SE-E4. DJ6-02 - VÃO AY | P30: =_xlfn.NUMBERVALUE(MID(M31, 1, LEN(M31) - 1)) -> 23466.28 | Q30: =_xlfn.NUMBERVALUE(MID(M32, 1, LEN(M32) - 1)) -> 5.73 | R30: =_xlfn.NUMBERVALUE(MID(M33, 1, LEN(M33) - 1)) -> 0.99975588 | S30: =_xlfn.NUMBERVALUE(MID(M34, 1, LEN(M34) - 1)) -> 0.99288805
B31: PONTO DE CONEXÃO 04P2 | H31: MTBF = | I31: =IFERROR(IF(_xlfn.NUMBERVALUE(TEXT((I38 - I39)/GETPIVOTDATA("Duração da Parada (h)",'BCKSTG-TABLES'!$AI$4,"Estrutura", H30), "0,00")) < 0, "—", TEXT((I38 - I39)/GETPIVOTDATA("Duração da Parada (h)",'BCKSTG-TABLES'!$AI$4,"Estrutura", H30), "0,00") & "h"), "—") -> 13266,11h | J31: MTBF = | K31: =IFERROR(IF(_xlfn.NUMBERVALUE(TEXT((K38 - K39)/GETPIVOTDATA("Duração da Parada (h)",'BCKSTG-TABLES'!$AI$4,"Estrutura", J30), "0,00")) < 0, "—", TEXT((K38 - K39)/GETPIVOTDATA("Duração da Parada (h)",'BCKSTG-TABLES'!$AI$4,"Estrutura", J30), "0,00") & "h"), "—") -> 12691,11h | L31: MTBF = | M31: =IFERROR(IF(_xlfn.NUMBERVALUE(TEXT((M38 - M39)/GETPIVOTDATA("Duração da Parada (h)",'BCKSTG-TABLES'!$AI$4,"Estrutura", L30), "0,00")) < 0, "—", TEXT((M38 - M39)/GETPIVOTDATA("Duração da Parada (h)",'BCKSTG-TABLES'!$AI$4,"Estrutura", L30), "0,00") & "h"), "—") -> 23466,28h | O31: SE-E4. DJ6-03 - VÃO BX | P31: =_xlfn.NUMBERVALUE(MID(I42, 1, LEN(I42) - 1)) -> 12523.43 | Q31: =_xlfn.NUMBERVALUE(MID(I43, 1, LEN(I43) - 1)) -> 4.57 | R31: =_xlfn.NUMBERVALUE(MID(I44, 1, LEN(I44) - 1)) -> 0.99963522 | S31: =_xlfn.NUMBERVALUE(MID(I45, 1, LEN(I45) - 1)) -> 0.98671511
B32: SE-E1. 289-01 - "VÃO BX" - LINK 6,9 kV - EBV-01 | H32: MTTR = | I32: =IFERROR(TEXT((GETPIVOTDATA("Duração da Parada (h)",'BCKSTG-TABLES'!$AL$4,"Estrutura", H30)/GETPIVOTDATA("Duração da Parada (h)",'BCKSTG-TABLES'!$AI$4,"Estrutura", H30)), "0,00") & "h", "—") -> 5,89h | J32: MTTR = | K32: =IFERROR(TEXT((GETPIVOTDATA("Duração da Parada (h)",'BCKSTG-TABLES'!$AL$4,"Estrutura", J30)/GETPIVOTDATA("Duração da Parada (h)",'BCKSTG-TABLES'!$AI$4,"Estrutura", J30)), "0,00") & "h", "—") -> 4,89h | L32: MTTR = | M32: =IFERROR(TEXT((GETPIVOTDATA("Duração da Parada (h)",'BCKSTG-TABLES'!$AL$4,"Estrutura", L30)/GETPIVOTDATA("Duração da Parada (h)",'BCKSTG-TABLES'!$AI$4,"Estrutura", L30)), "0,00") & "h", "—") -> 5,73h | O32: SE-E5. DJ4-02 - VÃO AY | P32: =_xlfn.NUMBERVALUE(MID(K42, 1, LEN(K42) - 1)) -> 12687.84 | Q32: =_xlfn.NUMBERVALUE(MID(K43, 1, LEN(K43) - 1)) -> 8.16 | R32: =_xlfn.NUMBERVALUE(MID(K44, 1, LEN(K44) - 1)) -> 0.99935728 | S32: =_xlfn.NUMBERVALUE(MID(K45, 1, LEN(K45) - 1)) -> 0.98688612
B33: SE-E2. 289-01 - "VÃO BX" - LINK 6,9 kV - EBV-02 | H33: DISP = | I33: =IFERROR((MID('BCKSTG-ANALYSIS'!I31, 1, LEN('BCKSTG-ANALYSIS'!I31) - 1))/(MID('BCKSTG-ANALYSIS'!I31, 1, LEN('BCKSTG-ANALYSIS'!I31) - 1) + MID('BCKSTG-ANALYSIS'!I32, 1, LEN('BCKSTG-ANALYSIS'!I32) - 1)), "—") -> 0.99955621 | J33: DISP = | K33: =IFERROR((MID('BCKSTG-ANALYSIS'!K31, 1, LEN('BCKSTG-ANALYSIS'!K31) - 1))/(MID('BCKSTG-ANALYSIS'!K31, 1, LEN('BCKSTG-ANALYSIS'!K31) - 1) + MID('BCKSTG-ANALYSIS'!K32, 1, LEN('BCKSTG-ANALYSIS'!K32) - 1)), "—") -> 0.99961484 | L33: DISP = | M33: =IFERROR((MID('BCKSTG-ANALYSIS'!M31, 1, LEN('BCKSTG-ANALYSIS'!M31) - 1))/(MID('BCKSTG-ANALYSIS'!M31, 1, LEN('BCKSTG-ANALYSIS'!M31) - 1) + MID('BCKSTG-ANALYSIS'!M32, 1, LEN('BCKSTG-ANALYSIS'!M32) - 1)), "—") -> 0.99975588 | O33: SE-E6. DJ4-02 - VÃO AZ - RAMAL DO AGRESTE | P33: =_xlfn.NUMBERVALUE(MID(M42, 1, LEN(M42) - 1)) -> 24644.37 | Q33: =_xlfn.NUMBERVALUE(MID(M43, 1, LEN(M43) - 1)) -> 3.63 | R33: =_xlfn.NUMBERVALUE(MID(M44, 1, LEN(M44) - 1)) -> 0.99985273 | S33: =_xlfn.NUMBERVALUE(MID(M45, 1, LEN(M45) - 1)) -> 0.99322687
B34: SE-E3. 289-01 - "VÃO BX" - LINK 6,9 kV - EBV-03 | H34: CONF = | I34: =IFERROR((2.71^-((1/MID('BCKSTG-ANALYSIS'!I31, 1, LEN('BCKSTG-ANALYSIS'!I31) - 1))*($M$17))), "—") -> 0.98745416 | J34: CONF = | K34: =IFERROR((2.71^-((1/MID('BCKSTG-ANALYSIS'!K31, 1, LEN('BCKSTG-ANALYSIS'!K31) - 1))*($M$17))), "—") -> 0.98688948 | L34: CONF = | M34: =IFERROR((2.71^-((1/MID('BCKSTG-ANALYSIS'!M31, 1, LEN('BCKSTG-ANALYSIS'!M31) - 1))*($M$17))), "—") -> 0.99288805 | O34: SE-E6. DJ4-06 - VÃO CZ | P34: =_xlfn.NUMBERVALUE(MID(I53, 1, LEN(I53) - 1)) -> 24020.37 | Q34: =_xlfn.NUMBERVALUE(MID(I54, 1, LEN(I54) - 1)) -> 3.63 | R34: =_xlfn.NUMBERVALUE(MID(I55, 1, LEN(I55) - 1)) -> 0.9998489 | S34: =_xlfn.NUMBERVALUE(MID(I56, 1, LEN(I56) - 1)) -> 0.99305153
B35: SE-E4. 289-01 - "VÃO BX" - LINK 6,9 kV - EBV-04 | O35: SE-E6. DJ6-01 - VÃO AX | P35: =_xlfn.NUMBERVALUE(MID(K53, 1, LEN(K53) - 1)) -> 24812.37 | Q35: =_xlfn.NUMBERVALUE(MID(K54, 1, LEN(K54) - 1)) -> 3.63 | R35: =_xlfn.NUMBERVALUE(MID(K55, 1, LEN(K55) - 1)) -> 0.99985372 | S35: =_xlfn.NUMBERVALUE(MID(K56, 1, LEN(K56) - 1)) -> 0.99327258
B36: SE-E5. 289-01 - "VÃO BX" - LINK 6,9 kV - EBV-05 | H36: Data mais antiga | I36: {=_xlfn.MINIFS(Preenchimento!$B:$B, Preenchimento!$C:$C, 'BCKSTG-ANALYSIS'!H30:H30)} -> 45489 | J36: Data mais antiga | K36: {=_xlfn.MINIFS(Preenchimento!$B:$B, Preenchimento!$C:$C, 'BCKSTG-ANALYSIS'!J30:J30)} -> 44984 | L36: Data mais antiga | M36: {=_xlfn.MINIFS(Preenchimento!$B:$B, Preenchimento!$C:$C, 'BCKSTG-ANALYSIS'!L30:L30)} -> 45064 | O36: PONTO DE CONEXÃO 04P2 | P36: =_xlfn.NUMBERVALUE(MID(M53, 1, LEN(M53) - 1)) -> 0 | Q36: =_xlfn.NUMBERVALUE(MID(M54, 1, LEN(M54) - 1)) -> 0 | R36: =_xlfn.NUMBERVALUE(MID(M55, 1, LEN(M55) - 1)) -> 0 | S36: =_xlfn.NUMBERVALUE(MID(M56, 1, LEN(M56) - 1)) -> 0
B37: SE-E6. 289-01 - "VÃO BX" - LINK 6,9 kV - EBV-06 | H37: Data mais recente | I37: {=_xlfn.MAXIFS(Preenchimento!$B:$B, Preenchimento!$C:$C, 'BCKSTG-ANALYSIS'!H30:H30)} -> 46042 | J37: Data mais recente | K37: {=_xlfn.MAXIFS(Preenchimento!$B:$B, Preenchimento!$C:$C, 'BCKSTG-ANALYSIS'!J30:J30)} -> 46042 | L37: Data mais recente | M37: {=_xlfn.MAXIFS(Preenchimento!$B:$B, Preenchimento!$C:$C, 'BCKSTG-ANALYSIS'!L30:L30)} -> 46042
H38: Tempo total de operação (sem deduções) | I38: =(I37 - I36)*24 -> 13272 | J38: Tempo total de operação (sem deduções) | K38: =(K37 - K36)*24 -> 25392 | L38: Tempo total de operação (sem deduções) | M38: =(M37 - M36)*24 -> 23472 | O38: Método anterior
H39: Tempo total de parada | I39: {=IFERROR(GETPIVOTDATA("Duração da Parada (h)",'BCKSTG-TABLES'!$AL$4,"Estrutura", 'BCKSTG-ANALYSIS'!H30:H30), "—")} -> 5.8916667 | J39: Tempo total de parada | K39: {=IFERROR(GETPIVOTDATA("Duração da Parada (h)",'BCKSTG-TABLES'!$AL$4,"Estrutura", 'BCKSTG-ANALYSIS'!J30:J30), "—")} -> 9.775 | L39: Tempo total de parada | M39: {=IFERROR(GETPIVOTDATA("Duração da Parada (h)",'BCKSTG-TABLES'!$AL$4,"Estrutura", 'BCKSTG-ANALYSIS'!L30:L30), "—")} -> 5.725 | P39: MTBF | Q39: MTTR | R39: DISP | S39: CONF
O40: MÁXIMO | P40: =TEXT(MAX(_xlfn.NUMBERVALUE(MID(I20, 1, LEN(I20) - 1)), _xlfn.NUMBERVALUE(MID(K20, 1, LEN(K20) - 1)), _xlfn.NUMBERVALUE(MID(M20, 1, LEN(M20) - 1)), _xlfn.NUMBERVALUE(MID(I31, 1, LEN(I31) - 1)), _xlfn.NUMBERVALUE(MID(K31, 1, LEN(K31) - 1)), _xlfn.NUMBERVALUE(MID(M31, 1, LEN(M31) - 1)), _xlfn.NUMBERVALUE(MID(I42, 1, LEN(I42) - 1)), _xlfn.NUMBERVALUE(MID(K42, 1, LEN(K42) - 1)), _xlfn.NUMBERVALUE(MID(M42, 1, LEN(M42) - 1)), _xlfn.NUMBERVALUE(MID(I53, 1, LEN(I53) - 1)), _xlfn.NUMBERVALUE(MID(K53, 1, LEN(K53) - 1)), _xlfn.NUMBERVALUE(MID(M53, 1, LEN(M53) - 1))), "0,00") & "h" -> 26467,41h | Q40: =TEXT(MAX(_xlfn.NUMBERVALUE(MID(I21, 1, LEN(I21) - 1)), _xlfn.NUMBERVALUE(MID(K21, 1, LEN(K21) - 1)), _xlfn.NUMBERVALUE(MID(M21, 1, LEN(M21) - 1)), _xlfn.NUMBERVALUE(MID(I32, 1, LEN(I32) - 1)), _xlfn.NUMBERVALUE(MID(K32, 1, LEN(K32) - 1)), _xlfn.NUMBERVALUE(MID(M32, 1, LEN(M32) - 1)), _xlfn.NUMBERVALUE(MID(I43, 1, LEN(I43) - 1)), _xlfn.NUMBERVALUE(MID(K43, 1, LEN(K43) - 1)), _xlfn.NUMBERVALUE(MID(M43, 1, LEN(M43) - 1)), _xlfn.NUMBERVALUE(MID(I54, 1, LEN(I54) - 1)), _xlfn.NUMBERVALUE(MID(K54, 1, LEN(K54) - 1)), _xlfn.NUMBERVALUE(MID(M54, 1, LEN(M54) - 1))), "0,00") & "h" -> 8,16h | R40: =MAX(_xlfn.NUMBERVALUE(MID(I22, 1, LEN(I22) - 1)), _xlfn.NUMBERVALUE(MID(K22, 1, LEN(K22) - 1)), _xlfn.NUMBERVALUE(MID(M22, 1, LEN(M22) - 1)), _xlfn.NUMBERVALUE(MID(I33, 1, LEN(I33) - 1)), _xlfn.NUMBERVALUE(MID(K33, 1, LEN(K33) - 1)), _xlfn.NUMBERVALUE(MID(M33, 1, LEN(M33) - 1)), _xlfn.NUMBERVALUE(MID(I44, 1, LEN(I44) - 1)), _xlfn.NUMBERVALUE(MID(K44, 1, LEN(K44) - 1)), _xlfn.NUMBERVALUE(MID(M44, 1, LEN(M44) - 1)), _xlfn.NUMBERVALUE(MID(I55, 1, LEN(I55) - 1)), _xlfn.NUMBERVALUE(MID(K55, 1, LEN(K55) - 1)), _xlfn.NUMBERVALUE(MID(M55, 1, LEN(M55) - 1))) -> 0.99985372 | S40: =MAX(_xlfn.NUMBERVALUE(MID(I23, 1, LEN(I23) - 1)), _xlfn.NUMBERVALUE(MID(K23, 1, LEN(K23) - 1)), _xlfn.NUMBERVALUE(MID(M23, 1, LEN(M23) - 1)), _xlfn.NUMBERVALUE(MID(I34, 1, LEN(I34) - 1)), _xlfn.NUMBERVALUE(MID(K34, 1, LEN(K34) - 1)), _xlfn.NUMBERVALUE(MID(M34, 1, LEN(M34) - 1)), _xlfn.NUMBERVALUE(MID(I45, 1, LEN(I45) - 1)), _xlfn.NUMBERVALUE(MID(K45, 1, LEN(K45) - 1)), _xlfn.NUMBERVALUE(MID(M45, 1, LEN(M45) - 1)), _xlfn.NUMBERVALUE(MID(I56, 1, LEN(I56) - 1)), _xlfn.NUMBERVALUE(MID(K56, 1, LEN(K56) - 1)), _xlfn.NUMBERVALUE(MID(M56, 1, LEN(M56) - 1))) -> 0.99369192
H41: SE-E4. DJ6-03 - VÃO BX | J41: SE-E5. DJ4-02 - VÃO AY | L41: SE-E6. DJ4-02 - VÃO AZ - RAMAL DO AGRESTE | O41: MÍNIMO | P41: =TEXT(MIN(_xlfn.NUMBERVALUE(MID(I20, 1, LEN(I20) - 1)), _xlfn.NUMBERVALUE(MID(K20, 1, LEN(K20) - 1)), _xlfn.NUMBERVALUE(MID(M20, 1, LEN(M20) - 1)), _xlfn.NUMBERVALUE(MID(I31, 1, LEN(I31) - 1)), _xlfn.NUMBERVALUE(MID(K31, 1, LEN(K31) - 1)), _xlfn.NUMBERVALUE(MID(M31, 1, LEN(M31) - 1)), _xlfn.NUMBERVALUE(MID(I42, 1, LEN(I42) - 1)), _xlfn.NUMBERVALUE(MID(K42, 1, LEN(K42) - 1)), _xlfn.NUMBERVALUE(MID(M42, 1, LEN(M42) - 1)), _xlfn.NUMBERVALUE(MID(I53, 1, LEN(I53) - 1)), _xlfn.NUMBERVALUE(MID(K53, 1, LEN(K53) - 1)), _xlfn.NUMBERVALUE(MID(M53, 1, LEN(M53) - 1))), "0,00") & "h" -> 0,00h | Q41: =TEXT(MIN(_xlfn.NUMBERVALUE(MID(I21, 1, LEN(I21) - 1)), _xlfn.NUMBERVALUE(MID(K21, 1, LEN(K21) - 1)), _xlfn.NUMBERVALUE(MID(M21, 1, LEN(M21) - 1)), _xlfn.NUMBERVALUE(MID(I32, 1, LEN(I32) - 1)), _xlfn.NUMBERVALUE(MID(K32, 1, LEN(K32) - 1)), _xlfn.NUMBERVALUE(MID(M32, 1, LEN(M32) - 1)), _xlfn.NUMBERVALUE(MID(I43, 1, LEN(I43) - 1)), _xlfn.NUMBERVALUE(MID(K43, 1, LEN(K43) - 1)), _xlfn.NUMBERVALUE(MID(M43, 1, LEN(M43) - 1)), _xlfn.NUMBERVALUE(MID(I54, 1, LEN(I54) - 1)), _xlfn.NUMBERVALUE(MID(K54, 1, LEN(K54) - 1)), _xlfn.NUMBERVALUE(MID(M54, 1, LEN(M54) - 1))), "0,00") & "h" -> 0,00h | R41: =MIN(_xlfn.NUMBERVALUE(MID(I22, 1, LEN(I22) - 1)), _xlfn.NUMBERVALUE(MID(K22, 1, LEN(K22) - 1)), _xlfn.NUMBERVALUE(MID(M22, 1, LEN(M22) - 1)), _xlfn.NUMBERVALUE(MID(I33, 1, LEN(I33) - 1)), _xlfn.NUMBERVALUE(MID(K33, 1, LEN(K33) - 1)), _xlfn.NUMBERVALUE(MID(M33, 1, LEN(M33) - 1)), _xlfn.NUMBERVALUE(MID(I44, 1, LEN(I44) - 1)), _xlfn.NUMBERVALUE(MID(K44, 1, LEN(K44) - 1)), _xlfn.NUMBERVALUE(MID(M44, 1, LEN(M44) - 1)), _xlfn.NUMBERVALUE(MID(I55, 1, LEN(I55) - 1)), _xlfn.NUMBERVALUE(MID(K55, 1, LEN(K55) - 1)), _xlfn.NUMBERVALUE(MID(M55, 1, LEN(M55) - 1))) -> 0 | S41: =MIN(_xlfn.NUMBERVALUE(MID(I23, 1, LEN(I23) - 1)), _xlfn.NUMBERVALUE(MID(K23, 1, LEN(K23) - 1)), _xlfn.NUMBERVALUE(MID(M23, 1, LEN(M23) - 1)), _xlfn.NUMBERVALUE(MID(I34, 1, LEN(I34) - 1)), _xlfn.NUMBERVALUE(MID(K34, 1, LEN(K34) - 1)), _xlfn.NUMBERVALUE(MID(M34, 1, LEN(M34) - 1)), _xlfn.NUMBERVALUE(MID(I45, 1, LEN(I45) - 1)), _xlfn.NUMBERVALUE(MID(K45, 1, LEN(K45) - 1)), _xlfn.NUMBERVALUE(MID(M45, 1, LEN(M45) - 1)), _xlfn.NUMBERVALUE(MID(I56, 1, LEN(I56) - 1)), _xlfn.NUMBERVALUE(MID(K56, 1, LEN(K56) - 1)), _xlfn.NUMBERVALUE(MID(M56, 1, LEN(M56) - 1))) -> 0
B42: *fim da contagem de estruturas. | H42: MTBF = | I42: =IFERROR(IF(_xlfn.NUMBERVALUE(TEXT((I49 - I50)/GETPIVOTDATA("Duração da Parada (h)",'BCKSTG-TABLES'!$AI$4,"Estrutura", H41), "0,00")) < 0, "—", TEXT((I49 - I50)/GETPIVOTDATA("Duração da Parada (h)",'BCKSTG-TABLES'!$AI$4,"Estrutura", H41), "0,00") & "h"), "—") -> 12523,43h | J42: MTBF = | K42: =IFERROR(IF(_xlfn.NUMBERVALUE(TEXT((K49 - K50)/GETPIVOTDATA("Duração da Parada (h)",'BCKSTG-TABLES'!$AI$4,"Estrutura", J41), "0,00")) < 0, "—", TEXT((K49 - K50)/GETPIVOTDATA("Duração da Parada (h)",'BCKSTG-TABLES'!$AI$4,"Estrutura", J41), "0,00") & "h"), "—") -> 12687,84h | L42: MTBF = | M42: =IFERROR(IF(_xlfn.NUMBERVALUE(TEXT((M49 - M50)/GETPIVOTDATA("Duração da Parada (h)",'BCKSTG-TABLES'!$AI$4,"Estrutura", L41), "0,00")) < 0, "—", TEXT((M49 - M50)/GETPIVOTDATA("Duração da Parada (h)",'BCKSTG-TABLES'!$AI$4,"Estrutura", L41), "0,00") & "h"), "—") -> 24644,37h | O42: MÉDIA | P42: =TEXT(AVERAGE(_xlfn.NUMBERVALUE(MID(I20, 1, LEN(I20) - 1)), _xlfn.NUMBERVALUE(MID(K20, 1, LEN(K20) - 1)), _xlfn.NUMBERVALUE(MID(M20, 1, LEN(M20) - 1)), _xlfn.NUMBERVALUE(MID(I31, 1, LEN(I31) - 1)), _xlfn.NUMBERVALUE(MID(K31, 1, LEN(K31) - 1)), _xlfn.NUMBERVALUE(MID(M31, 1, LEN(M31) - 1)), _xlfn.NUMBERVALUE(MID(I42, 1, LEN(I42) - 1)), _xlfn.NUMBERVALUE(MID(K42, 1, LEN(K42) - 1)), _xlfn.NUMBERVALUE(MID(M42, 1, LEN(M42) - 1)), _xlfn.NUMBERVALUE(MID(I53, 1, LEN(I53) - 1)), _xlfn.NUMBERVALUE(MID(K53, 1, LEN(K53) - 1)), _xlfn.NUMBERVALUE(MID(M53, 1, LEN(M53) - 1))), "0,00") & "h" -> 16648,54h | Q42: =TEXT(AVERAGE(_xlfn.NUMBERVALUE(MID(I21, 1, LEN(I21) - 1)), _xlfn.NUMBERVALUE(MID(K21, 1, LEN(K21) - 1)), _xlfn.NUMBERVALUE(MID(M21, 1, LEN(M21) - 1)), _xlfn.NUMBERVALUE(MID(I32, 1, LEN(I32) - 1)), _xlfn.NUMBERVALUE(MID(K32, 1, LEN(K32) - 1)), _xlfn.NUMBERVALUE(MID(M32, 1, LEN(M32) - 1)), _xlfn.NUMBERVALUE(MID(I43, 1, LEN(I43) - 1)), _xlfn.NUMBERVALUE(MID(K43, 1, LEN(K43) - 1)), _xlfn.NUMBERVALUE(MID(M43, 1, LEN(M43) - 1)), _xlfn.NUMBERVALUE(MID(I54, 1, LEN(I54) - 1)), _xlfn.NUMBERVALUE(MID(K54, 1, LEN(K54) - 1)), _xlfn.NUMBERVALUE(MID(M54, 1, LEN(M54) - 1))), "0,00") & "h" -> 4,46h | R42: =AVERAGE(_xlfn.NUMBERVALUE(MID(I22, 1, LEN(I22) - 1)), _xlfn.NUMBERVALUE(MID(K22, 1, LEN(K22) - 1)), _xlfn.NUMBERVALUE(MID(M22, 1, LEN(M22) - 1)), _xlfn.NUMBERVALUE(MID(I33, 1, LEN(I33) - 1)), _xlfn.NUMBERVALUE(MID(K33, 1, LEN(K33) - 1)), _xlfn.NUMBERVALUE(MID(M33, 1, LEN(M33) - 1)), _xlfn.NUMBERVALUE(MID(I44, 1, LEN(I44) - 1)), _xlfn.NUMBERVALUE(MID(K44, 1, LEN(K44) - 1)), _xlfn.NUMBERVALUE(MID(M44, 1, LEN(M44) - 1)), _xlfn.NUMBERVALUE(MID(I55, 1, LEN(I55) - 1)), _xlfn.NUMBERVALUE(MID(K55, 1, LEN(K55) - 1)), _xlfn.NUMBERVALUE(MID(M55, 1, LEN(M55) - 1))) -> 0.91638352 | S42: =AVERAGE(_xlfn.NUMBERVALUE(MID(I23, 1, LEN(I23) - 1)), _xlfn.NUMBERVALUE(MID(K23, 1, LEN(K23) - 1)), _xlfn.NUMBERVALUE(MID(M23, 1, LEN(M23) - 1)), _xlfn.NUMBERVALUE(MID(I34, 1, LEN(I34) - 1)), _xlfn.NUMBERVALUE(MID(K34, 1, LEN(K34) - 1)), _xlfn.NUMBERVALUE(MID(M34, 1, LEN(M34) - 1)), _xlfn.NUMBERVALUE(MID(I45, 1, LEN(I45) - 1)), _xlfn.NUMBERVALUE(MID(K45, 1, LEN(K45) - 1)), _xlfn.NUMBERVALUE(MID(M45, 1, LEN(M45) - 1)), _xlfn.NUMBERVALUE(MID(I56, 1, LEN(I56) - 1)), _xlfn.NUMBERVALUE(MID(K56, 1, LEN(K56) - 1)), _xlfn.NUMBERVALUE(MID(M56, 1, LEN(M56) - 1))) -> 0.90730573
H43: MTTR = | I43: =IFERROR(TEXT((GETPIVOTDATA("Duração da Parada (h)",'BCKSTG-TABLES'!$AL$4,"Estrutura", H41)/GETPIVOTDATA("Duração da Parada (h)",'BCKSTG-TABLES'!$AI$4,"Estrutura", H41)), "0,00") & "h", "—") -> 4,57h | J43: MTTR = | K43: =IFERROR(TEXT((GETPIVOTDATA("Duração da Parada (h)",'BCKSTG-TABLES'!$AL$4,"Estrutura", J41)/GETPIVOTDATA("Duração da Parada (h)",'BCKSTG-TABLES'!$AI$4,"Estrutura", J41)), "0,00") & "h", "—") -> 8,16h | L43: MTTR = | M43: =IFERROR(TEXT((GETPIVOTDATA("Duração da Parada (h)",'BCKSTG-TABLES'!$AL$4,"Estrutura", L41)/GETPIVOTDATA("Duração da Parada (h)",'BCKSTG-TABLES'!$AI$4,"Estrutura", L41)), "0,00") & "h", "—") -> 3,63h
B44: #000 – Sem vínculo | H44: DISP = | I44: =IFERROR((MID('BCKSTG-ANALYSIS'!I42, 1, LEN('BCKSTG-ANALYSIS'!I42) - 1))/(MID('BCKSTG-ANALYSIS'!I42, 1, LEN('BCKSTG-ANALYSIS'!I42) - 1) + MID('BCKSTG-ANALYSIS'!I43, 1, LEN('BCKSTG-ANALYSIS'!I43) - 1)), "—") -> 0.99963522 | J44: DISP = | K44: =IFERROR((MID('BCKSTG-ANALYSIS'!K42, 1, LEN('BCKSTG-ANALYSIS'!K42) - 1))/(MID('BCKSTG-ANALYSIS'!K42, 1, LEN('BCKSTG-ANALYSIS'!K42) - 1) + MID('BCKSTG-ANALYSIS'!K43, 1, LEN('BCKSTG-ANALYSIS'!K43) - 1)), "—") -> 0.99935728 | L44: DISP = | M44: =IFERROR((MID('BCKSTG-ANALYSIS'!M42, 1, LEN('BCKSTG-ANALYSIS'!M42) - 1))/(MID('BCKSTG-ANALYSIS'!M42, 1, LEN('BCKSTG-ANALYSIS'!M42) - 1) + MID('BCKSTG-ANALYSIS'!M43, 1, LEN('BCKSTG-ANALYSIS'!M43) - 1)), "—") -> 0.99985273
H45: CONF = | I45: =IFERROR((2.71^-((1/MID('BCKSTG-ANALYSIS'!I42, 1, LEN('BCKSTG-ANALYSIS'!I42) - 1))*($M$17))), "—") -> 0.98671511 | J45: CONF = | K45: =IFERROR((2.71^-((1/MID('BCKSTG-ANALYSIS'!K42, 1, LEN('BCKSTG-ANALYSIS'!K42) - 1))*($M$17))), "—") -> 0.98688612 | L45: CONF = | M45: =IFERROR((2.71^-((1/MID('BCKSTG-ANALYSIS'!M42, 1, LEN('BCKSTG-ANALYSIS'!M42) - 1))*($M$17))), "—") -> 0.99322687
